Workbook
Name Авиа_межд: #REF!
Name Авиа_межд: #REF!
Name Авиа_межд: #REF!
Name Авиа_межд: #REF!
Name Авиа_межд: #REF!
Name Авиа_межд: #REF!
Name Авиа_межд: Параметры!$B$25
Name Авиа_РК: #REF!
Name Авиа_РК: #REF!
Name Авиа_РК: #REF!
Name Авиа_РК: #REF!
Name Авиа_РК: #REF!
Name Авиа_РК: #REF!
Name Авиа_РК: Параметры!$B$18
Name Аренда_депозит: #REF!
Name Аренда_депозит: #REF!
Name Аренда_депозит: #REF!
Name Аренда_депозит: #REF!
Name Аренда_депозит: #REF!
Name Аренда_депозит: #REF!
Name Аренда_депозит: Параметры!$B$48
Name Аренда_мес: #REF!
Name Аренда_мес: #REF!
Name Аренда_мес: #REF!
Name Аренда_мес: #REF!
Name Аренда_мес: #REF!
Name Аренда_мес: #REF!
Name Аренда_мес: Параметры!$B$32
Name Аренда_мес_2026: #REF!
Name Аренда_мес_2026: #REF!
Name Аренда_мес_2026: #REF!
Name Аренда_мес_2026: #REF!
Name Аренда_мес_2026: #REF!
Name Аренда_мес_2026: #REF!
Name Аренда_мес_2026: Параметры!$B$49
Name Аренда_с_НДС: #REF!
Name Аренда_с_НДС: #REF!
Name Аренда_с_НДС: #REF!
Name Аренда_с_НДС: #REF!
Name Аренда_с_НДС: #REF!
Name Аренда_с_НДС: #REF!
Name Аренда_с_НДС: Параметры!$B$47
Name Депозит_мес: #REF!
Name Депозит_мес: #REF!
Name Депозит_мес: #REF!
Name Депозит_мес: #REF!
Name Депозит_мес: #REF!
Name Депозит_мес: #REF!
Name Депозит_мес: Параметры!$B$33
Name Дней_межд: #REF!
Name Дней_межд: #REF!
Name Дней_межд: #REF!
Name Дней_межд: #REF!
Name Дней_межд: #REF!
Name Дней_межд: #REF!
Name Дней_межд: Параметры!$B$28
Name Дней_РК: #REF!
Name Дней_РК: #REF!
Name Дней_РК: #REF!
Name Дней_РК: #REF!

Sheet Свод
A1: Бюджет ЦАКФ на ноябрь 2026 – февраль 2027 года, ₸
A3: Статья | B3: Октябрь-ноябрь 2026 | C3: Декабрь 2026 | D3: Январь 2027 | E3: Февраль 2027 | F3: Итого ноябрь 2026 – февраль 2027
A4: Штатная численность, чел. | B4: =SUMPRODUCT((Штат!$E$5:$E$36="штат")*Штат!$G$5:$G$36*(Штат!$I$5:$I$36<=2)) -> 22 | C4: =SUMPRODUCT((Штат!$E$5:$E$36="штат")*Штат!$G$5:$G$36*(Штат!$I$5:$I$36<=3)) -> 23 | D4: =SUMPRODUCT((Штат!$E$5:$E$36="штат")*Штат!$G$5:$G$36*(Штат!$I$5:$I$36<=3)) -> 23 | E4: =D4+COUNT('Февраль 2027'!D4:D10) -> 30
A5: в т.ч. проектный офис «Таза Қазақстан», чел. | F5: =Штат!G38 -> 15
A6: 1. Оплата труда и отчисления работодателя | B6: =(SUMPRODUCT((Штат!$E$5:$E$36="штат")*Штат!$K$5:$K$36*(Штат!$I$5:$I$36<=2)))+B7+Обязательства_ЗП -> 56312240 | C6: =(SUMPRODUCT((Штат!$E$5:$E$36="штат")*Штат!$K$5:$K$36*(Штат!$I$5:$I$36<=3)))+C7+C20 -> 37571650 | D6: =(SUMPRODUCT((Штат!$E$5:$E$36="штат")*Штат!$K$5:$K$36*(Штат!$I$5:$I$36<=3)))+D7+D20 -> 28182130 | E6: =D6+'Февраль 2027'!F11 -> 34985400 | F6: =SUM(B6:E6) -> 157051420
A7: 1а. Премия 8 работникам проектного офиса по итогам работы в октябре (1 оклад с отчислениями, выплата в декабре) | B7: 0 | C7: =Штат!$H$44 -> 9389520 | D7: 0 | E7: 0 | F7: =SUM(B7:E7) -> 9389520
A8: 2. Аутсорс-услуги: юрист МФЦА, сис.админ, разработчик, режиссёр, копирайтер, социолог, менеджер по креаторам (с НДС исполнителя) | B8: =SUMPRODUCT(Аутсорс!$I$4:$I$10*((Аутсорс!$J$4:$J$10<=1)+(Аутсорс!$J$4:$J$10<=2))) -> 6881596 | C8: =SUMPRODUCT(Аутсорс!$I$4:$I$10*(Аутсорс!$J$4:$J$10<=3)) -> 6881596 | D8: =SUMPRODUCT(Аутсорс!$I$4:$I$10*(Аутсорс!$J$4:$J$10<=3)) -> 6881596 | E8: =D8 -> 6881596 | F8: =SUM(B8:E8) -> 27526384
A9: 3. ОСНС: годовой полис на новых сотрудников | B9: =Штат!$N$37 -> 645095.24 | C9: 0 | D9: 0 | E9: ='Февраль 2027'!F23 -> 205000 | F9: =SUM(B9:E9) -> 850095.24
A10: 4. Командировки по РК | B10: =Командировки!$G$12/2 -> 1899506.2 | C10: =Командировки!$G$12/2 -> 1899506.2 | D10: =SUMPRODUCT(Командировки!$C$5:$C$11*(Командировки!$D$5:$D$11/12*Поездка_РК+Командировки!$E$5:$E$11*Поездка_местн)) -> 1958850 | E10: =D10+'Февраль 2027'!F24 -> 2554912.5 | F10: =SUM(B10:E10) -> 8312775
A11: 5. Оснащение (разово): ноутбуки, мебель, МФУ, интерактивная панель, ИБП, фото-видео, сеть | B11: =SUMIFS('Оснащение и офис'!$J$5:$J$77,'Оснащение и офис'!$A$5:$A$77,"Оснащение") -> 12336434 | C11: =SUMIFS('Оснащение и офис'!$K$5:$K$77,'Оснащение и офис'!$A$5:$A$77,"Оснащение") -> 1695609 | D11: =SUMIFS('Оснащение и офис'!$L$5:$L$77,'Оснащение и офис'!$A$5:$A$77,"Оснащение") -> 0 | E11: ='Февраль 2027'!F19 -> 505594 | F11: =SUM(B11:E11) -> 14537637
A12: 6. Офис: аренда, депозит, текущие хозрасходы, курьер, интернет, обслуживание МФУ, канцелярия, представительские, нотариус и услуги МФЦА, расчёты с поставщиками за прошлые периоды | B12: =SUMIFS('Оснащение и офис'!$J$5:$J$77,'Оснащение и офис'!$A$5:$A$77,"Офис")+Обязательства_прочие -> 12661707 | C12: =SUMIFS('Оснащение и офис'!$K$5:$K$77,'Оснащение и офис'!$A$5:$A$77,"Офис") -> 5212743.1 | D12: =SUMIFS('Оснащение и офис'!$L$5:$L$77,'Оснащение и офис'!$A$5:$A$77,"Офис") -> 5212743.1 | E12: =D12 -> 5212743.1 | F12: =SUM(B12:E12) -> 28299936
A13: 7. Цифровые инструменты | B13: =SUMIFS('Оснащение и офис'!$J$5:$J$77,'Оснащение и офис'!$A$5:$A$77,"Цифровые") -> 332947 | C13: =SUMIFS('Оснащение и офис'!$K$5:$K$77,'Оснащение и офис'!$A$5:$A$77,"Цифровые") -> 253500 | D13: =SUMIFS('Оснащение и офис'!$L$5:$L$77,'Оснащение и офис'!$A$5:$A$77,"Цифровые") -> 253500 | E13: =D13+'Февраль 2027'!F22 -> 302500 | F13: =SUM(B13:E13) -> 1142447
A14: 8. Медиа: таргет, полиграфия, подписки | B14: =SUMIFS('Оснащение и офис'!$J$5:$J$77,'Оснащение и офис'!$A$5:$A$77,"Медиа") -> 1175000 | C14: =SUMIFS('Оснащение и офис'!$K$5:$K$77,'Оснащение и офис'!$A$5:$A$77,"Медиа") -> 1175000 | D14: =SUMIFS('Оснащение и офис'!$L$5:$L$77,'Оснащение и офис'!$A$5:$A$77,"Медиа") -> 1175000 | E14: =D14 -> 1175000 | F14: =SUM(B14:E14) -> 4700000
A15: Прямые затраты | B15: =SUM(B6:B14)-B7 -> 92244525 | C15: =SUM(C6:C14)-C7 -> 54689604 | D15: =SUM(D6:D14)-D7 -> 43663819 | E15: =SUM(E6:E14)-E7 -> 51822746 | F15: =SUM(B15:E15) -> 2.4242069e+08
A16: Резерв 10% на непредвиденные расходы | B16: =(B15-Обязательства_ЗП-Обязательства_прочие-'Оснащение и офис'!$J$76)*Резерв -> 6179952.5 | C16: =(C15-C20-'Оснащение и офис'!$K$76)*Резерв -> 5468960.4 | D16: =(D15-D20-'Оснащение и офис'!$L$76)*Резерв -> 4366381.9 | E16: =(E15-E20)*Резерв -> 5182274.6 | F16: =SUM(B16:E16) -> 21197569
A17: НДС: 16% на закупки, аренду, услуги, подписки и первоочередные проекты; расчёты с бюджетом по НДС | B17: =((B11+B12+B13+B14)-Обязательства_прочие-'Оснащение и офис'!$J$59-'Оснащение и офис'!$J$76)*(1+Резерв)*НДС+Обязательства_НДС+B19*НДС -> 17136024 | C17: =((C11+C12+C13+C14)-'Оснащение и офис'!$K$59-'Оснащение и офис'!$K$76)*(1+Резерв)*НДС+C19*НДС -> 6560273.7 | D17: =((D11+D12+D13+D14)-'Оснащение и офис'!$L$59-'Оснащение и офис'!$L$76)*(1+Резерв)*НДС+D19*НДС -> 3914006.5 | E17: =(E11+E12+E13+E14)*(1+Резерв)*НДС+E19*НДС -> 5918964.4 | F17: =SUM(B17:E17) -> 33529269
A18: А. ИТОГО организационное обеспечение | B18: =B15+B16+B17 -> 1.155605e+08 | C18: =C15+C16+C17 -> 66718838 | D18: =D15+D16+D17 -> 51944208 | E18: =E15+E16+E17 -> 62923985 | F18: =SUM(B18:E18) -> 2.9714753e+08
A19: Б. Первоочередные проекты (лист «Проекты») | B19: =Проекты!$H$13 -> 38245973 | C19: =Проекты!$I$13 -> 31831173 | D19: =Проекты!$J$13 -> 17157173 | E19: ='Февраль 2027'!F25 -> 29078107 | F19: =SUM(B19:E19) -> 1.1631243e+08
A20: В. Обязательства по оплате труда и налогам за июль–октябрь 2026 | B20: =Обязательства_ЗП+Обязательства_НДС+Обязательства_прочие -> 37450000 | C20: 0 | D20: 0 | E20: 0 | F20: =SUM(B20:E20) -> 37450000
A21: ВСЕГО (А + Б) | B21: =B18+B19 -> 1.5380648e+08 | C21: =C18+C19 -> 98550012 | D21: =D18+D19 -> 69101381 | E21: =E18+E19 -> 92002091 | F21: =F18+F19 -> 4.1345996e+08
A23: Нарастающим итогом | B23: =B21 -> 1.5380648e+08 | C23: =B23+C21 -> 2.5235649e+08 | D23: =C23+D21 -> 3.2145787e+08 | E23: =D23+E21 -> 4.1345996e+08
A24: Финансирование | F24: 250000000
A25: Разница с 250 млн (+ остаток / − дефицит) | B25: =$F$24-B23 -> 96193524 | C25: =$F$24-C23 -> -2356487.3 | D25: =$F$24-D23 -> -71457868 | E25: =$F$24-E23 -> -1.6345996e+08 | F25: =F24-F21 -> -1.6345996e+08

Sheet Параметры
A1: Параметры расчёта (меняйте значения в колонке B — всё пересчитается)
A3: Имя | B3: Значение | C3: Пояснение
A4: МЗП | B4: 85000 | C4: МЗП 2026, ₸
A5: МРП | B5: 4325 | C5: МРП 2026, ₸
A6: Ставка_СН | B6: 0.06 | C6: Социальный налог — 6% (НК с 01.01.2026), база: оклад − ОПВ 10% − ВОСМС 2%
A7: Ставка_ОПВР | B7: 0.035 | C7: Пенсионные взносы работодателя — 3,5% (2026)
A8: Ставка_СО | B8: 0.05 | C8: Социальные отчисления — 5%, база до 7 МЗП
A9: Кап_СО | B9: 7 | C9: Предел базы СО, в МЗП
A10: Ставка_ООСМС | B10: 0.03 | C10: Отчисления на ОСМС работодателя — 3%
A11: Кап_ООСМС | B11: 40 | C11: Предел базы ООСМС, в МЗП (с 01.01.2026 предел вырос с 10 до 40 МЗП — изм. в Закон РК "Об обязательном соц. мед. страховании"; было 10 МЗП — это предел до 2025 г.)
A12: Ставка_ОПВ | B12: 0.1 | C12: ОПВ работника 10% — удерживается из оклада (для базы СН и СО)
A13: Ставка_ВОСМС | B13: 0.02 | C13: ВОСМС работника 2% — удерживается из оклада
A14: ОСНС | B14: 28000 | C14: ОСНС на штатного сотрудника в год, ₸
A15: ОСНС_полис | B15: =ROUND(0.29%*12*SUMIFS(Штат!$H$5:$H$36,Штат!$E$5:$E$36,"штат",Штат!$F$5:$F$36,"новая"),-3) -> 713000 | C15: Годовой полис ОСНС на новых сотрудников 2026 года: 0,29% от их годового ФОТ (тариф по КП сентября 2026), ₸
A16: Курс | B16: 530 | C16: ₸ за 1 $
A17: Сут_РК | B17: 2 | C17: Суточные по РК, МРП в день (норма 2 МРП/день — п.3 Правил, утв. пост. Правительства РК от 11.05.2018 № 256, с изм. от 29.12.2018 № 934; было 6 МРП — это порог необлагаемости суточных по ст.319 НК РК, а не норма возмещения)
A18: Авиа_РК | B18: 90000 | C18: Авиабилет Астана — областной центр, туда-обратно, ₸
A19: Отель_РК | B19: 30000 | C19: Гостиница в регионе, ₸ за ночь
A20: Трансп_РК | B20: 15000 | C20: Местный транспорт в поездке, ₸
A21: Дней_РК | B21: 3 | C21: Длительность типовой поездки по РК, дней
A22: Ночей_РК | B22: 2 | C22: Ночей в типовой поездке
A23: Поездка_РК | B23: =Авиа_РК+Отель_РК*Ночей_РК+Сут_РК*МРП*Дней_РК+Трансп_РК -> 190950 | C23: Одна поездка по РК на человека, ₸
A24: Поездка_местн | B24: =Трансп_РК+Сут_РК*МРП -> 23650 | C24: Выезд регионального координатора внутри макрорегиона (1 день), ₸
A25: Авиа_межд | B25: 900 | C25: Международный перелёт эконом, $
A26: Отель_межд | B26: 150 | C26: Гостиница за рубежом, $ за ночь
A27: Сут_межд | B27: 150 | C27: Суточные за рубежом, $ в день
A28: Дней_межд | B28: 5 | C28: Длительность загранпоездки, дней
A29: Ночей_межд | B29: 4 | C29: Ночей
A30: Страх_межд | B30: 50 | C30: Страховка/виза, $
A31: Поездка_межд | B31: =(Авиа_межд+Отель_межд*Ночей_межд+Сут_межд*Дней_межд+Страх_межд)*Курс -> 1219000 | C31: Одна загранпоездка на человека, ₸
A32: Аренда_мес | B32: =Площадь_офиса*Ставка_аренды_м2+Коммун_мес+Парковка_мест*Парковка_цена -> 4869152.1 | C32: Аренда офисов с коммунальными и парковкой, ₸ в месяц без НДС (БЦ «Сыганак», 7 этаж: 701–702 + зона 710 – расчёт ниже)
A33: Депозит_мес | B33: 1 | C33: Гарантийный депозит по аренде, в месячных ставках (возвратный)
A34: Резерв | B34: 0.1 | C34: Резерв на непредвиденные расходы (10% — по требованию, было 5%)
A35: НДС | B35: 0.16 | C35: НДС 16% — для аутсорса (ТОО — плательщик НДС) и справочно для договора услуг
A37: Период: октябрь–декабрь 2026 (3 мес.).
A38: Старт позиции/расхода: 1 – октябрь, 2 – ноябрь, 3 – декабрь 2026.
A41: Аренда – БЦ «Сыганак», ул. Сыганак, 70, 7 этаж: 701–702 + зона 710
A42: Площадь_офиса | B42: =ROUND((52.2+21.4+12.4+33.7+190)*1.1,2) -> 340.67 | C42: Площадь к оплате, м²: 701 (52,2) + 701а (21,4) + 701б (12,4) + 702 (33,7) = 119,7 по плану БЦ; зона 710 – 190,0 по экспликации БЦ; итого 309,7 полезной + 10% мест общего пользования
A43: Ставка_аренды_м2 | B43: 13500 | C43: Ставка аренды со скидкой, ₸ за 1 м² в месяц без НДС и без коммунальных (условия БЦ от 22.09.2026)
A44: Коммун_мес | B44: =743*309.7 -> 230107.1 | C44: Коммунальные, ₸ в месяц без НДС: 743 ₸/м² × 309,7 м² полезной площади (без МОП)
...

Sheet Штат
A1: Штатная структура ЦАКФ и проектного офиса «Таза Қазақстан» и расходы на персонал, ₸
A4: № | B4: Блок | C4: Должность | D4: Подчиняется | E4: Форма | F4: Статус | G4: Кол-во | H4: Оклад за ед., гросс в мес. (аутсорс — без НДС) | I4: Старт (1 – октябрь, 2 – ноябрь, 3 – декабрь) | J4: Отчисления работодателя / НДС на ед. в мес. | K4: Стоимость строки в мес. | L4: Мес. 2026 (новые – с 01.11) | M4: ФОТ+отчисл. окт–дек 2026 | N4: ОСНС (годовой полис новым сотрудникам) | O4: Итого окт–дек 2026 | P4: Функционал и опыт | Q4: Премия за октябрь (1 – да)
A5: 1 | B5: ЦАКФ — руководство Фонда | C5: Главный исполнительный директор (ГИД) | D5: — | E5: штат | F5: действующий | G5: 1 | H5: 1600000 | I5: 2 | J5: =IF(E5="штат",ROUND(Ставка_СН*H5*(1-Ставка_ОПВ-Ставка_ВОСМС)+Ставка_ОПВР*H5+Ставка_СО*MIN(H5*(1-Ставка_ОПВ),Кап_СО*МЗП)+Ставка_ООСМС*MIN(H5,Кап_ООСМС*МЗП),0),ROUND(H5*НДС,0)) -> 218230 | K5: =G5*(H5+J5) -> 1818230 | L5: =IF(AND(F5="новая",I5=1),Мес_2026_новые,MAX(0,4-I5)) -> 2 | M5: =K5*L5 -> 3636460 | N5: =IF(AND(E5="штат",F5="новая"),ОСНС_полис*G5/COUNTIFS($E$5:$E$36,"штат",$F$5:$F$36,"новая"),0) -> 0 | O5: =M5+N5 -> 3636460 | P5: [Қаражан Е.Н.] Общее руководство Фондом и проектным офисом, руководство Проектным офисом для Центральной Азии, соглашение с МЭПР, отчётность перед органами Фонда. Опыт: к.э.н. (PhD), MSc LSE («Болашақ»), Chevening; ГИД ЦАКФ с 02.2025 (Региональный экологический саммит 2026); председатель Правления ИЭИ, советник Министра национальной экономики, консультант АБР, директор по устойчивому развитию ФНБ «Самрук-Қазына».
A6: 2 | B6: ЦАКФ — руководство Фонда | C6: Советник ГИД по стратегии и науке | D6: ГИД | E6: штат | F6: действующий | G6: 1 | H6: 1400000 | I6: 2 | J6: =IF(E6="штат",ROUND(Ставка_СН*H6*(1-Ставка_ОПВ-Ставка_ВОСМС)+Ставка_ОПВР*H6+Ставка_СО*MIN(H6*(1-Ставка_ОПВ),Кап_СО*МЗП)+Ставка_ООСМС*MIN(H6,Кап_ООСМС*МЗП),0),ROUND(H6*НДС,0)) -> 194670 | K6: =G6*(H6+J6) -> 1594670 | L6: =IF(AND(F6="новая",I6=1),Мес_2026_новые,MAX(0,4-I6)) -> 2 | M6: =K6*L6 -> 3189340 | N6: =IF(AND(E6="штат",F6="новая"),ОСНС_полис*G6/COUNTIFS($E$5:$E$36,"штат",$F$5:$F$36,"новая"),0) -> 0 | O6: =M6+N6 -> 3189340 | P6: [Кононец А.В.] Стратегия и научное направление Фонда, аналитические и экспертные материалы, международные партнёры; поручения ГИД. Опыт: 20 лет в медиа и госкоммуникациях – руководитель пресс-службы, советник министра труда и социальной защиты, главный редактор Казправды, Total.kz и др.; в ЦАКФ с 07.2025.
A7: 3 | B7: ЦАКФ — руководство Фонда | C7: Заместитель ГИД (адм.-хоз. вопросы, закупки, кадры, проекты) | D7: ГИД | E7: штат | F7: действующий | G7: 1 | H7: 1400000 | I7: 2 | J7: =IF(E7="штат",ROUND(Ставка_СН*H7*(1-Ставка_ОПВ-Ставка_ВОСМС)+Ставка_ОПВР*H7+Ставка_СО*MIN(H7*(1-Ставка_ОПВ),Кап_СО*МЗП)+Ставка_ООСМС*MIN(H7,Кап_ООСМС*МЗП),0),ROUND(H7*НДС,0)) -> 194670 | K7: =G7*(H7+J7) -> 1594670 | L7: =IF(AND(F7="новая",I7=1),Мес_2026_новые,MAX(0,4-I7)) -> 2 | M7: =K7*L7 -> 3189340 | N7: =IF(AND(E7="штат",F7="новая"),ОСНС_полис*G7/COUNTIFS($E$5:$E$36,"штат",$F$5:$F$36,"новая"),0) -> 0 | O7: =M7+N7 -> 3189340 | P7: [Темирбеков М.Е.] Наём, закупки, офис, договоры с поставщиками. Опыт: международные экономические отношения (диплом с отличием); акиматы Костанайской области и Астаны; руководитель аппарата холдинга (3 000+ сотрудников); проекты МЗ РК и Всемирного банка; руководитель в общественных организациях, структур в квазигоссекторе; в ЦАКФ с 02.2025, член Управляющего совета.
A8: 4 | B8: Проектный офис — руководство | C8: Руководитель проектного офиса «Таза Қазақстан» | D8: ГИД | E8: штат | F8: новая | G8: 1 | H8: 1400000 | I8: 2 | J8: =IF(E8="штат",ROUND(Ставка_СН*H8*(1-Ставка_ОПВ-Ставка_ВОСМС)+Ставка_ОПВР*H8+Ставка_СО*MIN(H8*(1-Ставка_ОПВ),Кап_СО*МЗП)+Ставка_ООСМС*MIN(H8,Кап_ООСМС*МЗП),0),ROUND(H8*НДС,0)) -> 194670 | K8: =G8*(H8+J8) -> 1594670 | L8: =IF(AND(F8="новая",I8=1),Мес_2026_новые,MAX(0,4-I8)) -> 2 | M8: =K8*L8 -> 3189340 | N8: =IF(AND(E8="штат",F8="новая"),ОСНС_полис*G8/COUNTIFS($E$5:$E$36,"штат",$F$5:$F$36,"новая"),0) -> 33952.381 | O8: =M8+N8 -> 3223292.4 | P8: [Серикжанова Айгерим] Руководитель проектного офиса: руководство командой, календарь мероприятий, работа с акиматами и госорганами. Опыт: директор Департамента развития талантов, образовательных программ и экспертного сопровождения КФ «Фонд развития креативных индустрий»; PhD, постдокторантура «Политология» (ЕНУ им. Л.Н. Гумилёва), магистр права LLM (РУДН), магистр юридических наук (КазНУ им. аль-Фараби). | Q8: 1
A9: 6 | B9: Департамент социологических исследований и аналитики | C9: Руководитель департамента | D9: Руководителю проектного офиса «Таза Қазақстан» | E9: штат | F9: новая | G9: 1 | H9: 1300000 | I9: 3 | J9: =IF(E9="штат",ROUND(Ставка_СН*H9*(1-Ставка_ОПВ-Ставка_ВОСМС)+Ставка_ОПВР*H9+Ставка_СО*MIN(H9*(1-Ставка_ОПВ),Кап_СО*МЗП)+Ставка_ООСМС*MIN(H9,Кап_ООСМС*МЗП),0),ROUND(H9*НДС,0)) -> 182890 | K9: =G9*(H9+J9) -> 1482890 | L9: =IF(AND(F9="новая",I9=1),Мес_2026_новые,MAX(0,4-I9)) -> 1 | M9: =K9*L9 -> 1482890 | N9: =IF(AND(E9="штат",F9="новая"),ОСНС_полис*G9/COUNTIFS($E$5:$E$36,"штат",$F$5:$F$36,"новая"),0) -> 33952.381 | O9: =M9+N9 -> 1516842.4 | P9: [Өміртай А.] Руководитель департамента социологии: программа исследований, методология измерения поведения, ежегодный доклад
A10: 6 | B10: Департамент социологических исследований и аналитики | C10: Главный специалист — аналитик | D10: Руководителю департамента | E10: штат | F10: новая | G10: 1 | H10: 1000000 | I10: 2 | J10: =IF(E10="штат",ROUND(Ставка_СН*H10*(1-Ставка_ОПВ-Ставка_ВОСМС)+Ставка_ОПВР*H10+Ставка_СО*MIN(H10*(1-Ставка_ОПВ),Кап_СО*МЗП)+Ставка_ООСМС*MIN(H10,Кап_ООСМС*МЗП),0),ROUND(H10*НДС,0)) -> 147550 | K10: =G10*(H10+J10) -> 1147550 | L10: =IF(AND(F10="новая",I10=1),Мес_2026_новые,MAX(0,4-I10)) -> 2 | M10: =K10*L10 -> 2295100 | N10: =IF(AND(E10="штат",F10="новая"),ОСНС_полис*G10/COUNTIFS($E$5:$E$36,"штат",$F$5:$F$36,"новая"),0) -> 33952.381 | O10: =M10+N10 -> 2329052.4 | P10: [Абенов Алибек] Аналитик: большие данные, дашборды, расчёт KPI, аналитическое сопровождение проектов. Опыт: руководитель управления развития кадров и документооборота АО «Центр международных программ»; бакалавр «Метрология, стандартизация и сертификация» (Карагандинский экономический университет). | Q10: 1
A11: 6 | B11: Департамент социологических исследований и аналитики | C11: Социолог — аутсорс | D11: Руководителю департамента | E11: аутсорс | F11: новая | G11: 0 | H11: 700000 | I11: 2 | J11: =IF(E11="штат",ROUND(Ставка_СН*H11*(1-Ставка_ОПВ-Ставка_ВОСМС)+Ставка_ОПВР*H11+Ставка_СО*MIN(H11*(1-Ставка_ОПВ),Кап_СО*МЗП)+Ставка_ООСМС*MIN(H11,Кап_ООСМС*МЗП),0),ROUND(H11*НДС,0)) -> 112000 | K11: =G11*(H11+J11) -> 0 | L11: =IF(AND(F11="новая",I11=1),Мес_2026_новые,MAX(0,4-I11)) -> 2 | M11: =K11*L11 -> 0 | N11: =IF(AND(E11="штат",F11="новая"),ОСНС_полис*G11/COUNTIFS($E$5:$E$36,"штат",$F$5:$F$36,"новая"),0) -> 0 | O11: =M11+N11 -> 0 | P11: [Нурканат А.] Социолог (аутсорс): опросы, полевые работы, обработка данных
A12: 6 | B12: Департамент социологических исследований и аналитики | C12: Главный специалист — социолог | D12: Руководителю департамента | E12: штат | F12: новая | G12: 1 | H12: 1000000 | I12: 2 | J12: =IF(E12="штат",ROUND(Ставка_СН*H12*(1-Ставка_ОПВ-Ставка_ВОСМС)+Ставка_ОПВР*H12+Ставка_СО*MIN(H12*(1-Ставка_ОПВ),Кап_СО*МЗП)+Ставка_ООСМС*MIN(H12,Кап_ООСМС*МЗП),0),ROUND(H12*НДС,0)) -> 147550 | K12: =G12*(H12+J12) -> 1147550 | L12: =IF(AND(F12="новая",I12=1),Мес_2026_новые,MAX(0,4-I12)) -> 2 | M12: =K12*L12 -> 2295100 | N12: =IF(AND(E12="штат",F12="новая"),ОСНС_полис*G12/COUNTIFS($E$5:$E$36,"штат",$F$5:$F$36,"новая"),0) -> 33952.381 | O12: =M12+N12 -> 2329052.4 | P12: [Тленчиева Ш.] Исследования восприятия акции, опросы. Опыт: PhD по социологии.
A13: 14 | B13: Департамент проектного управления и региональной координации | C13: Заместитель директора (МЭПР, ЦГО, регионы) | D13: Директору департамента | E13: штат | F13: новая | G13: 1 | H13: 1100000 | I13: 2 | J13: =IF(E13="штат",ROUND(Ставка_СН*H13*(1-Ставка_ОПВ-Ставка_ВОСМС)+Ставка_ОПВР*H13+Ставка_СО*MIN(H13*(1-Ставка_ОПВ),Кап_СО*МЗП)+Ставка_ООСМС*MIN(H13,Кап_ООСМС*МЗП),0),ROUND(H13*НДС,0)) -> 159330 | K13: =G13*(H13+J13) -> 1259330 | L13: =IF(AND(F13="новая",I13=1),Мес_2026_новые,MAX(0,4-I13)) -> 2 | M13: =K13*L13 -> 2518660 | N13: =IF(AND(E13="штат",F13="новая"),ОСНС_полис*G13/COUNTIFS($E$5:$E$36,"штат",$F$5:$F$36,"новая"),0) -> 33952.381 | O13: =M13+N13 -> 2552612.4 | P13: Взаимодействие с МЭПР, ЦГО и регионами
A14: 15 | B14: Департамент проектного управления и региональной координации | C14: Главный специалист | D14: Директору департамента | E14: штат | F14: новая | G14: 1 | H14: 1000000 | I14: 2 | J14: =IF(E14="штат",ROUND(Ставка_СН*H14*(1-Ставка_ОПВ-Ставка_ВОСМС)+Ставка_ОПВР*H14+Ставка_СО*MIN(H14*(1-Ставка_ОПВ),Кап_СО*МЗП)+Ставка_ООСМС*MIN(H14,Кап_ООСМС*МЗП),0),ROUND(H14*НДС,0)) -> 147550 | K14: =G14*(H14+J14) -> 1147550 | L14: =IF(AND(F14="новая",I14=1),Мес_2026_новые,MAX(0,4-I14)) -> 2 | M14: =K14*L14 -> 2295100 | N14: =IF(AND(E14="штат",F14="новая"),ОСНС_полис*G14/COUNTIFS($E$5:$E$36,"штат",$F$5:$F$36,"новая"),0) -> 33952.381 | O14: =M14+N14 -> 2329052.4 | P14: [Қуандық Жасұлан] Проектный менеджер: ведение проектов, координация регионов, молодёжные проекты. Опыт: президент благотворительного фонда «Dauletten», основатель портала для молодёжи jastar.online; КазНУ им. аль-Фараби – бакалавр «Государственное и местное управление», MBA, докторантура (PhD). | Q14: 1
A15: 17 | B15: Департамент проектного управления и региональной координации | C15: Главный специалист | D15: Директору департамента | E15: штат | F15: новая | G15: 1 | H15: 1000000 | I15: 2 | J15: =IF(E15="штат",ROUND(Ставка_СН*H15*(1-Ставка_ОПВ-Ставка_ВОСМС)+Ставка_ОПВР*H15+Ставка_СО*MIN(H15*(1-Ставка_ОПВ),Кап_СО*МЗП)+Ставка_ООСМС*MIN(H15,Кап_ООСМС*МЗП),0),ROUND(H15*НДС,0)) -> 147550 | K15: =G15*(H15+J15) -> 1147550 | L15: =IF(AND(F15="новая",I15=1),Мес_2026_новые,MAX(0,4-I15)) -> 2 | M15: =K15*L15 -> 2295100 | N15: =IF(AND(E15="штат",F15="новая"),ОСНС_полис*G15/COUNTIFS($E$5:$E$36,"штат",$F$5:$F$36,"новая"),0) -> 33952.381 | O15: =M15+N15 -> 2329052.4 | P15: [Жандилдаев Бакдаулет] Проектный менеджер: координация регионов, взаимодействие с госорганами и общественными организациями. Опыт: исполнительный директор ОЮЛ «Конгресс молодежи Казахстана»; бакалавр «Государственное и местное управление» (КазУТБ), «Финансы» (Тұран-Астана), магистр юриспруденции («Синергия»). | Q15: 1
A16: 18 | B16: Департамент проектного управления и региональной координации | C16: Ведущий специалист | D16: Директору департамента | E16: штат | F16: новая | G16: 1 | H16: 1000000 | I16: 2 | J16: =IF(E16="штат",ROUND(Ставка_СН*H16*(1-Ставка_ОПВ-Ставка_ВОСМС)+Ставка_ОПВР*H16+Ставка_СО*MIN(H16*(1-Ставка_ОПВ),Кап_СО*МЗП)+Ставка_ООСМС*MIN(H16,Кап_ООСМС*МЗП),0),ROUND(H16*НДС,0)) -> 147550 | K16: =G16*(H16+J16) -> 1147550 | L16: =IF(AND(F16="новая",I16=1),Мес_2026_новые,MAX(0,4-I16)) -> 2 | M16: =K16*L16 -> 2295100 | N16: =IF(AND(E16="штат",F16="новая"),ОСНС_полис*G16/COUNTIFS($E$5:$E$36,"штат",$F$5:$F$36,"новая"),0) -> 33952.381 | O16: =M16+N16 -> 2329052.4 | P16: [Шербаева Бибинур] Проектный менеджер: ведение проектов календаря, планы и отчёты, взаимодействие с акиматами. Опыт: председатель ОСО «За будущее Казахстана»; бакалавр «Профессиональное обучение», магистр «Казахский язык и литература» (Казахский национальный женский педагогический университет). | Q16: 1
A17: 19 | B17: Департамент проектного управления и региональной координации | C17: Главный специалист | D17: Директору департамента | E17: штат | F17: новая | G17: 0 | H17: 1000000 | I17: 3 | J17: =IF(E17="штат",ROUND(Ставка_СН*H17*(1-Ставка_ОПВ-Ставка_ВОСМС)+Ставка_ОПВР*H17+Ставка_СО*MIN(H17*(1-Ставка_ОПВ),Кап_СО*МЗП)+Ставка_ООСМС*MIN(H17,Кап_ООСМС*МЗП),0),ROUND(H17*НДС,0)) -> 147550 | K17: =G17*(H17+J17) -> 0 | L17: =IF(AND(F17="новая",I17=1),Мес_2026_новые,MAX(0,4-I17)) -> 1 | M17: =K17*L17 -> 0 | N17: =IF(AND(E17="штат",F17="новая"),ОСНС_полис*G17/COUNTIFS($E$5:$E$36,"штат",$F$5:$F$36,"новая"),0) -> 0 | O17: =M17+N17 -> 0 | P17: [Арманов Р.] Ведение проектов и закреплённых регионов, мониторинг мероприятий
A18: 19 | B18: Департамент проектного управления и региональной координации | C18: Ведущий специалист | D18: Директору департамента | E18: штат | F18: новая | G18: 0 | H18: 700000 | I18: 3 | J18: =IF(E18="штат",ROUND(Ставка_СН*H18*(1-Ставка_ОПВ-Ставка_ВОСМС)+Ставка_ОПВР*H18+Ставка_СО*MIN(H18*(1-Ставка_ОПВ),Кап_СО*МЗП)+Ставка_ООСМС*MIN(H18,Кап_ООСМС*МЗП),0),ROUND(H18*НДС,0)) -> 112210 | K18: =G18*(H18+J18) -> 0 | L18: =IF(AND(F18="новая",I18=1),Мес_2026_новые,MAX(0,4-I18)) -> 1 | M18: =K18*L18 -> 0 | N18: =IF(AND(E18="штат",F18="новая"),ОСНС_полис*G18/COUNTIFS($E$5:$E$36,"штат",$F$5:$F$36,"новая"),0) -> 0 | O18: =M18+N18 -> 0 | P18: [Мирам А.] Ведение проектов и закреплённых регионов, сбор данных
A19: 19 | B19: Департамент проектного управления и региональной координации | C19: Ведущий специалист | D19: Директору департамента | E19: штат | F19: новая | G19: 1 | H19: 700000 | I19: 2 | J19: =IF(E19="штат",ROUND(Ставка_СН*H19*(1-Ставка_ОПВ-Ставка_ВОСМС)+Ставка_ОПВР*H19+Ставка_СО*MIN(H19*(1-Ставка_ОПВ),Кап_СО*МЗП)+Ставка_ООСМС*MIN(H19,Кап_ООСМС*МЗП),0),ROUND(H19*НДС,0)) -> 112210 | K19: =G19*(H19+J19) -> 812210 | L19: =IF(AND(F19="новая",I19=1),Мес_2026_новые,MAX(0,4-I19)) -> 2 | M19: =K19*L19 -> 1624420 | N19: =IF(AND(E19="штат",F19="новая"),ОСНС_полис*G19/COUNTIFS($E$5:$E$36,"штат",$F$5:$F$36,"новая"),0) -> 33952.381 | O19: =M19+N19 -> 1658372.4 | P19: [Тулесова А.] Ведение проектов и закреплённых регионов, мониторинг мероприятий, отчётность
A20: 23 | B20: Департамент цифрового развития | C20: Руководитель департамента | D20: Руководителю проектного офиса «Таза Қазақстан» | E20: штат | F20: новая | G20: 1 | H20: 1300000 | I20: 2 | J20: =IF(E20="штат",ROUND(Ставка_СН*H20*(1-Ставка_ОПВ-Ставка_ВОСМС)+Ставка_ОПВР*H20+Ставка_СО*MIN(H20*(1-Ставка_ОПВ),Кап_СО*МЗП)+Ставка_ООСМС*MIN(H20,Кап_ООСМС*МЗП),0),ROUND(H20*НДС,0)) -> 182890 | K20: =G20*(H20+J20) -> 1482890 | L20: =IF(AND(F20="новая",I20=1),Мес_2026_новые,MAX(0,4-I20)) -> 2 | M20: =K20*L20 -> 2965780 | N20: =IF(AND(E20="штат",F20="новая"),ОСНС_полис*G20/COUNTIFS($E$5:$E$36,"штат",$F$5:$F$36,"новая"),0) -> 33952.381 | O20: =M20+N20 -> 2999732.4 | P20: [Тастан Нұрбол] IT-специалист: платформа TAZA.KZ, цифровой мониторинг, информационная безопасность, работа с подрядчиком платформы. Опыт: советник председателя по информационной безопасности НАО «ННПЦ Тіл-Қазына»; бакалавр «Вычислительная техника и программное обеспечение» (ЕНУ им. Л.Н. Гумилёва), магистр юриспруденции. | Q20: 1
A21: 24 | B21: Департамент цифрового развития | C21: Разработчик (ИИ, ГИС), платформа — аутсорс | D21: Руководителю департамента | E21: аутсорс | F21: новая | G21: 0 | H21: 1000000 | I21: 2 | J21: =IF(E21="штат",ROUND(Ставка_СН*H21*(1-Ставка_ОПВ-Ставка_ВОСМС)+Ставка_ОПВР*H21+Ставка_СО*MIN(H21*(1-Ставка_ОПВ),Кап_СО*МЗП)+Ставка_ООСМС*MIN(H21,Кап_ООСМС*МЗП),0),ROUND(H21*НДС,0)) -> 160000 | K21: =G21*(H21+J21) -> 0 | L21: =IF(AND(F21="новая",I21=1),Мес_2026_новые,MAX(0,4-I21)) -> 2 | M21: =K21*L21 -> 0 | N21: =IF(AND(E21="штат",F21="новая"),ОСНС_полис*G21/COUNTIFS($E$5:$E$36,"штат",$F$5:$F$36,"новая"),0) -> 0 | O21: =M21+N21 -> 0 | P21: [аутсорс] Разработка и сопровождение ИИ- и ГИС-инструментов, цифровой платформы
A22: 25 | B22: Группа «Коммуникация и креатив» | C22: Руководитель группы | D22: Руководителю проектного офиса «Таза Қазақстан» | E22: штат | F22: новая | G22: 1 | H22: 1300000 | I22: 2 | J22: =IF(E22="штат",ROUND(Ставка_СН*H22*(1-Ставка_ОПВ-Ставка_ВОСМС)+Ставка_ОПВР*H22+Ставка_СО*MIN(H22*(1-Ставка_ОПВ),Кап_СО*МЗП)+Ставка_ООСМС*MIN(H22,Кап_ООСМС*МЗП),0),ROUND(H22*НДС,0)) -> 182890 | K22: =G22*(H22+J22) -> 1482890 | L22: =IF(AND(F22="новая",I22=1),Мес_2026_новые,MAX(0,4-I22)) -> 2 | M22: =K22*L22 -> 2965780 | N22: =IF(AND(E22="штат",F22="новая"),ОСНС_полис*G22/COUNTIFS($E$5:$E$36,"штат",$F$5:$F$36,"новая"),0) -> 33952.381 | O22: =M22+N22 -> 2999732.4 | P22: [Сағынұлы С.] Коммуникационная стратегия, медиаплан, работа со СМИ
A23: 26 | B23: Группа «Коммуникация и креатив» | C23: Главный специалист — PR, пресс-секретарь | D23: Руководителю группы | E23: штат | F23: новая | G23: 1 | H23: 1000000 | I23: 2 | J23: =IF(E23="штат",ROUND(Ставка_СН*H23*(1-Ставка_ОПВ-Ставка_ВОСМС)+Ставка_ОПВР*H23+Ставка_СО*MIN(H23*(1-Ставка_ОПВ),Кап_СО*МЗП)+Ставка_ООСМС*MIN(H23,Кап_ООСМС*МЗП),0),ROUND(H23*НДС,0)) -> 147550 | K23: =G23*(H23+J23) -> 1147550 | L23: =IF(AND(F23="новая",I23=1),Мес_2026_новые,MAX(0,4-I23)) -> 2 | M23: =K23*L23 -> 2295100 | N23: =IF(AND(E23="штат",F23="новая"),ОСНС_полис*G23/COUNTIFS($E$5:$E$36,"штат",$F$5:$F$36,"новая"),0) -> 33952.381 | O23: =M23+N23 -> 2329052.4 | P23: [Талғат Айман] PR-менеджер: пресс-служба, тексты и материалы для СМИ и соцсетей. Опыт: ведущий специалист КФ «Фонд развития креативных индустрий»; бакалавр журналистики (ЕНУ им. Л.Н. Гумилёва). | Q23: 1
A24: 27 | B24: Группа «Коммуникация и креатив» | C24: Режиссёр, видеограф-монтажёр — аутсорс | D24: Руководителю группы | E24: аутсорс | F24: новая | G24: 0 | H24: 1000000 | I24: 2 | J24: =IF(E24="штат",ROUND(Ставка_СН*H24*(1-Ставка_ОПВ-Ставка_ВОСМС)+Ставка_ОПВР*H24+Ставка_СО*MIN(H24*(1-Ставка_ОПВ),Кап_СО*МЗП)+Ставка_ООСМС*MIN(H24,Кап_ООСМС*МЗП),0),ROUND(H24*НДС,0)) -> 160000 | K24: =G24*(H24+J24) -> 0 | L24: =IF(AND(F24="новая",I24=1),Мес_2026_новые,MAX(0,4-I24)) -> 2 | M24: =K24*L24 -> 0 | N24: =IF(AND(E24="штат",F24="новая"),ОСНС_полис*G24/COUNTIFS($E$5:$E$36,"штат",$F$5:$F$36,"новая"),0) -> 0 | O24: =M24+N24 -> 0 | P24: [аутсорс] Съёмка и монтаж видео, ролики
A25: 28 | B25: Группа «Коммуникация и креатив» | C25: Копирайтер — аутсорс | D25: Руководителю группы | E25: аутсорс | F25: новая | G25: 0 | H25: 700000 | I25: 2 | J25: =IF(E25="штат",ROUND(Ставка_СН*H25*(1-Ставка_ОПВ-Ставка_ВОСМС)+Ставка_ОПВР*H25+Ставка_СО*MIN(H25*(1-Ставка_ОПВ),Кап_СО*МЗП)+Ставка_ООСМС*MIN(H25,Кап_ООСМС*МЗП),0),ROUND(H25*НДС,0)) -> 112000 | K25: =G25*(H25+J25) -> 0 | L25: =IF(AND(F25="новая",I25=1),Мес_2026_новые,MAX(0,4-I25)) -> 2 | M25: =K25*L25 -> 0 | N25: =IF(AND(E25="штат",F25="новая"),ОСНС_полис*G25/COUNTIFS($E$5:$E$36,"штат",$F$5:$F$36,"новая"),0) -> 0 | O25: =M25+N25 -> 0 | P25: [аутсорс] Тексты для соцсетей, сайта, СМИ
A26: 29 | B26: Группа «Коммуникация и креатив» | C26: Ведущий специалист — дизайнер | D26: Руководителю группы | E26: штат | F26: новая | G26: 1 | H26: 700000 | I26: 2 | J26: =IF(E26="штат",ROUND(Ставка_СН*H26*(1-Ставка_ОПВ-Ставка_ВОСМС)+Ставка_ОПВР*H26+Ставка_СО*MIN(H26*(1-Ставка_ОПВ),Кап_СО*МЗП)+Ставка_ООСМС*MIN(H26,Кап_ООСМС*МЗП),0),ROUND(H26*НДС,0)) -> 112210 | K26: =G26*(H26+J26) -> 812210 | L26: =IF(AND(F26="новая",I26=1),Мес_2026_новые,MAX(0,4-I26)) -> 2 | M26: =K26*L26 -> 1624420 | N26: =IF(AND(E26="штат",F26="новая"),ОСНС_полис*G26/COUNTIFS($E$5:$E$36,"штат",$F$5:$F$36,"новая"),0) -> 33952.381 | O26: =M26+N26 -> 1658372.4 | P26: [Найла] Визуалы, инфографика, макеты, фирменный стиль | Q26: 1
A27: 30 | B27: Группа «Коммуникация и креатив» | C27: Ведущий специалист — фотограф, рилсмейкер | D27: Руководителю группы | E27: штат | F27: новая | G27: 1 | H27: 1000000 | I27: 2 | J27: =IF(E27="штат",ROUND(Ставка_СН*H27*(1-Ставка_ОПВ-Ставка_ВОСМС)+Ставка_ОПВР*H27+Ставка_СО*MIN(H27*(1-Ставка_ОПВ),Кап_СО*МЗП)+Ставка_ООСМС*MIN(H27,Кап_ООСМС*МЗП),0),ROUND(H27*НДС,0)) -> 147550 | K27: =G27*(H27+J27) -> 1147550 | L27: =IF(AND(F27="новая",I27=1),Мес_2026_новые,MAX(0,4-I27)) -> 2 | M27: =K27*L27 -> 2295100 | N27: =IF(AND(E27="штат",F27="новая"),ОСНС_полис*G27/COUNTIFS($E$5:$E$36,"штат",$F$5:$F$36,"новая"),0) -> 33952.381 | O27: =M27+N27 -> 2329052.4 | P27: [Жумабай Б.] Фотосъёмка, короткие видео
A28: 31 | B28: Группа «Коммуникация и креатив» | C28: Ведущий специалист — менеджер по блогерам | D28: Руководителю группы | E28: штат | F28: новая | G28: 1 | H28: 700000 | I28: 2 | J28: =IF(E28="штат",ROUND(Ставка_СН*H28*(1-Ставка_ОПВ-Ставка_ВОСМС)+Ставка_ОПВР*H28+Ставка_СО*MIN(H28*(1-Ставка_ОПВ),Кап_СО*МЗП)+Ставка_ООСМС*MIN(H28,Кап_ООСМС*МЗП),0),ROUND(H28*НДС,0)) -> 112210 | K28: =G28*(H28+J28) -> 812210 | L28: =IF(AND(F28="новая",I28=1),Мес_2026_новые,MAX(0,4-I28)) -> 2 | M28: =K28*L28 -> 1624420 | N28: =IF(AND(E28="штат",F28="новая"),ОСНС_полис*G28/COUNTIFS($E$5:$E$36,"штат",$F$5:$F$36,"новая"),0) -> 33952.381 | O28: =M28+N28 -> 1658372.4 | P28: [Дутбаева] Работа с блогерами и лидерами мнений
A29: 32 | B29: Группа «Коммуникация и креатив» | C29: Менеджер по креаторам и креативным проектам — аутсорс | D29: Руководителю группы | E29: аутсорс | F29: новая | G29: 0 | H29: 700000 | I29: 2 | J29: =IF(E29="штат",ROUND(Ставка_СН*H29*(1-Ставка_ОПВ-Ставка_ВОСМС)+Ставка_ОПВР*H29+Ставка_СО*MIN(H29*(1-Ставка_ОПВ),Кап_СО*МЗП)+Ставка_ООСМС*MIN(H29,Кап_ООСМС*МЗП),0),ROUND(H29*НДС,0)) -> 112000 | K29: =G29*(H29+J29) -> 0 | L29: =IF(AND(F29="новая",I29=1),Мес_2026_новые,MAX(0,4-I29)) -> 2 | M29: =K29*L29 -> 0 | N29: =IF(AND(E29="штат",F29="новая"),ОСНС_полис*G29/COUNTIFS($E$5:$E$36,"штат",$F$5:$F$36,"новая"),0) -> 0 | O29: =M29+N29 -> 0 | P29: [аутсорс] Работа с креаторами, креативные проекты
A30: 33 | B30: Административный персонал | C30: Финансовый директор | D30: ГИД | E30: штат | F30: действующий | G30: 1 | H30: 1400000 | I30: 2 | J30: =IF(E30="штат",ROUND(Ставка_СН*H30*(1-Ставка_ОПВ-Ставка_ВОСМС)+Ставка_ОПВР*H30+Ставка_СО*MIN(H30*(1-Ставка_ОПВ),Кап_СО*МЗП)+Ставка_ООСМС*MIN(H30,Кап_ООСМС*МЗП),0),ROUND(H30*НДС,0)) -> 194670 | K30: =G30*(H30+J30) -> 1594670 | L30: =IF(AND(F30="новая",I30=1),Мес_2026_новые,MAX(0,4-I30)) -> 2 | M30: =K30*L30 -> 3189340 | N30: =IF(AND(E30="штат",F30="новая"),ОСНС_полис*G30/COUNTIFS($E$5:$E$36,"штат",$F$5:$F$36,"новая"),0) -> 0 | O30: =M30+N30 -> 3189340 | P30: [Оразбаева М.К.] Бюджет проекта, раздельный учёт, работа со спонсорами, финансовая отчётность, налоги. Опыт: 30+ лет в финансах, бухгалтерском и налоговом учёте – главный бухгалтер АО «Международный аэропорт Нурсултан Назарбаев», аудит BDO Qazaqstan (МФЦА); профессиональный бухгалтер РК, ДипИФР ACCA, налоговый консультант.
A31: 34 | B31: Административный персонал | C31: Бухгалтер | D31: Финансовому директору | E31: штат | F31: новая | G31: 1 | H31: 700000 | I31: 2 | J31: =IF(E31="штат",ROUND(Ставка_СН*H31*(1-Ставка_ОПВ-Ставка_ВОСМС)+Ставка_ОПВР*H31+Ставка_СО*MIN(H31*(1-Ставка_ОПВ),Кап_СО*МЗП)+Ставка_ООСМС*MIN(H31,Кап_ООСМС*МЗП),0),ROUND(H31*НДС,0)) -> 112210 | K31: =G31*(H31+J31) -> 812210 | L31: =IF(AND(F31="новая",I31=1),Мес_2026_новые,MAX(0,4-I31)) -> 2 | M31: =K31*L31 -> 1624420 | N31: =IF(AND(E31="штат",F31="новая"),ОСНС_полис*G31/COUNTIFS($E$5:$E$36,"штат",$F$5:$F$36,"новая"),0) -> 33952.381 | O31: =M31+N31 -> 1658372.4 | P31: [вакансия] Первичные документы, платежи, зарплата, авансовые отчёты, учёт основных средств
A32: 35 | B32: Проектный офис для Центральной Азии по изменению климата и зеленой энергетике | C32: Заместитель руководителя ПО для ЦА | D32: ГИД (Руководитель Проектного офиса для Центральной Азии) | E32: штат | F32: новая | G32: 1 | H32: 1000000 | I32: 2 | J32: =IF(E32="штат",ROUND(Ставка_СН*H32*(1-Ставка_ОПВ-Ставка_ВОСМС)+Ставка_ОПВР*H32+Ставка_СО*MIN(H32*(1-Ставка_ОПВ),Кап_СО*МЗП)+Ставка_ООСМС*MIN(H32,Кап_ООСМС*МЗП),0),ROUND(H32*НДС,0)) -> 147550 | K32: =G32*(H32+J32) -> 1147550 | L32: =IF(AND(F32="новая",I32=1),Мес_2026_новые,MAX(0,4-I32)) -> 2 | M32: =K32*L32 -> 2295100 | N32: =IF(AND(E32="штат",F32="новая"),ОСНС_полис*G32/COUNTIFS($E$5:$E$36,"штат",$F$5:$F$36,"новая"),0) -> 33952.381 | O32: =M32+N32 -> 2329052.4 | P32: Международные и страновые проекты Фонда
A33: 35 | B33: Проектный офис для Центральной Азии по изменению климата и зеленой энергетике | C33: Менеджер проектов | D33: ГИД (Руководитель Проектного офиса для Центральной Азии) | E33: штат | F33: новая | G33: 1 | H33: 800000 | I33: 2 | J33: =IF(E33="штат",ROUND(Ставка_СН*H33*(1-Ставка_ОПВ-Ставка_ВОСМС)+Ставка_ОПВР*H33+Ставка_СО*MIN(H33*(1-Ставка_ОПВ),Кап_СО*МЗП)+Ставка_ООСМС*MIN(H33,Кап_ООСМС*МЗП),0),ROUND(H33*НДС,0)) -> 123990 | K33: =G33*(H33+J33) -> 923990 | L33: =IF(AND(F33="новая",I33=1),Мес_2026_новые,MAX(0,4-I33)) -> 2 | M33: =K33*L33 -> 1847980 | N33: =IF(AND(E33="штат",F33="новая"),ОСНС_полис*G33/COUNTIFS($E$5:$E$36,"штат",$F$5:$F$36,"новая"),0) -> 33952.381 | O33: =M33+N33 -> 1881932.4 | P33: [Загирова Анастасия] Экологическая экспертиза, данные о состоянии окружающей среды, методические материалы
A34: 35 | B34: Проектный офис для Центральной Азии по изменению климата и зеленой энергетике | C34: Менеджер проектов | D34: ГИД (Руководитель Проектного офиса для Центральной Азии) | E34: штат | F34: новая | G34: 1 | H34: 800000 | I34: 2 | J34: =IF(E34="штат",ROUND(Ставка_СН*H34*(1-Ставка_ОПВ-Ставка_ВОСМС)+Ставка_ОПВР*H34+Ставка_СО*MIN(H34*(1-Ставка_ОПВ),Кап_СО*МЗП)+Ставка_ООСМС*MIN(H34,Кап_ООСМС*МЗП),0),ROUND(H34*НДС,0)) -> 123990 | K34: =G34*(H34+J34) -> 923990 | L34: =IF(AND(F34="новая",I34=1),Мес_2026_новые,MAX(0,4-I34)) -> 2 | M34: =K34*L34 -> 1847980 | N34: =IF(AND(E34="штат",F34="новая"),ОСНС_полис*G34/COUNTIFS($E$5:$E$36,"штат",$F$5:$F$36,"новая"),0) -> 33952.381 | O34: =M34+N34 -> 1881932.4 | P34: [Абулхан А.] Молодёжь, волонтёры, НПО, школы и вузы; экспертиза молодёжных и общественных проектов
A35: 36 | B35: Административный персонал | C35: Юрист (МФЦА) — аутсорс | D35: Заместителю ГИД (адм.-хоз.) | E35: аутсорс | F35: новая | G35: 0 | H35: 867500 | I35: 2 | J35: =IF(E35="штат",ROUND(Ставка_СН*H35*(1-Ставка_ОПВ-Ставка_ВОСМС)+Ставка_ОПВР*H35+Ставка_СО*MIN(H35*(1-Ставка_ОПВ),Кап_СО*МЗП)+Ставка_ООСМС*MIN(H35,Кап_ООСМС*МЗП),0),ROUND(H35*НДС,0)) -> 138800 | K35: =G35*(H35+J35) -> 0 | L35: =IF(AND(F35="новая",I35=1),Мес_2026_новые,MAX(0,4-I35)) -> 2 | M35: =K35*L35 -> 0 | N35: =IF(AND(E35="штат",F35="новая"),ОСНС_полис*G35/COUNTIFS($E$5:$E$36,"штат",$F$5:$F$36,"новая"),0) -> 0 | O35: =M35+N35 -> 0 | P35: [аутсорс] Договоры и соглашения, право МФЦА, сопровождение закупок и кадровых документов
A36: 37 | B36: Административный персонал | C36: Администратор (сис.админ) — аутсорс | D36: Заместителю ГИД (адм.-хоз.) | E36: аутсорс | F36: новая | G36: 0 | H36: 425600 | I36: 2 | J36: =IF(E36="штат",ROUND(Ставка_СН*H36*(1-Ставка_ОПВ-Ставка_ВОСМС)+Ставка_ОПВР*H36+Ставка_СО*MIN(H36*(1-Ставка_ОПВ),Кап_СО*МЗП)+Ставка_ООСМС*MIN(H36,Кап_ООСМС*МЗП),0),ROUND(H36*НДС,0)) -> 68096 | K36: =G36*(H36+J36) -> 0 | L36: =IF(AND(F36="новая",I36=1),Мес_2026_новые,MAX(0,4-I36)) -> 2 | M36: =K36*L36 -> 0 | N36: =IF(AND(E36="штат",F36="новая"),ОСНС_полис*G36/COUNTIFS($E$5:$E$36,"штат",$F$5:$F$36,"новая"),0) -> 0 | O36: =M36+N36 -> 0 | P36: [аутсорс] ИТ-инфраструктура, сеть и техника; делопроизводство, хоз. администрирование, ассистирование
C37: ИТОГО (штат) | G37: =SUM(G5:G36) -> 23 | H37: =SUMPRODUCT(G5:G36,H5:H36) -> 24600000 | K37: =SUM(K5:K36) -> 28182130 | M37: =SUM(M5:M36) -> 54881370 | N37: =SUM(N5:N36) -> 645095.24 | O37: =SUM(O5:O36) -> 55526465
C38: в т.ч. проектный офис | G38: =SUM(G8:G12)+SUM(G13:G29) -> 15 | H38: =SUMPRODUCT(G8:G12,H8:H12)+SUMPRODUCT(G13:G29,H13:H29) -> 15500000
C39: в т.ч. Фонд | G39: =G37-G38 -> 8 | H39: =H37-H38 -> 9100000
C41: Премия по итогам работы в октябре 2026 года (выплата в декабре)
C42: База: оклады 8 работников проектного офиса «Таза Қазақстан» (столбец Q) за один месяц, гросс | H42: =SUMPRODUCT(Q5:Q36,H5:H36) -> 8400000
C43: Отчисления работодателя на премию (ОПВР 3,5% + ООСМС 3% + СН 6% от дохода за вычетом ОПВ и ВОСМС) | H43: =H42*(Ставка_ОПВР+Ставка_ООСМС+Ставка_СН*(1-Ставка_ОПВ-Ставка_ВОСМС)) -> 989520
...

Sheet Аутсорс
A1: Аутсорс-услуги: расчёт на октябрь–декабрь 2026 года, ₸
A3: № | B3: Позиция | C3: Подчиняется | D3: Функции | E3: Ставка в мес. без НДС | F3: Вознаграждение Antal 10%, ₸/мес | G3: Стоимость с вознаграждением, ₸/мес без НДС | H3: НДС 16% | I3: В мес. с НДС | J3: Старт (1 – октябрь, 2 – ноябрь, 3 – декабрь) | K3: Мес. 2026 | L3: Окт–дек 2026
A4: 1 | B4: Юрист (МФЦА), на руки 700 000 | C4: Заместителю ГИД (адм.-хоз.) | D4: Договоры и соглашения, право МФЦА, сопровождение закупок и кадровых документов | E4: 867500 | F4: =ROUND(E4*'Комиссия Antal'!$B$4,0) -> 86750 | G4: =E4+F4 -> 954250 | H4: =ROUND(G4*НДС,0) -> 152680 | I4: =G4+H4 -> 1106930 | J4: 2 | K4: =IF(J4=1,Мес_2026_новые,MAX(0,4-J4)) -> 2 | L4: =I4*K4 -> 2213860
A5: 2 | B5: Администратор (сис.админ), на руки 350 000 | C5: Заместителю ГИД (адм.-хоз.) | D5: ИТ-инфраструктура, сеть и техника; делопроизводство, хоз. администрирование, ассистирование | E5: 425600 | F5: =ROUND(E5*'Комиссия Antal'!$B$4,0) -> 42560 | G5: =E5+F5 -> 468160 | H5: =ROUND(G5*НДС,0) -> 74906 | I5: =G5+H5 -> 543066 | J5: 2 | K5: =IF(J5=1,Мес_2026_новые,MAX(0,4-J5)) -> 2 | L5: =I5*K5 -> 1086132
A6: 3 | B6: Разработчик (ИИ, ГИС), платформа | C6: Руководителю цифрового развития | D6: Разработка и сопровождение ИИ- и ГИС-инструментов, цифровой платформы | E6: 1000000 | F6: =ROUND(E6*'Комиссия Antal'!$B$4,0) -> 100000 | G6: =E6+F6 -> 1100000 | H6: =ROUND(G6*НДС,0) -> 176000 | I6: =G6+H6 -> 1276000 | J6: 2 | K6: =IF(J6=1,Мес_2026_новые,MAX(0,4-J6)) -> 2 | L6: =I6*K6 -> 2552000
A7: 4 | B7: Режиссёр, видеограф-монтажёр | C7: Руководителю группы «Коммуникация и креатив» | D7: Съёмка и монтаж видео, ролики | E7: 1000000 | F7: =ROUND(E7*'Комиссия Antal'!$B$4,0) -> 100000 | G7: =E7+F7 -> 1100000 | H7: =ROUND(G7*НДС,0) -> 176000 | I7: =G7+H7 -> 1276000 | J7: 2 | K7: =IF(J7=1,Мес_2026_новые,MAX(0,4-J7)) -> 2 | L7: =I7*K7 -> 2552000
A8: 5 | B8: Копирайтер | C8: Руководителю группы «Коммуникация и креатив» | D8: Тексты для соцсетей, сайта, СМИ | E8: 700000 | F8: =ROUND(E8*'Комиссия Antal'!$B$4,0) -> 70000 | G8: =E8+F8 -> 770000 | H8: =ROUND(G8*НДС,0) -> 123200 | I8: =G8+H8 -> 893200 | J8: 2 | K8: =IF(J8=1,Мес_2026_новые,MAX(0,4-J8)) -> 2 | L8: =I8*K8 -> 1786400
A9: 6 | B9: Социолог (Нурканат А.) | C9: Руководителю департамента социологии | D9: Опросы и полевые работы, обработка данных | E9: 700000 | F9: =ROUND(E9*'Комиссия Antal'!$B$4,0) -> 70000 | G9: =E9+F9 -> 770000 | H9: =ROUND(G9*НДС,0) -> 123200 | I9: =G9+H9 -> 893200 | J9: 2 | K9: =IF(J9=1,Мес_2026_новые,MAX(0,4-J9)) -> 2 | L9: =I9*K9 -> 1786400
A10: 7 | B10: Менеджер по креаторам и креативным проектам | C10: Руководителю группы «Коммуникация и креатив» | D10: Работа с креаторами, креативные проекты | E10: 700000 | F10: =ROUND(E10*'Комиссия Antal'!$B$4,0) -> 70000 | G10: =E10+F10 -> 770000 | H10: =ROUND(G10*НДС,0) -> 123200 | I10: =G10+H10 -> 893200 | J10: 2 | K10: =IF(J10=1,Мес_2026_новые,MAX(0,4-J10)) -> 2 | L10: =I10*K10 -> 1786400
B11: ИТОГО аутсорс | E11: =SUM(E4:E10) -> 5393100 | F11: =SUM(F4:F10) -> 539310 | G11: =SUM(G4:G10) -> 5932410 | H11: =SUM(H4:H10) -> 949186 | I11: =SUM(I4:I10) -> 6881596 | L11: =SUM(L4:L10) -> 13763192
B12: Вознаграждение Antal – 10% от суммы «зарплата и налоги работодателя» (п. 6.1 договора), ставка берётся с листа «Комиссия Antal», ячейка B4. НДС 16% начисляется на стоимость вместе с вознаграждением по всем специалистам: решение 24.10.2026 – все оформляются через Antal Kazakhstan, ТОО на общеустановленном режиме и плательщик НДС.

Sheet Комиссия Antal
A1: Вознаграждение Antal Kazakhstan за аутстаффинг: сколько Фонд платит за посредничество
A2: Источник – КП «Аутстаффинг» для ЦАКФ и проект договора (п. 6.1): вознаграждение 10% не от оклада, а от «окончательной суммы» – фонда оплаты труда вместе с налогами работодателя; НДС начисляется сверху на всё, включая само вознаграждение. Ставки налогов берутся с листа «Параметры».
A4: Ставка вознаграждения Antal | B4: 0.1 | C4: п. 6.1 договора; фиксируется на срок контракта 3 года
A5: Эффективная ставка налогов работодателя | B5: =Ставка_ОПВР+Ставка_ООСМС+Ставка_СН*(1-Ставка_ОПВ-Ставка_ВОСМС) -> 0.1178 | C5: ОПВР + ООСМС + социальный налог от дохода за вычетом ОПВ и ВОСМС. Социальные отчисления не прибавляются: на них уменьшается социальный налог и при окладе выше 564 тыс. ₸ они гасятся полностью
A7: Оклад начисленный (гросс), ₸/мес | B7: Налоги работодателя, ₸ | C7: База вознаграждения, ₸ | D7: Вознаграждение Antal, ₸ | E7: НДС на вознаграждение, ₸ | F7: Вознаграждение с НДС, ₸ | G7: Без НДС, % от оклада
A8: 500000 | B8: =A8*$B$5 -> 58900 | C8: =A8+B8 -> 558900 | D8: =C8*$B$4 -> 55890 | E8: =D8*НДС -> 8942.4 | F8: =D8+E8 -> 64832.4 | G8: =D8/A8 -> 0.11178
A9: 700000 | B9: =A9*$B$5 -> 82460 | C9: =A9+B9 -> 782460 | D9: =C9*$B$4 -> 78246 | E9: =D9*НДС -> 12519.36 | F9: =D9+E9 -> 90765.36 | G9: =D9/A9 -> 0.11178
A10: 813286 | B10: =A10*$B$5 -> 95805.091 | C10: =A10+B10 -> 909091.09 | D10: =C10*$B$4 -> 90909.109 | E10: =D10*НДС -> 14545.457 | F10: =D10+E10 -> 105454.57 | G10: =D10/A10 -> 0.11178
A11: 1000000 | B11: =A11*$B$5 -> 117800 | C11: =A11+B11 -> 1117800 | D11: =C11*$B$4 -> 111780 | E11: =D11*НДС -> 17884.8 | F11: =D11+E11 -> 129664.8 | G11: =D11/A11 -> 0.11178
A13: Правило в одну строку
A14: Вознаграждение без НДС, % от оклада | B14: =$B$4*(1+$B$5) -> 0.11178 | C14: Реальные расходы Фонда: входной НДС берётся в зачёт
A15: Вознаграждение с НДС, % от оклада | B15: =$B$4*(1+$B$5)*(1+НДС) -> 0.1296648 | C15: Столько видно в счёте Antal
A17: Вознаграждение Antal по аутсорс-блоку бюджета (лист «Аутсорс», октябрь–декабрь 2026)
A18: Вознаграждение Antal по аутсорс-блоку бюджета (лист «Аутсорс», колонка «Вознаграждение Antal 10%»)
A19: Стоимость специалистов (зарплата и налоги), ₸/мес | B19: =Аутсорс!E11 -> 5393100
A20: Вознаграждение Antal, ₸/мес без НДС | B20: =Аутсорс!F11 -> 539310
A21: Вознаграждение Antal за квартал без НДС, ₸ | B21: =Аутсорс!F11*2 -> 1078620
A22: Вознаграждение Antal за квартал с НДС, ₸ | B22: =B21*(1+НДС) -> 1251199.2
A23: Аутсорс за период всего с вознаграждением и НДС, ₸ | B23: =Аутсорс!L11 -> 13763192
A25: Вознаграждение посчитано по каждому аутсорс-специалисту на листе «Аутсорс», колонка F. Подробный расчёт с рекрутингом – D:\Закупки\1 Процедуры закупок\9 Реестры и списки\Расчёт – аутстаффинг через Antal по тарифам КП (проект 2026-10-23).xlsx

Sheet Командировки
A1: Командировки по РК на октябрь–декабрь 2026 года, ₸
A2: Нормы поездок — на человека; стоимость поездки — лист «Параметры»; количество и старт — с листа «Штат».
A4: Роль | B4: Строка «Штат» | C4: Кол-во чел. | D4: Поездок по РК в год на чел. | E4: Выездов по макрорегиону в мес. на чел. | F4: Мес. 2026 (поездки – с ноября) | G4: Окт–дек 2026
A5: =Штат!C5 -> Главный исполнительный директор (ГИД) | C5: =Штат!G5 -> 1 | D5: 4 | E5: 0 | F5: =MIN(2,Штат!L5) -> 2 | G5: =C5*(D5/12*F5*Поездка_РК+E5*F5*Поездка_местн) -> 127300
A6: =Штат!C6 -> Советник ГИД по стратегии и науке | C6: =Штат!G6 -> 1 | D6: 6 | E6: 0 | F6: =MIN(2,Штат!L6) -> 2 | G6: =C6*(D6/12*F6*Поездка_РК+E6*F6*Поездка_местн) -> 190950
A7: =Штат!C8 -> Руководитель проектного офиса «Таза Қазақстан» | C7: =Штат!G8 -> 1 | D7: 10 | E7: 0 | F7: =MIN(2,Штат!L8) -> 2 | G7: =C7*(D7/12*F7*Поездка_РК+E7*F7*Поездка_местн) -> 318250
A8: Департамент социологических исследований и аналитики (3 чел.) | C8: =SUMIFS(Штат!$G$5:$G$36,Штат!$B$5:$B$36,"Департамент социологических*",Штат!$E$5:$E$36,"штат") -> 3 | D8: 3 | E8: 3 | F8: =MIN(2,IF(C8>0,SUMIFS(Штат!$L$5:$L$36,Штат!$B$5:$B$36,"Департамент социологических*",Штат!$E$5:$E$36,"штат")/C8,0)) -> 1.6666667 | G8: =C8*(D8/12*F8*Поездка_РК+E8*F8*Поездка_местн) -> 593437.5
A9: Департамент проектного управления и региональной координации (5 чел.) | C9: =SUMIFS(Штат!$G$5:$G$36,Штат!$B$5:$B$36,"Департамент проектного управления*",Штат!$E$5:$E$36,"штат") -> 5 | D9: 6 | E9: 0 | F9: =MIN(2,IF(C9>0,SUMIFS(Штат!$L$5:$L$36,Штат!$B$5:$B$36,"Департамент проектного управления*",Штат!$E$5:$E$36,"штат")/C9,0)) -> 2 | G9: =C9*(D9/12*F9*Поездка_РК+E9*F9*Поездка_местн) -> 954750
A10: Департамент цифрового развития (1 чел., разработчик — аутсорс) | C10: =SUM(Штат!G20:G21) -> 1 | D10: 1 | E10: 0 | F10: =MIN(2,Штат!L20) -> 2 | G10: =C10*(D10/12*F10*Поездка_РК+E10*F10*Поездка_местн) -> 31825
A11: Группа «Коммуникация и креатив» (5 чел.): съёмки и освещение мероприятий в регионах | C11: =SUM(Штат!G22:G29) -> 5 | D11: 4 | E11: 4 | F11: =MIN(2,Штат!L22) -> 2 | G11: =C11*(D11/12*F11*Поездка_РК+E11*F11*Поездка_местн) -> 1582500
A12: ИТОГО | G12: =SUM(G5:G11) -> 3799012.5

Sheet Оснащение и офис
A1: Оснащение, офис, цифровые инструменты и медиа на октябрь–декабрь 2026 года, ₸
A2: Тип: разово – в месяц старта; мес – ежемесячно с месяца старта; год – годовая сумма × 3/12.
A4: Раздел | B4: Статья | C4: Ед. | D4: Кол-во | E4: Цена, ₸ | F4: Тип | G4: Старт (1 – октябрь) | I4: Окт–дек 2026 | J4: Ноябрь 2026 | K4: Декабрь 2026 | L4: Январь 2027 | M4: Месяц оплаты разовых (11 / 12)
A5: Оснащение | B5: Ноутбук стандартный (Core i5 / Ryzen 5, 16 ГБ, SSD 512 ГБ) | C5: шт. | D5: 4 | E5: 450000 | F5: разово | G5: 1 | I5: =IF(F5="разово",IF(G5<=3,D5*E5,0),IF(F5="мес",D5*E5*MAX(0,4-G5),D5*E5*MAX(0,4-G5)/12)) -> 1800000 | J5: =IF($F5="разово",IF($M5=12,0,$I5),IF($F5="мес",$D5*$E5*(($G5<=1)+($G5<=2)),IF($F5="год",$D5*$E5/12*(($G5<=1)+($G5<=2)),$I5/2))) -> 1800000 | K5: =IF($F5="разово",IF($M5=12,$I5,0),IF($F5="мес",$D5*$E5*($G5<=3),IF($F5="год",$D5*$E5/12*($G5<=3),$I5/2))) -> 0 | L5: =IF($F5="разово",0,IF($F5="мес",$D5*$E5*($G5<=3),IF($F5="год",$D5*$E5/12*($G5<=3),$I5/2))) -> 0 | M5: 11
A6: Оснащение | B6: Ноутбук производительный | C6: шт. | D6: 1 | E6: 900000 | F6: разово | G6: 1 | I6: =IF(F6="разово",IF(G6<=3,D6*E6,0),IF(F6="мес",D6*E6*MAX(0,4-G6),D6*E6*MAX(0,4-G6)/12)) -> 900000 | J6: =IF($F6="разово",IF($M6=12,0,$I6),IF($F6="мес",$D6*$E6*(($G6<=1)+($G6<=2)),IF($F6="год",$D6*$E6/12*(($G6<=1)+($G6<=2)),$I6/2))) -> 900000 | K6: =IF($F6="разово",IF($M6=12,$I6,0),IF($F6="мес",$D6*$E6*($G6<=3),IF($F6="год",$D6*$E6/12*($G6<=3),$I6/2))) -> 0 | L6: =IF($F6="разово",0,IF($F6="мес",$D6*$E6*($G6<=3),IF($F6="год",$D6*$E6/12*($G6<=3),$I6/2))) -> 0 | M6: 11
A7: Оснащение | B7: Монитор 24" + клавиатура, мышь, гарнитура | C7: компл. | D7: 5 | E7: 100000 | F7: разово | G7: 1 | I7: =IF(F7="разово",IF(G7<=3,D7*E7,0),IF(F7="мес",D7*E7*MAX(0,4-G7),D7*E7*MAX(0,4-G7)/12)) -> 500000 | J7: =IF($F7="разово",IF($M7=12,0,$I7),IF($F7="мес",$D7*$E7*(($G7<=1)+($G7<=2)),IF($F7="год",$D7*$E7/12*(($G7<=1)+($G7<=2)),$I7/2))) -> 500000 | K7: =IF($F7="разово",IF($M7=12,$I7,0),IF($F7="мес",$D7*$E7*($G7<=3),IF($F7="год",$D7*$E7/12*($G7<=3),$I7/2))) -> 0 | L7: =IF($F7="разово",0,IF($F7="мес",$D7*$E7*($G7<=3),IF($F7="год",$D7*$E7/12*($G7<=3),$I7/2))) -> 0 | M7: 11
A8: Оснащение | B8: Стол рабочий с подкатной тумбой (ZETA Лофт, 140×70×77,7 см, ЛДСП, каркас металл, тумба на колёсах с 3 ящиками) | C8: шт. | D8: 20 | E8: =ROUND(80861/(1+НДС),0) -> 69708 | F8: разово | G8: 1 | I8: =IF(F8="разово",IF(G8<=3,D8*E8,0),IF(F8="мес",D8*E8*MAX(0,4-G8),D8*E8*MAX(0,4-G8)/12)) -> 1394160 | J8: =IF($F8="разово",IF($M8=12,0,$I8),IF($F8="мес",$D8*$E8*(($G8<=1)+($G8<=2)),IF($F8="год",$D8*$E8/12*(($G8<=1)+($G8<=2)),$I8/2))) -> 1394160 | K8: =IF($F8="разово",IF($M8=12,$I8,0),IF($F8="мес",$D8*$E8*($G8<=3),IF($F8="год",$D8*$E8/12*($G8<=3),$I8/2))) -> 0 | L8: =IF($F8="разово",0,IF($F8="мес",$D8*$E8*($G8<=3),IF($F8="год",$D8*$E8/12*($G8<=3),$I8/2))) -> 0 | M8: 11
A9: Оснащение | B9: Кресло рабочее (МИ-6 Z, спинка-сетка, подлокотники, крестовина с колёсами, регулировка высоты, нагрузка 120 кг) | C9: шт. | D9: 26 | E9: =ROUND(17110/(1+НДС),0) -> 14750 | F9: разово | G9: 1 | I9: =IF(F9="разово",IF(G9<=3,D9*E9,0),IF(F9="мес",D9*E9*MAX(0,4-G9),D9*E9*MAX(0,4-G9)/12)) -> 383500 | J9: =IF($F9="разово",IF($M9=12,0,$I9),IF($F9="мес",$D9*$E9*(($G9<=1)+($G9<=2)),IF($F9="год",$D9*$E9/12*(($G9<=1)+($G9<=2)),$I9/2))) -> 383500 | K9: =IF($F9="разово",IF($M9=12,$I9,0),IF($F9="мес",$D9*$E9*($G9<=3),IF($F9="год",$D9*$E9/12*($G9<=3),$I9/2))) -> 0 | L9: =IF($F9="разово",0,IF($F9="мес",$D9*$E9*($G9<=3),IF($F9="год",$D9*$E9/12*($G9<=3),$I9/2))) -> 0 | M9: 11
A10: Оснащение | B10: Кресло руководителя (ZETA Гермес, высокая спинка, механизм качания, подлокотники, нагрузка 120 кг) | C10: шт. | D10: 4 | E10: =ROUND(70900/(1+НДС),0) -> 61121 | F10: разово | G10: 1 | I10: =IF(F10="разово",IF(G10<=3,D10*E10,0),IF(F10="мес",D10*E10*MAX(0,4-G10),D10*E10*MAX(0,4-G10)/12)) -> 244484 | J10: =IF($F10="разово",IF($M10=12,0,$I10),IF($F10="мес",$D10*$E10*(($G10<=1)+($G10<=2)),IF($F10="год",$D10*$E10/12*(($G10<=1)+($G10<=2)),$I10/2))) -> 244484 | K10: =IF($F10="разово",IF($M10=12,$I10,0),IF($F10="мес",$D10*$E10*($G10<=3),IF($F10="год",$D10*$E10/12*($G10<=3),$I10/2))) -> 0 | L10: =IF($F10="разово",0,IF($F10="мес",$D10*$E10*($G10<=3),IF($F10="год",$D10*$E10/12*($G10<=3),$I10/2))) -> 0 | M10: 11
A11: Оснащение | B11: Кресло Главного исполнительного директора (ZETA мод. 2338, экокожа, высокая спинка, нагрузка 120 кг) | C11: шт. | D11: 1 | E11: =ROUND(114460/(1+НДС),0) -> 98672 | F11: разово | G11: 1 | I11: =IF(F11="разово",IF(G11<=3,D11*E11,0),IF(F11="мес",D11*E11*MAX(0,4-G11),D11*E11*MAX(0,4-G11)/12)) -> 98672 | J11: =IF($F11="разово",IF($M11=12,0,$I11),IF($F11="мес",$D11*$E11*(($G11<=1)+($G11<=2)),IF($F11="год",$D11*$E11/12*(($G11<=1)+($G11<=2)),$I11/2))) -> 98672 | K11: =IF($F11="разово",IF($M11=12,$I11,0),IF($F11="мес",$D11*$E11*($G11<=3),IF($F11="год",$D11*$E11/12*($G11<=3),$I11/2))) -> 0 | L11: =IF($F11="разово",0,IF($F11="мес",$D11*$E11*($G11<=3),IF($F11="год",$D11*$E11/12*($G11<=3),$I11/2))) -> 0 | M11: 11
A12: Оснащение | B12: Стол руководителя (ZETA Тейлор, 140×70×75 см, светло-серый) | C12: шт. | D12: 0 | E12: =ROUND(67576/(1+НДС),0) -> 58255 | F12: разово | G12: 1 | I12: =IF(F12="разово",IF(G12<=3,D12*E12,0),IF(F12="мес",D12*E12*MAX(0,4-G12),D12*E12*MAX(0,4-G12)/12)) -> 0 | J12: =IF($F12="разово",IF($M12=12,0,$I12),IF($F12="мес",$D12*$E12*(($G12<=1)+($G12<=2)),IF($F12="год",$D12*$E12/12*(($G12<=1)+($G12<=2)),$I12/2))) -> 0 | K12: =IF($F12="разово",IF($M12=12,$I12,0),IF($F12="мес",$D12*$E12*($G12<=3),IF($F12="год",$D12*$E12/12*($G12<=3),$I12/2))) -> 0 | L12: =IF($F12="разово",0,IF($F12="мес",$D12*$E12*($G12<=3),IF($F12="год",$D12*$E12/12*($G12<=3),$I12/2))) -> 0 | M12: 11
A13: Оснащение | B13: Шкаф для документов финансовому директору, полностью закрытый, с замком (ZETA ШММ-1, металл, 42,5×37×176 см, 4 полки) | C13: шт. | D13: 1 | E13: =ROUND(45900/(1+НДС),0) -> 39569 | F13: разово | G13: 1 | I13: =IF(F13="разово",IF(G13<=3,D13*E13,0),IF(F13="мес",D13*E13*MAX(0,4-G13),D13*E13*MAX(0,4-G13)/12)) -> 39569 | J13: =IF($F13="разово",IF($M13=12,0,$I13),IF($F13="мес",$D13*$E13*(($G13<=1)+($G13<=2)),IF($F13="год",$D13*$E13/12*(($G13<=1)+($G13<=2)),$I13/2))) -> 39569 | K13: =IF($F13="разово",IF($M13=12,$I13,0),IF($F13="мес",$D13*$E13*($G13<=3),IF($F13="год",$D13*$E13/12*($G13<=3),$I13/2))) -> 0 | L13: =IF($F13="разово",0,IF($F13="мес",$D13*$E13*($G13<=3),IF($F13="год",$D13*$E13/12*($G13<=3),$I13/2))) -> 0 | M13: 11
A14: Оснащение | B14: Тумба офисная подкатная в кабинет руководителя (ZETA OZ9134000000ST, 44×61×40 см, на колёсиках, ящик и дверца) | C14: шт. | D14: 0 | E14: =ROUND(23645/(1+НДС),0) -> 20384 | F14: разово | G14: 1 | I14: =IF(F14="разово",IF(G14<=3,D14*E14,0),IF(F14="мес",D14*E14*MAX(0,4-G14),D14*E14*MAX(0,4-G14)/12)) -> 0 | J14: =IF($F14="разово",IF($M14=12,0,$I14),IF($F14="мес",$D14*$E14*(($G14<=1)+($G14<=2)),IF($F14="год",$D14*$E14/12*(($G14<=1)+($G14<=2)),$I14/2))) -> 0 | K14: =IF($F14="разово",IF($M14=12,$I14,0),IF($F14="мес",$D14*$E14*($G14<=3),IF($F14="год",$D14*$E14/12*($G14<=3),$I14/2))) -> 0 | L14: =IF($F14="разово",0,IF($F14="мес",$D14*$E14*($G14<=3),IF($F14="год",$D14*$E14/12*($G14<=3),$I14/2))) -> 0 | M14: 11
A15: Оснащение | B15: Шкаф-гардероб офисный в кабинет руководителя (со штангой и полкой, высота от 190 см) | C15: шт. | D15: 0 | E15: =ROUND(55451/(1+НДС),0) -> 47803 | F15: разово | G15: 1 | I15: =IF(F15="разово",IF(G15<=3,D15*E15,0),IF(F15="мес",D15*E15*MAX(0,4-G15),D15*E15*MAX(0,4-G15)/12)) -> 0 | J15: =IF($F15="разово",IF($M15=12,0,$I15),IF($F15="мес",$D15*$E15*(($G15<=1)+($G15<=2)),IF($F15="год",$D15*$E15/12*(($G15<=1)+($G15<=2)),$I15/2))) -> 0 | K15: =IF($F15="разово",IF($M15=12,$I15,0),IF($F15="мес",$D15*$E15*($G15<=3),IF($F15="год",$D15*$E15/12*($G15<=3),$I15/2))) -> 0 | L15: =IF($F15="разово",0,IF($F15="мес",$D15*$E15*($G15<=3),IF($F15="год",$D15*$E15/12*($G15<=3),$I15/2))) -> 0 | M15: 11
A16: Оснащение | B16: Вешалка-стойка напольная на крестовине, 7 крючков (ZETA Кактус, металл, 50×50×175 см) | C16: шт. | D16: 5 | E16: =ROUND(8950/(1+НДС),0) -> 7716 | F16: разово | G16: 1 | I16: =IF(F16="разово",IF(G16<=3,D16*E16,0),IF(F16="мес",D16*E16*MAX(0,4-G16),D16*E16*MAX(0,4-G16)/12)) -> 38580 | J16: =IF($F16="разово",IF($M16=12,0,$I16),IF($F16="мес",$D16*$E16*(($G16<=1)+($G16<=2)),IF($F16="год",$D16*$E16/12*(($G16<=1)+($G16<=2)),$I16/2))) -> 38580 | K16: =IF($F16="разово",IF($M16=12,$I16,0),IF($F16="мес",$D16*$E16*($G16<=3),IF($F16="год",$D16*$E16/12*($G16<=3),$I16/2))) -> 0 | L16: =IF($F16="разово",0,IF($F16="мес",$D16*$E16*($G16<=3),IF($F16="год",$D16*$E16/12*($G16<=3),$I16/2))) -> 0 | M16: 11
A17: Оснащение | B17: Комплект мебели кабинетов ГИД и руководителя проектного офиса (ILMER Рук: стол овальный 180×80, приставка 140×65, тумба 120×40, шкаф и стеллаж 210×180 – 6 предметов) | C17: компл. | D17: 2 | E17: =ROUND(249999/(1+НДС),0) -> 215516 | F17: разово | G17: 1 | I17: =IF(F17="разово",IF(G17<=3,D17*E17,0),IF(F17="мес",D17*E17*MAX(0,4-G17),D17*E17*MAX(0,4-G17)/12)) -> 431032 | J17: =IF($F17="разово",IF($M17=12,0,$I17),IF($F17="мес",$D17*$E17*(($G17<=1)+($G17<=2)),IF($F17="год",$D17*$E17/12*(($G17<=1)+($G17<=2)),$I17/2))) -> 431032 | K17: =IF($F17="разово",IF($M17=12,$I17,0),IF($F17="мес",$D17*$E17*($G17<=3),IF($F17="год",$D17*$E17/12*($G17<=3),$I17/2))) -> 0 | L17: =IF($F17="разово",0,IF($F17="мес",$D17*$E17*($G17<=3),IF($F17="год",$D17*$E17/12*($G17<=3),$I17/2))) -> 0 | M17: 11
A18: Оснащение | B18: Комплект мебели кабинетов заместителя ГИД и финансового директора (АТЛАНТИК К103, коричневый: шкаф плательный 800×400×1950, шкаф для документов 800×400×1950, стол 1100×600×750, стол с полкой для клавиатуры 800×600×750, приставка угловая 600×600 – 5 предметов) | C18: компл. | D18: 2 | E18: =ROUND(265000/(1+НДС),0) -> 228448 | F18: разово | G18: 1 | I18: =IF(F18="разово",IF(G18<=3,D18*E18,0),IF(F18="мес",D18*E18*MAX(0,4-G18),D18*E18*MAX(0,4-G18)/12)) -> 456896 | J18: =IF($F18="разово",IF($M18=12,0,$I18),IF($F18="мес",$D18*$E18*(($G18<=1)+($G18<=2)),IF($F18="год",$D18*$E18/12*(($G18<=1)+($G18<=2)),$I18/2))) -> 456896 | K18: =IF($F18="разово",IF($M18=12,$I18,0),IF($F18="мес",$D18*$E18*($G18<=3),IF($F18="год",$D18*$E18/12*($G18<=3),$I18/2))) -> 0 | L18: =IF($F18="разово",0,IF($F18="мес",$D18*$E18*($G18<=3),IF($F18="год",$D18*$E18/12*($G18<=3),$I18/2))) -> 0 | M18: 11
A19: Оснащение | B19: Стул представительский (ZETA Shugyla, 87×55×57 см, металл, обивка велюр, бежевый) | C19: шт. | D19: 3 | E19: =ROUND(26905/(1+НДС),0) -> 23194 | F19: разово | G19: 1 | I19: =IF(F19="разово",IF(G19<=3,D19*E19,0),IF(F19="мес",D19*E19*MAX(0,4-G19),D19*E19*MAX(0,4-G19)/12)) -> 69582 | J19: =IF($F19="разово",IF($M19=12,0,$I19),IF($F19="мес",$D19*$E19*(($G19<=1)+($G19<=2)),IF($F19="год",$D19*$E19/12*(($G19<=1)+($G19<=2)),$I19/2))) -> 69582 | K19: =IF($F19="разово",IF($M19=12,$I19,0),IF($F19="мес",$D19*$E19*($G19<=3),IF($F19="год",$D19*$E19/12*($G19<=3),$I19/2))) -> 0 | L19: =IF($F19="разово",0,IF($F19="мес",$D19*$E19*($G19<=3),IF($F19="год",$D19*$E19/12*($G19<=3),$I19/2))) -> 0 | M19: 11
A20: Оснащение | B20: Кухонный гарнитур ZETA Денвер, 200×215×60 см, ЛДСП, серый / бежевый | C20: компл. | D20: 1 | E20: =ROUND(118860/(1+НДС),0) -> 102466 | F20: разово | G20: 1 | I20: =IF(F20="разово",IF(G20<=3,D20*E20,0),IF(F20="мес",D20*E20*MAX(0,4-G20),D20*E20*MAX(0,4-G20)/12)) -> 102466 | J20: =IF($F20="разово",IF($M20=12,0,$I20),IF($F20="мес",$D20*$E20*(($G20<=1)+($G20<=2)),IF($F20="год",$D20*$E20/12*(($G20<=1)+($G20<=2)),$I20/2))) -> 102466 | K20: =IF($F20="разово",IF($M20=12,$I20,0),IF($F20="мес",$D20*$E20*($G20<=3),IF($F20="год",$D20*$E20/12*($G20<=3),$I20/2))) -> 0 | L20: =IF($F20="разово",0,IF($F20="мес",$D20*$E20*($G20<=3),IF($F20="год",$D20*$E20/12*($G20<=3),$I20/2))) -> 0 | M20: 11
A21: Оснащение | B21: Мойка врезная HALI со смесителем, 60×45×22 см, нерж. сталь 3 мм, графит | C21: компл. | D21: 1 | E21: =ROUND(36990/(1+НДС),0) -> 31888 | F21: разово | G21: 1 | I21: =IF(F21="разово",IF(G21<=3,D21*E21,0),IF(F21="мес",D21*E21*MAX(0,4-G21),D21*E21*MAX(0,4-G21)/12)) -> 31888 | J21: =IF($F21="разово",IF($M21=12,0,$I21),IF($F21="мес",$D21*$E21*(($G21<=1)+($G21<=2)),IF($F21="год",$D21*$E21/12*(($G21<=1)+($G21<=2)),$I21/2))) -> 31888 | K21: =IF($F21="разово",IF($M21=12,$I21,0),IF($F21="мес",$D21*$E21*($G21<=3),IF($F21="год",$D21*$E21/12*($G21<=3),$I21/2))) -> 0 | L21: =IF($F21="разово",0,IF($F21="мес",$D21*$E21*($G21<=3),IF($F21="год",$D21*$E21/12*($G21<=3),$I21/2))) -> 0 | M21: 11
