Workbook
Name Авиа_межд: Параметры!$B$25
Name Авиа_РК: Параметры!$B$18
Name Аренда_депозит: Параметры!$B$48
Name Аренда_мес: Параметры!$B$32
Name Аренда_мес_2026: Параметры!$B$49
Name Аренда_с_НДС: Параметры!$B$47
Name Депозит_мес: Параметры!$B$33
Name Дней_межд: Параметры!$B$28
Name Дней_РК: Параметры!$B$21
Name Кап_ООСМС: Параметры!$B$11
Name Кап_СО: Параметры!$B$9
Name Коммун_мес: Параметры!$B$44
Name Курс: Параметры!$B$16
Name Мес_2026_новые: Параметры!$B$52
Name МЗП: Параметры!$B$4
Name МРП: Параметры!$B$5
Name НДС: Параметры!$B$35
Name Ночей_межд: Параметры!$B$29
Name Ночей_РК: Параметры!$B$22
Name ОСНС: Параметры!$B$14
Name ОСНС_полис: Параметры!$B$15
Name Отель_межд: Параметры!$B$26
Name Отель_РК: Параметры!$B$19
Name Парковка_мест: Параметры!$B$45
Name Парковка_цена: Параметры!$B$46
Name Площадь_офиса: Параметры!$B$42
Name Поездка_межд: Параметры!$B$31
Name Поездка_местн: Параметры!$B$24
Name Поездка_РК: Параметры!$B$23
Name Резерв: Параметры!$B$34
Name Сборка_мебели_проц: Параметры!$B$51
Name Ставка_аренды_м2: Параметры!$B$43
Name Ставка_ВОСМС: Параметры!$B$13
Name Ставка_ООСМС: Параметры!$B$10
Name Ставка_ОПВ: Параметры!$B$12
Name Ставка_ОПВР: Параметры!$B$7
Name Ставка_СН: Параметры!$B$6
Name Ставка_СО: Параметры!$B$8
Name Страх_межд: Параметры!$B$30
Name Сут_межд: Параметры!$B$27
Name Сут_РК: Параметры!$B$17
Name Трансп_РК: Параметры!$B$20

Sheet Свод
A1: Бюджет ЦАКФ на октябрь–декабрь 2026 года, ₸
A3: Статья | B3: Октябрь–декабрь 2026
A4: Штатная численность, чел. | B4: =SUMIF(Штат!E5:E29,"штат",Штат!G5:G29) -> 18
A5: в т.ч. проектный офис «Таза Қазақстан», чел. | B5: =Штат!G31 -> 12
A6: 1. Персонал: оклады и отчисления работодателя (СН, ОПВР, СО, ООСМС) | B6: =SUMIFS(Штат!M5:M29,Штат!E5:E29,"штат") -> 58691748
A7: 2. Аутсорс-услуги: юрист МФЦА, сис.админ, разработчик, режиссёр, копирайтер, дизайнер, менеджер по креаторам (с НДС исполнителя) | B7: =Аутсорс!J11 -> 14567355
A8: 3. ОСНС: годовой полис на новых сотрудников | B8: =Штат!N30 -> 500000
A9: 4. Командировки по РК | B9: =Командировки!G12 -> 3783804
A10: 5. Оснащение (разово): ноутбуки, мебель, МФУ, интерактивная панель, ИБП, фото-видео, сеть | B10: =SUMIFS('Оснащение и офис'!I5:I57,'Оснащение и офис'!A5:A57,"Оснащение") -> 29170035
A11: 6. Офис: аренда, депозит, текущие хозрасходы, курьер, интернет, обслуживание МФУ, канцелярия, представительские | B11: =SUMIFS('Оснащение и офис'!I5:I57,'Оснащение и офис'!A5:A57,"Офис") -> 17530038
A12: 7. Цифровые инструменты | B12: =SUMIFS('Оснащение и офис'!I5:I57,'Оснащение и офис'!A5:A57,"Цифровые") -> 589500
A13: 8. Медиа: таргет, полиграфия, подписки | B13: =SUMIFS('Оснащение и офис'!I5:I57,'Оснащение и офис'!A5:A57,"Медиа") -> 2525000
A14: Прямые затраты | B14: =B6+B7+B8+B9+B10+B11+B12+B13 -> 1.2735748e+08
A15: Непредвиденные расходы: резерв 10% и прочие (страхование фото- и видеооборудования, нотариус, переводы и т.п.) | B15: =B14*Резерв+SUMIFS('Оснащение и офис'!I5:I57,'Оснащение и офис'!A5:A57,"Прочие") -> 12810748
A16: НДС 16% | B16: =(B14+B15)*НДС -> 22426916
A17: А. ИТОГО организационное обеспечение | B17: =B14+B15+B16 -> 1.6259514e+08
A18: Б. Первоочередные проекты (лист «Проекты») | B18: =Проекты!G13 -> 87404855
A19: ВСЕГО (А + Б) | B19: =B17+B18 -> 2.5e+08

Sheet Параметры
A1: Параметры расчёта (меняйте значения в колонке B — всё пересчитается)
A3: Имя | B3: Значение | C3: Пояснение
A4: МЗП | B4: 85000 | C4: МЗП 2026, ₸
A5: МРП | B5: 4325 | C5: МРП 2026, ₸
A6: Ставка_СН | B6: 0.06 | C6: Социальный налог — 6% (НК с 01.01.2026), база: оклад − ОПВ 10% − ВОСМС 2%
A7: Ставка_ОПВР | B7: 0.035 | C7: Пенсионные взносы работодателя — 3,5% (2026)
A8: Ставка_СО | B8: 0.05 | C8: Социальные отчисления — 5%, база до 7 МЗП
A9: Кап_СО | B9: 7 | C9: Предел базы СО, в МЗП
A10: Ставка_ООСМС | B10: 0.03 | C10: Отчисления на ОСМС работодателя — 3%
A11: Кап_ООСМС | B11: 40 | C11: Предел базы ООСМС, в МЗП (с 01.01.2026 предел вырос с 10 до 40 МЗП — изм. в Закон РК "Об обязательном соц. мед. страховании"; было 10 МЗП — это предел до 2025 г.)
A12: Ставка_ОПВ | B12: 0.1 | C12: ОПВ работника 10% — удерживается из оклада (для базы СН и СО)
A13: Ставка_ВОСМС | B13: 0.02 | C13: ВОСМС работника 2% — удерживается из оклада
A14: ОСНС | B14: 28000 | C14: ОСНС на штатного сотрудника в год, ₸
A15: ОСНС_полис | B15: 500000 | C15: Годовой полис ОСНС на новых сотрудников 2026 года, ₸ (оценка: тариф 0,29% от годового ФОТ)
... A22: Ночей_РК | B22: 2 | C22: Ночей в типовой поездке
A23: Поездка_РК | B23: =Авиа_РК+Отель_РК*Ночей_РК+Сут_РК*МРП*Дней_РК+Трансп_РК -> 190950 | C23: Одна поездка по РК на человека, ₸
A24: Поездка_местн | B24: =Трансп_РК+Сут_РК*МРП -> 23650 | C24: Выезд регионального координатора внутри макрорегиона (1 день), ₸
A25: Авиа_межд | B25: 900 | C25: Международный перелёт эконом, $
A26: Отель_межд | B26: 150 | C26: Гостиница за рубежом, $ за ночь
A27: Сут_межд | B27: 150 | C27: Суточные за рубежом, $ в день
A28: Дней_межд | B28: 5 | C28: Длительность загранпоездки, дней
A29: Ночей_межд | B29: 4 | C29: Ночей
A30: Страх_межд | B30: 50 | C30: Страховка/виза, $
A31: Поездка_межд | B31: =(Авиа_межд+Отель_межд*Ночей_межд+Сут_межд*Дней_межд+Страх_межд)*Курс -> 1219000 | C31: Одна загранпоездка на человека, ₸
A32: Аренда_мес | B32: =Площадь_офиса*Ставка_аренды_м2+Коммун_мес+Парковка_мест*Парковка_цена -> 4909152.1 | C32: Аренда офисов с коммунальными и парковкой, ₸ в месяц без НДС (БЦ «Сыганак», 7 этаж: 701–702 + зона 710 – расчёт ниже)
A33: Депозит_мес | B33: 1 | C33: Гарантийный депозит по аренде, в месячных ставках (возвратный) — допущение 1 месяц, условия запрошены у БЦ
A34: Резерв | B34: 0.1 | C34: Резерв на непредвиденные расходы (10% — по требованию, было 5%)
A35: НДС | B35: 0.16 | C35: НДС 16% — для аутсорса (ТОО — плательщик НДС) и справочно для договора услуг
A37: Период: октябрь–декабрь 2026 (3 мес.).
A38: Старт позиции/расхода: 1 – октябрь, 2 – ноябрь, 3 – декабрь 2026.
A41: Аренда – БЦ «Сыганак», ул. Сыганак, 70, 7 этаж: 701–702 + зона 710
A42: Площадь_офиса | B42: =ROUND((52.2+21.4+12.4+33.7+190)*1.1,2) -> 340.67 | C42: Площадь к оплате, м²: 701 (52,2) + 701а (21,4) + 701б (12,4) + 702 (33,7) = 119,7 по плану БЦ; зона 710 – 190,0 по экспликации БЦ; итого 309,7 полезной + 10% мест общего пользования
A43: Ставка_аренды_м2 | B43: 13500 | C43: Ставка аренды со скидкой, ₸ за 1 м² в месяц без НДС и без коммунальных (условия БЦ от 22.09.2026)
A44: Коммун_мес | B44: =743*309.7 -> 230107.1 | C44: Коммунальные, ₸ в месяц без НДС: 743 ₸/м² × 309,7 м² полезной площади (без МОП); ориентир, уточнить у БЦ
A45: Парковка_мест | B45: 2 | C45: Парковка — 2 платных места (указание 30.09.2026)
A46: Парковка_цена | B46: 40000 | C46: Парковка, ₸ за 1 место в месяц без НДС – 40 000, уточнено у БЦ
A47: Аренда_с_НДС | B47: =Аренда_мес*(1+НДС) -> 5694616.4 | C47: Справочно: аренда с коммунальными и парковкой, ₸ в месяц с НДС 16%
A48: Аренда_депозит | B48: =Аренда_мес*Депозит_мес -> 4909152.1 | C48: Справочно: гарантийный депозит (возвратный), ₸
A49: Аренда_мес_2026 | B49: =11/31+2 -> 2.3548387 | C49: Месяцев аренды в 2026: заезд ориентировочно 21.10.2026 (III декада) — 11 дней октября + ноябрь + декабрь ≈ 2,35 мес.
A50: Оснащение офиса
...

Sheet Штат
A1: Штатная структура ЦАКФ по штатному расписанию 01.10.2026 и расходы на персонал, ₸
A4: № | B4: Блок | C4: Должность | D4: Подчиняется | E4: Форма | F4: Статус | G4: Кол-во | H4: Оклад за ед., гросс в мес. (аутсорс — без НДС) | I4: Старт (1 – октябрь, 2 – ноябрь, 3 – декабрь) | J4: Отчисления работодателя / НДС на ед. в мес. | K4: Стоимость строки в мес. | L4: Мес. 2026 (новые — с 21.10) | M4: ФОТ+отчисл. окт–дек 2026 | N4: ОСНС (годовой полис новым сотрудникам) | O4: Итого окт–дек 2026 | P4: Функционал и опыт
A5: 1 | B5: ЦАКФ — руководство Фонда | C5: Главный исполнительный директор (ГИД) | D5: — | E5: штат | F5: действующий | G5: 1 | H5: 1600000 | I5: 1 | J5: =IF(E5="штат",ROUND(Ставка_СН*H5*(1-Ставка_ОПВ-Ставка_ВОСМС)+Ставка_ОПВР*H5+Ставка_СО*MIN(H5*(1-Ставка_ОПВ),Кап_СО*МЗП)+Ставка_ООСМС*MIN(H5,Кап_ООСМС*МЗП),0),ROUND(H5*НДС,0)) -> 218230 | K5: =G5*(H5+J5) -> 1818230 | L5: =IF(AND(F5="новая",I5=1),Мес_2026_новые,MAX(0,4-I5)) -> 3 | M5: =K5*L5 -> 5454690 | N5: =IF(AND(E5="штат",F5="новая"),ОСНС_полис*G5/COUNTIFS($E$5:$E$29,"штат",$F$5:$F$29,"новая"),0) -> 0 | O5: =M5+N5 -> 5454690 | P5: [Қаражан Е.Н.] Общее руководство Фондом и проектным офисом, соглашение с МЭПР, отчётность перед органами Фонда. Опыт: к.э.н. (PhD), MSc LSE («Болашақ»), Chevening; ГИД ЦАКФ с 02.2025 (Региональный экологический саммит 2026); председатель Правления ИЭИ, советник Министра национальной экономики, консультант АБР, директор по устойчивому развитию ФНБ «Самрук-Қазына».
A6: 2 | B6: ЦАКФ — руководство Фонда | C6: Заместитель ГИД по стратегии и проектам | D6: ГИД | E6: штат | F6: действующий | G6: 1 | H6: 1400000 | I6: 1 | J6: =IF(E6="штат",ROUND(Ставка_СН*H6*(1-Ставка_ОПВ-Ставка_ВОСМС)+Ставка_ОПВР*H6+Ставка_СО*MIN(H6*(1-Ставка_ОПВ),Кап_СО*МЗП)+Ставка_ООСМС*MIN(H6,Кап_ООСМС*МЗП),0),ROUND(H6*НДС,0)) -> 194670 | K6: =G6*(H6+J6) -> 1594670 | L6: =IF(AND(F6="новая",I6=1),Мес_2026_новые,MAX(0,4-I6)) -> 3 | M6: =K6*L6 -> 4784010 | N6: =IF(AND(E6="штат",F6="новая"),ОСНС_полис*G6/COUNTIFS($E$5:$E$29,"штат",$F$5:$F$29,"новая"),0) -> 0 | O6: =M6+N6 -> 4784010 | P6: [Кононец А.В.] Стратегия и портфель проектов Фонда, партнёрства; Проектный офис для Центральной Азии; курация проектного управления. Опыт: 20 лет в медиа и госкоммуникациях – руководитель пресс-службы, советник министра труда и социальной защиты, главный редактор Казправды, Total.kz и др.; в ЦАКФ с 07.2025.
A7: 3 | B7: ЦАКФ — руководство Фонда | C7: Заместитель ГИД (адм.-хоз. вопросы, закупки, кадры, проекты) | D7: ГИД | E7: штат | F7: действующий | G7: 1 | H7: 1400000 | I7: 1 | J7: =IF(E7="штат",ROUND(Ставка_СН*H7*(1-Ставка_ОПВ-Ставка_ВОСМС)+Ставка_ОПВР*H7+Ставка_СО*MIN(H7*(1-Ставка_ОПВ),Кап_СО*МЗП)+Ставка_ООСМС*MIN(H7,Кап_ООСМС*МЗП),0),ROUND(H7*НДС,0)) -> 194670 | K7: =G7*(H7+J7) -> 1594670 | L7: =IF(AND(F7="новая",I7=1),Мес_2026_новые,MAX(0,4-I7)) -> 3 | M7: =K7*L7 -> 4784010 | N7: =IF(AND(E7="штат",F7="новая"),ОСНС_полис*G7/COUNTIFS($E$5:$E$29,"штат",$F$5:$F$29,"новая"),0) -> 0 | O7: =M7+N7 -> 4784010 | P7: [Темирбеков М.Е.] Наём, закупки, офис, договоры с поставщиками. Опыт: международные экономические отношения (диплом с отличием); акиматы Костанайской области и Астаны; руководитель аппарата холдинга (3 000+ сотрудников); проекты МЗ РК и Всемирного банка; руководитель в общественных организациях, структур в квазигоссекторе; в ЦАКФ с 02.2025, член Управляющего совета.
A8: 4 | B8: Проектный офис — руководство | C8: Руководитель проектного офиса «Таза Қазақстан» | D8: ГИД | E8: штат | F8: новая | G8: 1 | H8: 1400000 | I8: 1 | J8: =IF(E8="штат",ROUND(Ставка_СН*H8*(1-Ставка_ОПВ-Ставка_ВОСМС)+Ставка_ОПВР*H8+Ставка_СО*MIN(H8*(1-Ставка_ОПВ),Кап_СО*МЗП)+Ставка_ООСМС*MIN(H8,Кап_ООСМС*МЗП),0),ROUND(H8*НДС,0)) -> 194670 | K8: =G8*(H8+J8) -> 1594670 | L8: =IF(AND(F8="новая",I8=1),Мес_2026_новые,MAX(0,4-I8)) -> 2.3548387 | M8: =K8*L8 -> 3755190.6 | N8: =IF(AND(E8="штат",F8="новая"),ОСНС_полис*G8/COUNTIFS($E$5:$E$29,"штат",$F$5:$F$29,"новая"),0) -> 35714.286 | O8: =M8+N8 -> 3790904.9 | P8: [Серикжанова Айгерим] Руководитель проектного офиса: руководство командой, календарь мероприятий, работа с акиматами и госорганами. Опыт: директор Департамента развития талантов, образовательных программ и экспертного сопровождения КФ «Фонд развития креативных индустрий»; PhD, постдокторантура «Политология» (ЕНУ им. Л.Н. Гумилёва), магистр права LLM (РУДН), магистр юридических наук (КазНУ им. аль-Фараби).
A9: 6 | B9: Департамент социологических исследований и аналитики | C9: Главный специалист — социолог | D9: Руководителю департамента | E9: штат | F9: новая | G9: 1 | H9: 1000000 | I9: 1 | J9: =IF(E9="штат",ROUND(Ставка_СН*H9*(1-Ставка_ОПВ-Ставка_ВОСМС)+Ставка_ОПВР*H9+Ставка_СО*MIN(H9*(1-Ставка_ОПВ),Кап_СО*МЗП)+Ставка_ООСМС*MIN(H9,Кап_ООСМС*МЗП),0),ROUND(H9*НДС,0)) -> 147550 | K9: =G9*(H9+J9) -> 1147550 | L9: =IF(AND(F9="новая",I9=1),Мес_2026_новые,MAX(0,4-I9)) -> 2.3548387 | M9: =K9*L9 -> 2702295.2 | N9: =IF(AND(E9="штат",F9="новая"),ОСНС_полис*G9/COUNTIFS($E$5:$E$29,"штат",$F$5:$F$29,"новая"),0) -> 35714.286 | O9: =M9+N9 -> 2738009.4 | P9: [Тленчиева Ш.] Исследования восприятия акции, опросы. Опыт: PhD по социологии.
A10: 14 | B10: Департамент проектного управления и региональной координации | C10: Заместитель директора (МЭПР, ЦГО, регионы) | D10: Директору департамента | E10: штат | F10: новая | G10: 1 | H10: 1100000 | I10: 1 | J10: =IF(E10="штат",ROUND(Ставка_СН*H10*(1-Ставка_ОПВ-Ставка_ВОСМС)+Ставка_ОПВР*H10+Ставка_СО*MIN(H10*(1-Ставка_ОПВ),Кап_СО*МЗП)+Ставка_ООСМС*MIN(H10,Кап_ООСМС*МЗП),0),ROUND(H10*НДС,0)) -> 159330 | K10: =G10*(H10+J10) -> 1259330 | L10: =IF(AND(F10="новая",I10=1),Мес_2026_новые,MAX(0,4-I10)) -> 2.3548387 | M10: =K10*L10 -> 2965519 | N10: =IF(AND(E10="штат",F10="новая"),ОСНС_полис*G10/COUNTIFS($E$5:$E$29,"штат",$F$5:$F$29,"новая"),0) -> 35714.286 | O10: =M10+N10 -> 3001233.3 | P10: Взаимодействие с МЭПР, ЦГО и регионами
A11: 15 | B11: Департамент проектного управления и региональной координации | C11: Главный специалист | D11: Директору департамента | E11: штат | F11: новая | G11: 1 | H11: 1000000 | I11: 1 | J11: =IF(E11="штат",ROUND(Ставка_СН*H11*(1-Ставка_ОПВ-Ставка_ВОСМС)+Ставка_ОПВР*H11+Ставка_СО*MIN(H11*(1-Ставка_ОПВ),Кап_СО*МЗП)+Ставка_ООСМС*MIN(H11,Кап_ООСМС*МЗП),0),ROUND(H11*НДС,0)) -> 147550 | K11: =G11*(H11+J11) -> 1147550 | L11: =IF(AND(F11="новая",I11=1),Мес_2026_новые,MAX(0,4-I11)) -> 2.3548387 | M11: =K11*L11 -> 2702295.2 | N11: =IF(AND(E11="штат",F11="новая"),ОСНС_полис*G11/COUNTIFS($E$5:$E$29,"штат",$F$5:$F$29,"новая"),0) -> 35714.286 | O11: =M11+N11 -> 2738009.4 | P11: [Қуандық Жасұлан] Проектный менеджер: ведение проектов, координация регионов, молодёжные проекты. Опыт: президент благотворительного фонда «Dauletten», основатель портала для молодёжи jastar.online; КазНУ им. аль-Фараби – бакалавр «Государственное и местное управление», MBA, докторантура (PhD).
A12: 17 | B12: Департамент проектного управления и региональной координации | C12: Главный специалист | D12: Директору департамента | E12: штат | F12: новая | G12: 1 | H12: 1000000 | I12: 1 | J12: =IF(E12="штат",ROUND(Ставка_СН*H12*(1-Ставка_ОПВ-Ставка_ВОСМС)+Ставка_ОПВР*H12+Ставка_СО*MIN(H12*(1-Ставка_ОПВ),Кап_СО*МЗП)+Ставка_ООСМС*MIN(H12,Кап_ООСМС*МЗП),0),ROUND(H12*НДС,0)) -> 147550 | K12: =G12*(H12+J12) -> 1147550 | L12: =IF(AND(F12="новая",I12=1),Мес_2026_новые,MAX(0,4-I12)) -> 2.3548387 | M12: =K12*L12 -> 2702295.2 | N12: =IF(AND(E12="штат",F12="новая"),ОСНС_полис*G12/COUNTIFS($E$5:$E$29,"штат",$F$5:$F$29,"новая"),0) -> 35714.286 | O12: =M12+N12 -> 2738009.4 | P12: [Жандилдаев Бакдаулет] Проектный менеджер: координация регионов, взаимодействие с госорганами и общественными организациями. Опыт: исполнительный директор ОЮЛ «Конгресс молодежи Казахстана»; бакалавр «Государственное и местное управление» (КазУТБ), «Финансы» (Тұран-Астана), магистр юриспруденции («Синергия»).
A13: 18 | B13: Департамент проектного управления и региональной координации | C13: Ведущий специалист | D13: Директору департамента | E13: штат | F13: новая | G13: 1 | H13: 1000000 | I13: 1 | J13: =IF(E13="штат",ROUND(Ставка_СН*H13*(1-Ставка_ОПВ-Ставка_ВОСМС)+Ставка_ОПВР*H13+Ставка_СО*MIN(H13*(1-Ставка_ОПВ),Кап_СО*МЗП)+Ставка_ООСМС*MIN(H13,Кап_ООСМС*МЗП),0),ROUND(H13*НДС,0)) -> 147550 | K13: =G13*(H13+J13) -> 1147550 | L13: =IF(AND(F13="новая",I13=1),Мес_2026_новые,MAX(0,4-I13)) -> 2.3548387 | M13: =K13*L13 -> 2702295.2 | N13: =IF(AND(E13="штат",F13="новая"),ОСНС_полис*G13/COUNTIFS($E$5:$E$29,"штат",$F$5:$F$29,"новая"),0) -> 35714.286 | O13: =M13+N13 -> 2738009.4 | P13: [Шербаева Бибинур] Проектный менеджер: ведение проектов календаря, планы и отчёты, взаимодействие с акиматами. Опыт: председатель ОСО «За будущее Казахстана»; бакалавр «Профессиональное обучение», магистр «Казахский язык и литература» (Казахский национальный женский педагогический университет).
A14: 19 | B14: Департамент проектного управления и региональной координации | C14: Ведущий специалист | D14: Директору департамента | E14: штат | F14: новая | G14: 1 | H14: 700000 | I14: 1 | J14: =IF(E14="штат",ROUND(Ставка_СН*H14*(1-Ставка_ОПВ-Ставка_ВОСМС)+Ставка_ОПВР*H14+Ставка_СО*MIN(H14*(1-Ставка_ОПВ),Кап_СО*МЗП)+Ставка_ООСМС*MIN(H14,Кап_ООСМС*МЗП),0),ROUND(H14*НДС,0)) -> 112210 | K14: =G14*(H14+J14) -> 812210 | L14: =IF(AND(F14="новая",I14=1),Мес_2026_новые,MAX(0,4-I14)) -> 2.3548387 | M14: =K14*L14 -> 1912623.5 | N14: =IF(AND(E14="штат",F14="новая"),ОСНС_полис*G14/COUNTIFS($E$5:$E$29,"штат",$F$5:$F$29,"новая"),0) -> 35714.286 | O14: =M14+N14 -> 1948337.8 | P14: [Абенов Алибек] Аналитик: аналитическое сопровождение проектов, методические материалы, отчётность. Опыт: руководитель управления развития кадров и документооборота АО «Центр международных программ»; бакалавр «Метрология, стандартизация и сертификация» (Карагандинский экономический университет).
A15: 23 | B15: Департамент цифрового развития | C15: Руководитель департамента | D15: Национальному координатору | E15: штат | F15: новая | G15: 1 | H15: 1300000 | I15: 1 | J15: =IF(E15="штат",ROUND(Ставка_СН*H15*(1-Ставка_ОПВ-Ставка_ВОСМС)+Ставка_ОПВР*H15+Ставка_СО*MIN(H15*(1-Ставка_ОПВ),Кап_СО*МЗП)+Ставка_ООСМС*MIN(H15,Кап_ООСМС*МЗП),0),ROUND(H15*НДС,0)) -> 182890 | K15: =G15*(H15+J15) -> 1482890 | L15: =IF(AND(F15="новая",I15=1),Мес_2026_новые,MAX(0,4-I15)) -> 2.3548387 | M15: =K15*L15 -> 3491966.8 | N15: =IF(AND(E15="штат",F15="новая"),ОСНС_полис*G15/COUNTIFS($E$5:$E$29,"штат",$F$5:$F$29,"новая"),0) -> 35714.286 | O15: =M15+N15 -> 3527681.1 | P15: [Тастан Нұрбол] IT-специалист: платформа TAZA.KZ, цифровой мониторинг, информационная безопасность, работа с подрядчиком платформы. Опыт: советник председателя по информационной безопасности НАО «ННПЦ Тіл-Қазына»; бакалавр «Вычислительная техника и программное обеспечение» (ЕНУ им. Л.Н. Гумилёва), магистр юриспруденции.
A16: 24 | B16: Департамент цифрового развития | C16: Разработчик (ИИ, ГИС), платформа — аутсорс | D16: Руководителю департамента | E16: аутсорс | F16: новая | G16: 0 | H16: 1000000 | I16: 1 | J16: =IF(E16="штат",ROUND(Ставка_СН*H16*(1-Ставка_ОПВ-Ставка_ВОСМС)+Ставка_ОПВР*H16+Ставка_СО*MIN(H16*(1-Ставка_ОПВ),Кап_СО*МЗП)+Ставка_ООСМС*MIN(H16,Кап_ООСМС*МЗП),0),ROUND(H16*НДС,0)) -> 160000 | K16: =G16*(H16+J16) -> 0 | L16: =IF(AND(F16="новая",I16=1),Мес_2026_новые,MAX(0,4-I16)) -> 2.3548387 | M16: =K16*L16 -> 0 | N16: =IF(AND(E16="штат",F16="новая"),ОСНС_полис*G16/COUNTIFS($E$5:$E$29,"штат",$F$5:$F$29,"новая"),0) -> 0 | O16: =M16+N16 -> 0 | P16: [аутсорс] Разработка и сопровождение ИИ- и ГИС-инструментов, цифровой платформы
... A29: 37 | B29: Административный персонал | C29: Администратор (сис.админ) — аутсорс | D29: Заместителю ГИД (адм.-хоз.) | E29: аутсорс | F29: новая | G29: 0 | H29: 700000 | I29: 1 | J29: =IF(E29="штат",ROUND(Ставка_СН*H29*(1-Ставка_ОПВ-Ставка_ВОСМС)+Ставка_ОПВР*H29+Ставка_СО*MIN(H29*(1-Ставка_ОПВ),Кап_СО*МЗП)+Ставка_ООСМС*MIN(H29,Кап_ООСМС*МЗП),0),ROUND(H29*НДС,0)) -> 112000 | K29: =G29*(H29+J29) -> 0 | L29: =IF(AND(F29="новая",I29=1),Мес_2026_новые,MAX(0,4-I29)) -> 2.3548387 | M29: =K29*L29 -> 0 | N29: =IF(AND(E29="штат",F29="новая"),ОСНС_полис*G29/COUNTIFS($E$5:$E$29,"штат",$F$5:$F$29,"новая"),0) -> 0 | O29: =M29+N29 -> 0 | P29: [аутсорс] ИТ-инфраструктура, сеть и техника; делопроизводство, хоз. администрирование, ассистирование
C30: ИТОГО (штат) | G30: =SUM(G5:G29) -> 18 | H30: =SUMPRODUCT(G5:G29,H5:H29) -> 20200000 | K30: =SUM(K5:K29) -> 23115060 | M30: =SUM(M5:M29) -> 58691748 | N30: =SUM(N5:N29) -> 500000 | O30: =SUM(O5:O29) -> 59191748
C31: в т.ч. проектный офис | G31: =SUM(G8:G9)+SUM(G10:G24) -> 12 | H31: =SUMPRODUCT(G8:G9,H8:H9)+SUMPRODUCT(G10:G24,H10:H24) -> 12500000
C32: в т.ч. Фонд | G32: =G30-G31 -> 6 | H32: =H30-H31 -> 7700000

Sheet Аутсорс
A1: Аутсорс-услуги: расчёт на октябрь–декабрь 2026 года, ₸
A3: № | B3: Позиция | C3: Подчиняется | D3: Функции | E3: Ставка в мес. без НДС | F3: НДС 16% | G3: В мес. с НДС | H3: Старт (1 – октябрь, 2 – ноябрь, 3 – декабрь) | I3: Мес. 2026 | J3: Окт–дек 2026
A4: 1 | B4: Юрист (МФЦА) | C4: Заместителю ГИД (адм.-хоз.) | D4: Договоры и соглашения, право МФЦА, сопровождение закупок и кадровых документов | E4: 1000000 | F4: =E4*НДС -> 160000 | G4: =E4+F4 -> 1160000 | H4: 1 | I4: =IF(H4=1,Мес_2026_новые,MAX(0,4-H4)) -> 2.3548387 | J4: =G4*I4 -> 2731612.9
A5: 2 | B5: Администратор (сис.админ) | C5: Заместителю ГИД (адм.-хоз.) | D5: ИТ-инфраструктура, сеть и техника; делопроизводство, хоз. администрирование, ассистирование | E5: 700000 | F5: =E5*НДС -> 112000 | G5: =E5+F5 -> 812000 | H5: 1 | I5: =IF(H5=1,Мес_2026_новые,MAX(0,4-H5)) -> 2.3548387 | J5: =G5*I5 -> 1912129
A6: 3 | B6: Разработчик (ИИ, ГИС), платформа | C6: Руководителю цифрового развития | D6: Разработка и сопровождение ИИ- и ГИС-инструментов, цифровой платформы | E6: 1000000 | F6: =E6*НДС -> 160000 | G6: =E6+F6 -> 1160000 | H6: 1 | I6: =IF(H6=1,Мес_2026_новые,MAX(0,4-H6)) -> 2.3548387 | J6: =G6*I6 -> 2731612.9
A7: 4 | B7: Режиссёр, видеограф-монтажёр | C7: Руководителю группы «Коммуникация и креатив» | D7: Съёмка и монтаж видео, ролики | E7: 1000000 | F7: =E7*НДС -> 160000 | G7: =E7+F7 -> 1160000 | H7: 2 | I7: =IF(H7=1,Мес_2026_новые,MAX(0,4-H7)) -> 2 | J7: =G7*I7 -> 2320000
A8: 5 | B8: Копирайтер | C8: Руководителю группы «Коммуникация и креатив» | D8: Тексты для соцсетей, сайта, СМИ | E8: 700000 | F8: =E8*НДС -> 112000 | G8: =E8+F8 -> 812000 | H8: 2 | I8: =IF(H8=1,Мес_2026_новые,MAX(0,4-H8)) -> 2 | J8: =G8*I8 -> 1624000
A9: 6 | B9: Дизайнер | C9: Руководителю группы «Коммуникация и креатив» | D9: Визуалы, инфографика, макеты | E9: 700000 | F9: =E9*НДС -> 112000 | G9: =E9+F9 -> 812000 | H9: 2 | I9: =IF(H9=1,Мес_2026_новые,MAX(0,4-H9)) -> 2 | J9: =G9*I9 -> 1624000
A10: 7 | B10: Менеджер по креаторам и креативным проектам | C10: Руководителю группы «Коммуникация и креатив» | D10: Работа с креаторами, креативные проекты | E10: 700000 | F10: =E10*НДС -> 112000 | G10: =E10+F10 -> 812000 | H10: 2 | I10: =IF(H10=1,Мес_2026_новые,MAX(0,4-H10)) -> 2 | J10: =G10*I10 -> 1624000
B11: ИТОГО аутсорс | E11: =SUM(E4:E10) -> 5800000 | F11: =SUM(F4:F10) -> 928000 | G11: =SUM(G4:G10) -> 6728000 | J11: =SUM(J4:J10) -> 14567355

Sheet Командировки
A1: Командировки по РК на октябрь–декабрь 2026 года, ₸
A2: Нормы поездок — на человека; стоимость поездки — лист «Параметры»; количество и старт — с листа «Штат» (структура от 16.09.2026).
A4: Роль | B4: Строка «Штат» | C4: Кол-во чел. | D4: Поездок по РК в год на чел. | E4: Выездов по макрорегиону в мес. на чел. | F4: Мес. 2026 | G4: Окт–дек 2026
A5: =Штат!C5 -> Главный исполнительный директор (ГИД) | C5: =Штат!G5 -> 1 | D5: 4 | E5: 0 | F5: =Штат!L5 -> 3 | G5: =C5*(D5/12*F5*Поездка_РК+E5*F5*Поездка_местн) -> 190950
A6: =Штат!C6 -> Заместитель ГИД по стратегии и проектам | C6: =Штат!G6 -> 1 | D6: 6 | E6: 0 | F6: =Штат!L6 -> 3 | G6: =C6*(D6/12*F6*Поездка_РК+E6*F6*Поездка_местн) -> 286425
A7: =Штат!C8 -> Руководитель проектного офиса «Таза Қазақстан» | C7: =Штат!G8 -> 1 | D7: 10 | E7: 0 | F7: =Штат!L8 -> 2.3548387 | G7: =C7*(D7/12*F7*Поездка_РК+E7*F7*Поездка_местн) -> 374713.71
A8: Департамент социологических исследований и аналитики (1 чел.) | C8: =SUM(Штат!G9:G9) -> 1 | D8: 3 | E8: 3 | F8: =Штат!L9 -> 2.3548387 | G8: =SUMPRODUCT((Штат!I9:I9<=3)*Штат!G9:G9)*(D8/12*F8*Поездка_РК+E8*F8*Поездка_местн) -> 279489.92
A9: Департамент проектного управления и региональной координации (5 чел.) | C9: =SUM(Штат!G10:G14) -> 5 | D9: 6 | E9: 0 | F9: =Штат!L11 -> 2.3548387 | G9: =SUMPRODUCT((Штат!I10:I14<=3)*Штат!G10:G14)*(D9/12*F9*Поездка_РК+E9*F9*Поездка_местн) -> 1124141.1
A10: Департамент цифрового развития (1 чел., разработчик — аутсорс) | C10: =SUM(Штат!G15:G16) -> 1 | D10: 1 | E10: 0 | F10: =Штат!L15 -> 2.3548387 | G10: =C10*(D10/12*F10*Поездка_РК+E10*F10*Поездка_местн) -> 37471.371
A11: Группа «Коммуникация и креатив» (4 чел.): съёмки и освещение мероприятий в регионах | C11: =SUM(Штат!G17:G24) -> 4 | D11: 4 | E11: 4 | F11: =Штат!L17 -> 2.3548387 | G11: =C11*(D11/12*F11*Поездка_РК+E11*F11*Поездка_местн) -> 1490612.9
A12: ИТОГО | G12: =SUM(G5:G11) -> 3783804

Sheet Оснащение и офис
A1: Оснащение, офис, цифровые инструменты, медиа и прочие расходы на октябрь–декабрь 2026 года, ₸
A2: Тип: разово – в месяц старта; мес – ежемесячно с месяца старта; год – годовая сумма × 3/12.
A4: Раздел | B4: Статья | C4: Ед. | D4: Кол-во | E4: Цена, ₸ | F4: Тип | G4: Старт (1 – октябрь) | H4: Примечание | I4: Окт–дек 2026
A5: Оснащение | B5: Ноутбук стандартный (Core i5 / Ryzen 5, 16 ГБ, SSD 512 ГБ) | C5: шт. | D5: 12 | E5: 450000 | F5: разово | G5: 1 | H5: новые сотрудники (14) без 2 производительных; 4 действующих – со своей техникой; аутсорс – со своей | I5: =IF(F5="разово",IF(G5<=3,D5*E5,0),IF(F5="мес",D5*E5*MAX(0,4-G5),D5*E5*MAX(0,4-G5)/12)) -> 5400000
A6: Оснащение | B6: Ноутбук производительный | C6: шт. | D6: 2 | E6: 900000 | F6: разово | G6: 1 | H6: руководитель департамента цифрового развития, фотограф-рилсмейкер (монтаж) | I6: =IF(F6="разово",IF(G6<=3,D6*E6,0),IF(F6="мес",D6*E6*MAX(0,4-G6),D6*E6*MAX(0,4-G6)/12)) -> 1800000
A7: Оснащение | B7: Монитор 24" + клавиатура, мышь, гарнитура | C7: компл. | D7: 10 | E7: 100000 | F7: разово | G7: 1 | H7: новые сотрудники в офисе (рег. координаторы — удалённо) | I7: =IF(F7="разово",IF(G7<=3,D7*E7,0),IF(F7="мес",D7*E7*MAX(0,4-G7),D7*E7*MAX(0,4-G7)/12)) -> 1000000
A8: Оснащение | B8: Рабочее место: стол, кресло, тумба | C8: место | D8: 19 | E8: 200000 | F8: разово | G8: 1 | H8: 16 сотрудников в open space + 3 гостевых (продакшн-группа, координаторы в приезд) | I8: =IF(F8="разово",IF(G8<=3,D8*E8,0),IF(F8="мес",D8*E8*MAX(0,4-G8),D8*E8*MAX(0,4-G8)/12)) -> 3800000
A9: Оснащение | B9: Мебель кабинетов руководства (ГИД, 2 заместителя, Нац.коорд., финдир) | C9: компл. | D9: 5 | E9: 500000 | F9: разово | G9: 1 | H9: новый офис | I9: =IF(F9="разово",IF(G9<=3,D9*E9,0),IF(F9="мес",D9*E9*MAX(0,4-G9),D9*E9*MAX(0,4-G9)/12)) -> 2500000
A10: Оснащение | B10: Переговорная: стол + 12 стульев | C10: компл. | D10: 1 | E10: 800000 | F10: разово | G10: 1 | I10: =IF(F10="разово",IF(G10<=3,D10*E10,0),IF(F10="мес",D10*E10*MAX(0,4-G10),D10*E10*MAX(0,4-G10)/12)) -> 800000
A11: Оснащение | B11: Стойка ресепшн | C11: компл. | D11: 1 | E11: 250000 | F11: разово | G11: 1 | I11: =IF(F11="разово",IF(G11<=3,D11*E11,0),IF(F11="мес",D11*E11*MAX(0,4-G11),D11*E11*MAX(0,4-G11)/12)) -> 250000
A12: Оснащение | B12: Шкафы для документов и сейф | C12: компл. | D12: 1 | E12: 450000 | F12: разово | G12: 1 | H12: Сейф офисный для документов и печатей входит в этот комплект | I12: =IF(F12="разово",IF(G12<=3,D12*E12,0),IF(F12="мес",D12*E12*MAX(0,4-G12),D12*E12*MAX(0,4-G12)/12)) -> 450000
A13: Оснащение | B13: Стеллажи для складов и архивов (склад техники, архив документов, архив основного блока) | C13: шт. | D13: 2 | E13: 60000 | F13: разово | G13: 1 | H13: Металлические стеллажи 2000×1000×500, 4–5 полок. По 2 шт.: склад фото- и видеотехники, архив документов, серверная (в БЦ «Санкт-Петербург» — помещение без окна 701Г или по месту). Цена ориентировочная, уточнить в КП | I13: =IF(F13="разово",IF(G13<=3,D13*E13,0),IF(F13="мес",D13*E13*MAX(0,4-G13),D13*E13*MAX(0,4-G13)/12)) -> 120000
A14: Оснащение | B14: Сборка, доставка и подъём мебели | C14: компл. | D14: 1 | E14: =(D8*E8+D9*E9+D10*E10+D11*E11+D12*E12+D13*E13)*Сборка_мебели_проц -> 792000 | F14: разово | G14: 1 | H14: Сборка и занос: рабочие места, кабинеты руководства, переговорная, ресепшн, шкафы и сейф, стеллажи. Ориентир 10% от стоимости мебели и стеллажей (лист «Параметры»), уточнить в КП | I14: =IF(F14="разово",IF(G14<=3,D14*E14,0),IF(F14="мес",D14*E14*MAX(0,4-G14),D14*E14*MAX(0,4-G14)/12)) -> 792000
A15: Оснащение | B15: МФУ цветное А3 (класс Kyocera TASKalfa 2554ci) с Wi-Fi, тумбой, доставкой и установкой | C15: шт. | D15: 1 | E15: 2500000 | F15: разово | G15: 1 | H15: печать/копия/скан А3; сетевой и Wi-Fi модуль — обязательно; уточнить КП | I15: =IF(F15="разово",IF(G15<=3,D15*E15,0),IF(F15="мес",D15*E15*MAX(0,4-G15),D15*E15*MAX(0,4-G15)/12)) -> 2500000
A16: Оснащение | B16: Стартовый комплект тонеров CMYK для МФУ А3 | C16: компл. | D16: 1 | E16: 300000 | F16: разово | G16: 1 | I16: =IF(F16="разово",IF(G16<=3,D16*E16,0),IF(F16="мес",D16*E16*MAX(0,4-G16),D16*E16*MAX(0,4-G16)/12)) -> 300000
A17: Оснащение | B17: МФУ А4 чёрно-белое с Wi-Fi, дуплексом и автоподатчиком (класс HP LaserJet Pro MFP 4103fdw / Kyocera ECOSYS MA4000fx) | C17: шт. | D17: 2 | E17: 280000 | F17: разово | G17: 1 | H17: ресепшн и кабинет аппарата: печать, копия, скан; работа по Wi-Fi и по сети | I17: =IF(F17="разово",IF(G17<=3,D17*E17,0),IF(F17="мес",D17*E17*MAX(0,4-G17),D17*E17*MAX(0,4-G17)/12)) -> 560000
A18: Оснащение | B18: Резервные картриджи для МФУ А4 (по 2 на аппарат) | C18: шт. | D18: 4 | E18: 55000 | F18: разово | G18: 1 | H18: ресурс ≈3 000 страниц; запас на первый год | I18: =IF(F18="разово",IF(G18<=3,D18*E18,0),IF(F18="мес",D18*E18*MAX(0,4-G18),D18*E18*MAX(0,4-G18)/12)) -> 220000
A19: Оснащение | B19: Резервный комплект тонеров CMYK для МФУ А3 | C19: компл. | D19: 1 | E19: 300000 | F19: разово | G19: 1 | H19: второй комплект вслед за стартовым | I19: =IF(F19="разово",IF(G19<=3,D19*E19,0),IF(F19="мес",D19*E19*MAX(0,4-G19),D19*E19*MAX(0,4-G19)/12)) -> 300000
A20: Оснащение | B20: Ламинатор Deli ET104, А3, 300 мм/мин | C20: шт. | D20: 1 | E20: =ROUND(42340/(1+НДС),0) -> 36500 | F20: разово | G20: 1 | H20: План закупок 2026, поз. 57 (ламинатор Deli А3 — 25 980 ₸). Цена b2bcompany.kz на 24.09.2026 — 42 340 ₸ с НДС, в бюджете без НДС (÷1,16): https://b2bcompany.kz/catalog/ofisnaya_tekhnika_i_aksessuary/laminatory/99742/ | I20: =IF(F20="разово",IF(G20<=3,D20*E20,0),IF(F20="мес",D20*E20*MAX(0,4-G20),D20*E20*MAX(0,4-G20)/12)) -> 36500
A21: Оснащение | B21: Плёнка для ламинирования А4, 100 мкм, 100 шт. в упаковке (OfficeSpace) | C21: уп. | D21: 1 | E21: =ROUND(6000/(1+НДС),0) -> 5172 | F21: разово | G21: 1 | H21: План закупок 2026, поз. 58 (8 880 ₸/уп.). b2bcompany.kz на 24.09.2026: 60 ₸/шт × 100 = 6 000 ₸ с НДС, в бюджете без НДС (÷1,16) — https://b2bcompany.kz/catalog/ofisnaya_tekhnika_i_aksessuary/pruzhiny_oblozhki_plyenka/plyenka_dlya_laminirovaniya/94307/ | I21: =IF(F21="разово",IF(G21<=3,D21*E21,0),IF(F21="мес",D21*E21*MAX(0,4-G21),D21*E21*MAX(0,4-G21)/12)) -> 5172
A22: Оснащение | B22: Переплётная машина Deli 3873 для пластиковой пружины (перфорирует до 18 л., сшивает до 425 л.) | C22: шт. | D22: 1 | E22: =ROUND(114327/(1+НДС),0) -> 98558 | F22: разово | G22: 1 | H22: План закупок 2026, поз. 50 (77 105 ₸). Цена b2bcompany.kz на 24.09.2026 — 114 327 ₸ с НДС, в бюджете без НДС (÷1,16): https://b2bcompany.kz/catalog/ofisnaya_tekhnika_i_aksessuary/pereplyetchiki/98863/ | I22: =IF(F22="разово",IF(G22<=3,D22*E22,0),IF(F22="мес",D22*E22*MAX(0,4-G22),D22*E22*MAX(0,4-G22)/12)) -> 98558
A23: Оснащение | B23: Расходники для переплёта: обложки А4 картонные и пластиковые, пружины 6, 10, 14 и 51 мм (по 100 шт.) | C23: компл. | D23: 1 | E23: =ROUND((100*55+100*68+100*26+100*37+100*57+100*244)/(1+НДС),0) -> 41983 | F23: разово | G23: 1 | H23: План закупок 2026, поз. 51–56. Итого 48 700 ₸ с НДС, в бюджете без НДС (÷1,16). Цены b2bcompany.kz на 24.09.2026, ₸/шт × 100 шт. (код товара на сайте): обложки картонные OfficeSpace А4 230 г/м² синие — 55 (94290); обложки пластиковые А4 200 мкм прозрачные — 68 (Brauberg 98583; OfficeSpace 200 мкм прозрачных нет); пружины Brauberg 6 мм — 26 (61538); OfficeSpace 10 мм — 37 (101049); 14 мм — 57 (81143); 51 мм, 2 уп. по 50 — 244 (81145) | I23: =IF(F23="разово",IF(G23<=3,D23*E23,0),IF(F23="мес",D23*E23*MAX(0,4-G23),D23*E23*MAX(0,4-G23)/12)) -> 41983
A24: Оснащение | B24: Сетевые фильтры на рабочие места: 5 розеток, 3 м, с заземлением (Defender ES) | C24: шт. | D24: 16 | E24: =ROUND(4118/(1+НДС),0) -> 3550 | F24: разово | G24: 1 | H24: По 1 на рабочее место новых сотрудников (14) и 2 у стола совещаний. b2bcompany.kz на 30.09.2026 – 4 118 ₸ с НДС (код 9320), в бюджете без НДС (÷1,16) | I24: =IF(F24="разово",IF(G24<=3,D24*E24,0),IF(F24="мес",D24*E24*MAX(0,4-G24),D24*E24*MAX(0,4-G24)/12)) -> 56800
A25: Оснащение | B25: Сетевые фильтры на общие зоны: 6 розеток, 5 м (Defender DFS 155) | C25: шт. | D25: 3 | E25: =ROUND(6101/(1+НДС),0) -> 5259 | F25: разово | G25: 1 | H25: ТВ и ВКС – 1, МФУ и сетевое оборудование – 1, кухонная зона – 1. b2bcompany.kz на 30.09.2026 – 6 101 ₸ с НДС (код 51417), в бюджете без НДС (÷1,16) | I25: =IF(F25="разово",IF(G25<=3,D25*E25,0),IF(F25="мес",D25*E25*MAX(0,4-G25),D25*E25*MAX(0,4-G25)/12)) -> 15777
A26: Оснащение | B26: Удлинители-магистрали 10 м, 3 розетки, с заземлением, ПВС 3×1 мм², 16 А (ЭРА U-3e-10m-3x1) | C26: шт. | D26: 4 | E26: =ROUND(7235/(1+НДС),0) -> 6237 | F26: разово | G26: 1 | H26: Розетки в офисе — только у стен и на колоннах. От колонны к каждому островному блоку столов: коммуникация — 1, проектное управление — 2 (9 мест), социология — 1. Kaspi.kz (Астана) на 30.09.2026 — 7 235 ₸ с НДС, в бюджете без НДС (÷1,16): https://kaspi.kz/shop/p/udlinitel-era-u-3e-10m-3x1-5055945573695-10-m-120249480/ | I26: =IF(F26="разово",IF(G26<=3,D26*E26,0),IF(F26="мес",D26*E26*MAX(0,4-G26),D26*E26*MAX(0,4-G26)/12)) -> 24948
A27: Оснащение | B27: Кабель-канал напольный ПВХ 70×16 мм, секция 2 м (IEK) | C27: шт. | D27: 5 | E27: =ROUND(9039/(1+НДС),0) -> 7792 | F27: разово | G27: 1 | H27: Прокладка удлинителей по полу через проходы от колонн к блокам столов и к столу совещаний — ≈10 м. Kaspi.kz (Астана) на 30.09.2026 — 9 039 ₸ с НДС за 2 м, в бюджете без НДС (÷1,16): https://kaspi.kz/shop/p/iek-kabel--kanal-profil-pvh-70h16h2000-mm-115737589/ | I27: =IF(F27="разово",IF(G27<=3,D27*E27,0),IF(F27="мес",D27*E27*MAX(0,4-G27),D27*E27*MAX(0,4-G27)/12)) -> 38960
A28: Оснащение | B28: Источник бесперебойного питания 1200 ВА / 650 Вт, линейно-интерактивный (APC Back-UPS BX1200MI-GR) | C28: шт. | D28: 10 | E28: =ROUND(89302/(1+НДС),0) -> 76984 | F28: разово | G28: 1 | H28: Kaspi.kz (Астана) на 10.10.2026 – 89 302 ₸ с НДС, в бюджете без НДС (÷1,16): https://kaspi.kz/shop/p/istochnik-bespereboinogo-pitanija-apc-by-schneider-electric-back-ups-bx1200mi-gr-101092827/ ; у b2bcompany.kz ИБП нет | I28: =IF(F28="разово",IF(G28<=3,D28*E28,0),IF(F28="мес",D28*E28*MAX(0,4-G28),D28*E28*MAX(0,4-G28)/12)) -> 769840
A29: Оснащение | B29: Интерактивная панель 75" (доска-экран) для зала совещаний: 4K, сенсорная, Android (класс Iiyama ProLite TE7515A-B2AG) | C29: шт. | D29: 1 | E29: =ROUND(989997/(1+НДС),0) -> 853446 | F29: разово | G29: 1 | H29: Вместо ТВ 65". Совещания, презентации, ВКС, работа со схемами. Kaspi.kz (Астана) на 10.10.2026 – 989 997 ₸ с НДС, в бюджете без НДС (÷1,16): https://kaspi.kz/shop/p/iiyama-te7515a-b2ag-75-djuim-177664336/ | I29: =IF(F29="разово",IF(G29<=3,D29*E29,0),IF(F29="мес",D29*E29*MAX(0,4-G29),D29*E29*MAX(0,4-G29)/12)) -> 853446
A30: Оснащение | B30: Мобильная стойка на колёсах для панели 32–75″ (AVA-1500) | C30: шт. | D30: 1 | E30: =ROUND(49990/(1+НДС),0) -> 43095 | F30: разово | G30: 1 | H30: Панель – на передвижной стойке у стола совещаний. Kaspi.kz (Астана) на 10.10.2026 – 49 990 ₸ с НДС, в бюджете без НДС (÷1,16): https://kaspi.kz/shop/p/napol-naja-stoika-dlja-televizora-ava-1500-32-75-na-koljosikah-chjornaja-178402637/ | I30: =IF(F30="разово",IF(G30<=3,D30*E30,0),IF(F30="мес",D30*E30*MAX(0,4-G30),D30*E30*MAX(0,4-G30)/12)) -> 43095
A31: Оснащение | B31: Конференц-камера и спикерфон | C31: компл. | D31: 1 | E31: 300000 | F31: разово | G31: 1 | H31: ВКС с акиматами и координаторами | I31: =IF(F31="разово",IF(G31<=3,D31*E31,0),IF(F31="мес",D31*E31*MAX(0,4-G31),D31*E31*MAX(0,4-G31)/12)) -> 300000
A32: Оснащение | B32: Сетевое оборудование и СКС (роутер, коммутатор, Wi-Fi, монтаж) | C32: компл. | D32: 1 | E32: 800000 | F32: разово | G32: 1 | H32: новый офис | I32: =IF(F32="разово",IF(G32<=3,D32*E32,0),IF(F32="мес",D32*E32*MAX(0,4-G32),D32*E32*MAX(0,4-G32)/12)) -> 800000
A33: Оснащение | B33: Сетевой накопитель (NAS) с дисками — архив фото/видео и документов | C33: шт. | D33: 1 | E33: 700000 | F33: разово | G33: 1 | I33: =IF(F33="разово",IF(G33<=3,D33*E33,0),IF(F33="мес",D33*E33*MAX(0,4-G33),D33*E33*MAX(0,4-G33)/12)) -> 700000
A34: Оснащение | B34: Фото- и видеооборудование – базовый комплект (КП PSP Digital) | C34: смета | D34: 1 | E34: ='Смета фото-видео'!G24 -> 3591930 | F34: разово | G34: 1 | H34: лист «Смета фото-видео»: камера, объектив 24-105, стабилизатор, микрофон, карта памяти, монопод, сумка, запасной аккумулятор, штатив, SSD | I34: =IF(F34="разово",IF(G34<=3,D34*E34,0),IF(F34="мес",D34*E34*MAX(0,4-G34),D34*E34*MAX(0,4-G34)/12)) -> 3591930
A35: Оснащение | B35: Бытовая техника (кулер для воды, холодильник, микроволновка, кофемашина) | C35: компл. | D35: 1 | E35: 400000 | F35: разово | G35: 1 | I35: =IF(F35="разово",IF(G35<=3,D35*E35,0),IF(F35="мес",D35*E35*MAX(0,4-G35),D35*E35*MAX(0,4-G35)/12)) -> 400000
A36: Оснащение | B36: Второй кулер для воды, напольный, нагрев и охлаждение (класс Midea MK-32H) | C36: шт. | D36: 1 | E36: =ROUND(35990/(1+НДС),0) -> 31026 | F36: разово | G36: 1 | H36: Второй кулер – для переговорной зоны (первый – в комплекте бытовой техники). Kaspi.kz (Астана) на 10.10.2026 – 35 990 ₸ с НДС, в бюджете без НДС (÷1,16): https://kaspi.kz/shop/p/midea-mk-32h-belyi-25900012/ | I36: =IF(F36="разово",IF(G36<=3,D36*E36,0),IF(F36="мес",D36*E36*MAX(0,4-G36),D36*E36*MAX(0,4-G36)/12)) -> 31026
A37: Оснащение | B37: Лицензии 1С на дополнительные рабочие места | C37: компл. | D37: 1 | E37: 150000 | F37: разово | G37: 1 | I37: =IF(F37="разово",IF(G37<=3,D37*E37,0),IF(F37="мес",D37*E37*MAX(0,4-G37),D37*E37*MAX(0,4-G37)/12)) -> 150000
A38: Оснащение | B38: Вывеска и брендирование офиса | C38: компл. | D38: 1 | E38: 400000 | F38: разово | G38: 1 | I38: =IF(F38="разово",IF(G38<=3,D38*E38,0),IF(F38="мес",D38*E38*MAX(0,4-G38),D38*E38*MAX(0,4-G38)/12)) -> 400000
A39: Оснащение | B39: Аптечки | C39: шт. | D39: 2 | E39: 10000 | F39: разово | G39: 1 | I39: =IF(F39="разово",IF(G39<=3,D39*E39,0),IF(F39="мес",D39*E39*MAX(0,4-G39),D39*E39*MAX(0,4-G39)/12)) -> 20000
A40: Офис | B40: Аренда офиса | C40: мес. | D40: 1 | E40: =Аренда_мес -> 4909152.1 | F40: мес | G40: 1 | H40: БЦ «Сыганак», 7 этаж: 701–702 (119,7 м²) + зона 710 (190,0) = 309,7 м² + 10% МОП = 340,7 м² × 13 500 ₸ + коммунальные 743 ₸/м² полезной (≈230 100) + парковка 2 × 40 000 = 4 909 152 ₸/мес без НДС (5 694 616 ₸ с НДС). Смета: D:\Аренда\Смета аренды — БЦ Сыганак, 701–702 + зона 710 (7 эт.) (проект 2026-10-08).xlsx. В 2026 – с 21.10 (≈2,35 мес.) | I40: =D40*E40*Аренда_мес_2026 -> 11560261
A41: Офис | B41: Гарантийный депозит по аренде (1 месячная ставка, возвратный) | C41: депозит | D41: 1 | E41: =Аренда_мес*Депозит_мес -> 4909152.1 | F41: разово | G41: 1 | H41: Возвращается по окончании аренды. По условиям БЦ «Сыганак» — 1 месяц оплаты | I41: =IF(F41="разово",IF(G41<=3,D41*E41,0),IF(F41="мес",D41*E41*MAX(0,4-G41),D41*E41*MAX(0,4-G41)/12)) -> 4909152.1
...

Sheet Проекты
A1: Первоочередные проекты на октябрь–декабрь 2026 года, ₸
A4: Раздел | B4: Статья | C4: Ед. | D4: Кол-во | E4: Цена, ₸ | F4: Тип | G4: Окт–дек 2026
A5: Проекты | B5: Реализация проекта «TAZA TALQY» (проведение встреч в регионах), в т.ч. круглые столы и семинары для акиматов | C5: сумма | F5: по ПО | G5: 3600000
A6: Проекты | B6: Реализация проекта «TAZA OI» | C6: сумма | F6: по ПО | G6: 1200000
A7: Проекты | B7: Реализация проектов, в т.ч. с молодёжью и волонтёрами | C7: сумма | F7: по ПО | G7: 6100000
A8: Проекты | B8: Информационное сопровождение, в т.ч. пресс-мероприятия, мобильный брендинг | C8: сумма | F8: по ПО | G8: 18400000
A9: Проекты | B9: Привлечение инфлюенсеров | C9: сумма | F9: по ПО | G9: 9200000
A10: Проекты | B10: Реализация специальных / креативных проектов | C10: сумма | F10: по ПО | G10: 30504855
A11: Проекты | B11: Разработка и техническое сопровождение цифровой платформы | C11: сумма | F11: по ПО | G11: 18400000
B13: ИТОГО первоочередные проекты | G13: =SUM(G5:G11) -> 87404855

Sheet Канцелярия
A1: Канцелярия и бумага, ₸
A4: Группа | B4: Позиция | C4: Ед. | D4: Кол-во в месяц | E4: Цена, ₸ | F4: Сумма в месяц, ₸ | G4: Примечание
A5: Бумага и печать | B5: Бумага А4, 80 г/м² (пачка 500 л.) | C5: пачка | D5: 3.5 | E5: 3000 | F5: =D5*E5 -> 10500 | G5: ≈3 500 страниц в месяц
A6: Бумага и печать | B6: Бумага А3 (пачка 500 л.) | C6: пачка | D6: 0.25 | E6: 6500 | F6: =D6*E6 -> 1625 | G6: схемы, плакаты, раздаточные материалы
A7: Бумага и печать | B7: Бумага для флипчарта (блок) | C7: блок | D7: 0.5 | E7: 6000 | F7: =D7*E7 -> 3000 | G7: совещания, семинары
A8: Бумага и печать | B8: Плотная бумага и обложки для брошюровки | C8: компл. | D8: 0.25 | E8: 5000 | F8: =D8*E8 -> 1250 | G8: отчёты, методические материалы
A9: Канцелярия | B9: Ручки, карандаши, маркеры, текстовыделители | C9: компл. | D9: 10 | E9: 1200 | F9: =D9*E9 -> 12000 | G9: на сотрудника в офисе
A10: Канцелярия | B10: Блокноты, стикеры, закладки | C10: компл. | D10: 10 | E10: 900 | F10: =D10*E10 -> 9000 | G10: на сотрудника в офисе
B11: ИТОГО в месяц | F11: =SUM(F5:F10) -> 37375
A13: Разово при открытии офиса | D13: Кол-во | F13: Сумма, ₸
A14: Канцелярия | B14: Папки-регистраторы, скоросшиватели, файлы А4 | C14: компл. | D14: 15 | E14: 1500 | F14: =D14*E14 -> 22500 | G14: делопроизводство, договоры, кадры
A15: Канцелярия | B15: Конверты, почтовые пакеты, бумага для заметок | C15: компл. | D15: 1 | E15: 8000 | F15: =D15*E15 -> 8000 | G15: переписка с МЭПР и акиматами
A16: Канцелярия | B16: Скобы, скрепки, клей, ножницы, ножи, линейки | C16: компл. | D16: 1 | E16: 10000 | F16: =D16*E16 -> 10000 | G16: пополнение
A17: Канцелярия | B17: Степлеры, дыроколы, лотки, органайзеры (пополнение) | C17: компл. | D17: 1 | E17: 6000 | F17: =D17*E17 -> 6000
A18: Канцелярия | B18: Архивные короба и файлы для архива | C18: компл. | D18: 2 | E18: 12000 | F18: =D18*E18 -> 24000 | G18: хранение документов проекта
A19: Канцелярия | B19: Батарейки, удлинители, мелкая электрика | C19: компл. | D19: 1 | E19: 8000 | F19: =D19*E19 -> 8000 | G19: техника, пульты, микрофоны
B20: ИТОГО разово | F20: =SUM(F14:F19) -> 78500

Sheet Смета фото-видео
A1: Смета фото- и видеооборудования, ₸
A2: Раздел 1 — КП PSP Digital / Photo Plus от 12.09.2026; разделы 2–3 — ориентировочные цены, уточняются КП.
A4: № | B4: Наименование | C4: Артикул | D4: Наличие / источник цены | E4: Кол-во | F4: Цена, ₸ | G4: Сумма, ₸
A5: 1. Оборудование по КП PSP Digital / Photo Plus
A6: 1 | B6: Кинокамера Canon EOS C70 Cinema Camera | C6: 5659 | D6: Предзаказ | E6: 1 | F6: 1669990 | G6: =E6*F6 -> 1669990
A7: 2 | B7: Объектив Canon RF 24-105mm f/4L IS USM | C7: 2584 | D7: В наличии | E7: 1 | F7: 485990 | G7: =E7*F7 -> 485990
A8: 4 | B8: Электронный стабилизатор DJI RS 4 Pro Combo | C8: 6218 | D8: В наличии | E8: 1 | F8: 479990 | G8: =E8*F8 -> 479990
A9: 6 | B9: Карта памяти Sony 128GB SF-G Tough UHS-II SDXC 299Mb/s | C9: 4240 | D9: В наличии | E9: 1 | F9: 104990 | G9: =E9*F9 -> 104990
A10: 7 | B10: DJI Mic 3 2-Person Compact Digital Wireless Microphone System | C10: 6976 | D10: В наличии | E10: 1 | F10: 119990 | G10: =E10*F10 -> 119990
A11: 9 | B11: Монопод E-Image MA600+610FH | C11: 3288 | D11: В наличии | E11: 1 | F11: 58990 | G11: =E11*F11 -> 58990
A12: 10 | B12: Сумка для видеокамер E-Image OSCAR S50 (EB0925) | C12: 1756 | D12: В наличии | E12: 1 | F12: 31990 | G12: =E12*F12 -> 31990
B13: Итого раздел 1 | G13: =SUM(G6:G12) -> 2951930
A15: 2. Аккумуляторы
A16: 2.1 | B16: Аккумулятор Canon BP-A30 для Canon EOS C70 — запасной | D16: ориентир | E16: 1 | F16: 240000 | G16: =E16*F16 -> 240000
B17: Итого раздел 2 | G17: =SUM(G16:G16) -> 240000
A19: 3. Дополнительное оборудование
A20: 3.3 | B20: Видеоштатив с видеоголовой | D20: ориентир | E20: 1 | F20: 250000 | G20: =E20*F20 -> 250000
A21: 3.4 | B21: Внешний SSD 2 ТБ для исходников | D21: ориентир | E21: 1 | F21: 150000 | G21: =E21*F21 -> 150000
B22: Итого раздел 3 | G22: =SUM(G20:G21) -> 400000
B24: ИТОГО смета (1 + 2 + 3) | G24: =G13+G17+G22 -> 3591930
