Workbook
Name Авиа_межд: Параметры!$B$27
Name Авиа_РК: Параметры!$B$20
Name Аренда_депозит: Параметры!$B$54
Name Аренда_мес: Параметры!$B$34
Name Аренда_мес_2026: Параметры!$B$55
Name Аренда_с_НДС: Параметры!$B$53
Name Депозит_мес: Параметры!$B$35
Name ДМС: Параметры!$B$16
Name Дней_межд: Параметры!$B$30
Name Дней_РК: Параметры!$B$23
Name Индекс_МРП_2027: Параметры!$B$42
Name Кап_ООСМС: Параметры!$B$11
Name Кап_СО: Параметры!$B$9
Name Коммун_мес: Параметры!$B$50
Name Курс: Параметры!$B$18
Name Мес_2026_новые: Параметры!$B$58
Name МЗП: Параметры!$B$4
Name МРП: Параметры!$B$5
Name МРП_2027: Параметры!$B$43
Name НДС: Параметры!$B$37
Name Ночей_межд: Параметры!$B$31
Name Ночей_РК: Параметры!$B$24
Name ОСНС: Параметры!$B$17
Name Отель_межд: Параметры!$B$28
Name Отель_РК: Параметры!$B$21
Name Парковка_мест: Параметры!$B$51
Name Парковка_цена: Параметры!$B$52
Name Площадь_офиса: Параметры!$B$48
Name Поездка_межд: Параметры!$B$33
Name Поездка_местн: Параметры!$B$26
Name Поездка_местн_2027: Параметры!$B$45
Name Поездка_РК: Параметры!$B$25
Name Поездка_РК_2027: Параметры!$B$44
Name Премия_KPI: Параметры!$B$15
Name Премия_НГ: Параметры!$B$14
Name Резерв: Параметры!$B$36
Name Сборка_мебели_проц: Параметры!$B$57
Name Ставка_аренды_м2: Параметры!$B$49
Name Ставка_ВОСМС: Параметры!$B$13
Name Ставка_ООСМС: Параметры!$B$10
Name Ставка_ОПВ: Параметры!$B$12
Name Ставка_ОПВР: Параметры!$B$7
Name Ставка_СН: Параметры!$B$6
Name Ставка_СО: Параметры!$B$8
Name Страх_межд: Параметры!$B$32
Name Сут_межд: Параметры!$B$29
Name Сут_РК: Параметры!$B$19
Name Трансп_РК: Параметры!$B$22

Sheet Свод
A1: Бюджет проектного офиса «Таза Қазақстан» (ЦАКФ) на октябрь–декабрь 2026 и 2027 год — СВОД, ₸
A2: Проект от 10.10.2026 (v15-2). Штат — по структуре и штатке 01.10.2026: 30 человек (Фонд с экспертной группой — 9, проектный офис — 21); с 21.10.2026 — 18, с 01.2027 — 1 (Ахантаева), с 02.2027 — 11 (в т.ч. экспертная группа и Абулхан); аутсорс — 7 позиций, расчёт — на листе «Аутсорс», в бюджете. Аренда – вариант 2: БЦ «Лазурный», ул. Сарайшык, 7/7, 6 этаж целиком: 469,3 м² полезной по обмерному плану; к оплате 657,1 м² (коэффициент общих зон 1,4); коммунальные, клининг и охрана – в ставке; 5 парковочных мест на этаж; в 2026 – с 21.10. Проекты и мероприятия — по статьям проектного офиса, однотипные объединены, — на листе «Проекты (вне бюджета)», в ИТОГО не входят. В оснащении — ламинатор, переплётчик, сетевые фильтры, удлинители, кабель-канал, стойка для ТВ, источники бесперебойного питания (10 шт.). Суммы пересчитываются от листов «Параметры», «Штат», «Командировки», «Оснащение и офис», «Канцелярия», «Смета фото-видео».
A4: Статья | B4: Октябрь–декабрь 2026 | C4: 2027 | D4: В среднем в месяц 2027
A5: Штатная численность, чел. | B5: =SUMIF(Штат!E5:E41,"штат",Штат!G5:G41) -> 30 | C5: =B5 -> 30
A6: из них нанять (новые позиции), чел. | B6: =SUMIFS(Штат!G5:G41,Штат!E5:E41,"штат",Штат!F5:F41,"новая") -> 26
A7: в том числе проектный офис «Таза Қазақстан», чел. | B7: =Штат!G43 -> 21 | C7: =B7 -> 21
A8: 1. Персонал штата: оклады + отчисления работодателя (СН, ОПВР, СО, ООСМС) — новые с 21.10 | B8: =SUMIFS(Штат!N5:N41,Штат!E5:E41,"штат") -> 58691748 | C8: =SUMIFS(Штат!O5:O41,Штат!E5:E41,"штат") -> 419273990 | D8: =C8/12 -> 34939499
A9: 2. Аутсорс-услуги (лист «Аутсорс»): юрист МФЦА, сис.админ, разработчик, режиссёр, копирайтер, дизайнер, менеджер по креаторам — с НДС подрядчика | B9: =Аутсорс!K11 -> 15843355 | C9: =Аутсорс!L11 -> 80736000 | D9: =C9/12 -> 6728000
A10: 3. Премии с отчислениями — по 1 окладу: новогодняя (декабрь 2026) и квартальная, согласно KPI (2027, 1 оклад за квартал) | B10: =Штат!P42 -> 23115060 | C10: =Штат!Q42 -> 1.39758e+08 | D10: =C10/12 -> 11646500
A11: 4. ДМС и ОСНС штатных сотрудников | B11: =Штат!R42 -> 854387.1 | C11: =Штат!S42 -> 6631000 | D11: =C11/12 -> 552583.33
A12: 5. Командировки (по РК, по макрорегионам, зарубежные) | B12: =Командировки!I26 -> 7246775.9 | C12: =Командировки!J26 -> 37657517 | D12: =C12/12 -> 3138126.4
A13: 6. Оснащение (разово): ноутбуки, мебель и стеллажи с их сборкой, МФУ А3 и 2 МФУ А4, ламинатор и переплётчик, удлинители (сетевые фильтры), ИБП (10 шт.), фото-видео, сеть | B13: =SUMIFS('Оснащение и офис'!I5:I181,'Оснащение и офис'!A5:A181,"Оснащение") -> 41946058 | C13: =SUMIFS('Оснащение и офис'!J5:J181,'Оснащение и офис'!A5:A181,"Оснащение") -> 0
A14: 7. Офис: аренда, депозит, ремонт, хозрасходы, курьер, связь, уборка | B14: =SUMIFS('Оснащение и офис'!I5:I181,'Оснащение и офис'!A5:A181,"Офис") -> 38573211 | C14: =SUMIFS('Оснащение и офис'!J5:J181,'Оснащение и офис'!A5:A181,"Офис") -> 128303400 | D14: =C14/12 -> 10691950
A15: в т.ч. аренда офисов (БЦ «Лазурный», 6 этаж, 657,1 м² к оплате – ставка 15 000, коммунальные, клининг и охрана в ставке; в 2026 – с 21.10, ≈2,35 мес.) | B15: ='Оснащение и офис'!I39 -> 23209761 | C15: ='Оснащение и офис'!J39 -> 118274400 | D15: =C15/12 -> 9856200
A16: в т.ч. гарантийный депозит (1 месяц, возвратный) | B16: ='Оснащение и офис'!I40 -> 9856200 | C16: ='Оснащение и офис'!J40 -> 0
A17: 8. Цифровые инструменты: ПО, хостинг, облако, API для ИИ | B17: =SUMIFS('Оснащение и офис'!I5:I181,'Оснащение и офис'!A5:A181,"Цифровые") -> 820500 | C17: =SUMIFS('Оснащение и офис'!J5:J181,'Оснащение и офис'!A5:A181,"Цифровые") -> 9282000 | D17: =C17/12 -> 773500
A18: 9. Медиа: таргет, полиграфия, подписки | B18: =SUMIFS('Оснащение и офис'!I5:I181,'Оснащение и офис'!A5:A181,"Медиа") -> 3325000 | C18: =SUMIFS('Оснащение и офис'!J5:J181,'Оснащение и офис'!A5:A181,"Медиа") -> 25300000 | D18: =C18/12 -> 2108333.3
A19: 10. Проекты и мероприятия по статьям проектного офиса (лист «Проекты (вне бюджета)») — в ИТОГО не входят | B19: ='Проекты (вне бюджета)'!G16 -> 213000000 | C19: ='Проекты (вне бюджета)'!H16 -> 1530000000 | D19: =C19/12 -> 127500000 | E19: не учтено
A20: 11. Прочие: найм, обучение, перевод, аудит, юруслуги, страхование | B20: =SUMIFS('Оснащение и офис'!I5:I181,'Оснащение и офис'!A5:A181,"Прочие") -> 5300000 | C20: =SUMIFS('Оснащение и офис'!J5:J181,'Оснащение и офис'!A5:A181,"Прочие") -> 9400000 | D20: =C20/12 -> 783333.33
A21: ПРЯМЫЕ ЗАТРАТЫ | B21: =B8+B9+B10+B11+B12+B13+B14+B17+B18+B20 -> 1.9571609e+08 | C21: =C8+C9+C10+C11+C12+C13+C14+C17+C18+C20 -> 8.563419e+08 | D21: =C21/12 -> 71361825
A22: Резерв на непредвиденные расходы (10%) | B22: =B21*Резерв -> 19571609 | C22: =C21*Резерв -> 85634190 | D22: =C22/12 -> 7136182.5
A23: ИТОГО без НДС | B23: =B21+B22 -> 2.152877e+08 | C23: =C21+C22 -> 9.4197609e+08 | D23: =C23/12 -> 78498008
A24: НДС 16% (если финансирование — по договору услуг) | B24: =B23*НДС -> 34446033 | C24: =C23*НДС -> 1.5071618e+08 | D24: =C24/12 -> 12559681
A25: ИТОГО с НДС | B25: =B23+B24 -> 2.4973374e+08 | C25: =C23+C24 -> 1.0926923e+09 | D25: =C25/12 -> 91057689
A26: ИТОГО с НДС 3 мес 2026 + 2027 | C26: =B25+C25 -> 1.342426e+09
A27: Справочно, в ИТОГО не входит: проекты и мероприятия по статьям проектного офиса, 3 мес 2026 + 2027 (лист «Проекты (вне бюджета)») | B27: 2026-2027 гг. всего: | C27: =B19+C19 -> 1743000000
A28: Источники финансирования:
A29: 1. Спонсоры ЦАКФ.
A30: 2. Транши от АО «Жасыл Даму».
A31: 3. Спонсоры проводимых мероприятий.
A33: Справка по аренде – вариант 2, БЦ «Лазурный», 6 этаж:
A34: Аренда с коммунальными и парковкой, ₸ в месяц без НДС | B34: =Аренда_мес -> 9856200
A35: То же с НДС 16% (если БЦ — плательщик НДС) | B35: =Аренда_с_НДС -> 11433192
A36: Гарантийный депозит (разово, возвратный) | B36: =Аренда_депозит -> 9856200
A37: Против варианта 1 – БЦ «Сыганак», 701–702 + 710 (4 909 152 ₸/мес без НДС) – разница, ₸ в месяц (минус – дешевле) | B37: =Аренда_мес-4909152.1 -> 4947047.9
A38: Против ориентира 5 000 000 ₸/мес без НДС — разница, ₸ в месяц (минус — укладываемся) | B38: =Аренда_мес-5000000 -> 4856200
A39: Ставка, при которой укладываемся в 5 000 000 ₸/мес без НДС (коммунальные и парковка внутри), ₸/м² | B39: =(5000000-Коммун_мес-Парковка_мест*Парковка_цена)/Площадь_офиса -> 7609.4235
A40: Стеллажи для складов и архива, ₸ разово | B40: ='Оснащение и офис'!I13 -> 360000
A41: Сборка, доставка и подъём мебели и стеллажей, ₸ разово (10%) | B41: ='Оснащение и офис'!E14 -> 841000
A42: Канцелярия, бумага и хозтовары, ₸ в месяц (лист «Канцелярия») | B42: =Канцелярия!F22 -> 240750
...

Sheet Параметры
A1: Параметры расчёта (меняйте значения в колонке B — всё пересчитается)
A3: Имя | B3: Значение | C3: Пояснение
A4: МЗП | B4: 85000 | C4: МЗП 2026, ₸
A5: МРП | B5: 4325 | C5: МРП 2026, ₸
A6: Ставка_СН | B6: 0.06 | C6: Социальный налог — 6% (НК с 01.01.2026), база: оклад − ОПВ 10% − ВОСМС 2%
A7: Ставка_ОПВР | B7: 0.035 | C7: Пенсионные взносы работодателя — 3,5% (2026)
A8: Ставка_СО | B8: 0.05 | C8: Социальные отчисления — 5%, база до 7 МЗП
A9: Кап_СО | B9: 7 | C9: Предел базы СО, в МЗП
A10: Ставка_ООСМС | B10: 0.03 | C10: Отчисления на ОСМС работодателя — 3%
A11: Кап_ООСМС | B11: 40 | C11: Предел базы ООСМС, в МЗП (с 01.01.2026 предел вырос с 10 до 40 МЗП — изм. в Закон РК "Об обязательном соц. мед. страховании"; было 10 МЗП — это предел до 2025 г.)
A12: Ставка_ОПВ | B12: 0.1 | C12: ОПВ работника 10% — удерживается из оклада (для базы СН и СО)
A13: Ставка_ВОСМС | B13: 0.02 | C13: ВОСМС работника 2% — удерживается из оклада
A14: Премия_НГ | B14: 0 | C14: Не используется: новогодняя премия (декабрь 2026) — 1 оклад на штатного сотрудника (формула в листе «Штат», столбец P)
A15: Премия_KPI | B15: 4 | C15: Квартальная премия, согласно KPI: 1 оклад за квартал, 4 оклада в год — пропорционально месяцам работы в 2027 году
... A24: Ночей_РК | B24: 2 | C24: Ночей в типовой поездке
A25: Поездка_РК | B25: =Авиа_РК+Отель_РК*Ночей_РК+Сут_РК*МРП*Дней_РК+Трансп_РК -> 190950 | C25: Одна поездка по РК на человека, ₸
A26: Поездка_местн | B26: =Трансп_РК+Сут_РК*МРП -> 23650 | C26: Выезд регионального координатора внутри макрорегиона (1 день), ₸
A27: Авиа_межд | B27: 900 | C27: Международный перелёт эконом, $
A28: Отель_межд | B28: 150 | C28: Гостиница за рубежом, $ за ночь
A29: Сут_межд | B29: 150 | C29: Суточные за рубежом, $ в день
A30: Дней_межд | B30: 5 | C30: Длительность загранпоездки, дней
A31: Ночей_межд | B31: 4 | C31: Ночей
A32: Страх_межд | B32: 50 | C32: Страховка/виза, $
A33: Поездка_межд | B33: =(Авиа_межд+Отель_межд*Ночей_межд+Сут_межд*Дней_межд+Страх_межд)*Курс -> 1219000 | C33: Одна загранпоездка на человека, ₸
A34: Аренда_мес | B34: =Площадь_офиса*Ставка_аренды_м2+Коммун_мес+Парковка_мест*Парковка_цена -> 9856200 | C34: Аренда офисов с коммунальными и парковкой, ₸ в месяц без НДС (БЦ «Лазурный», 6 этаж – расчёт ниже)
A35: Депозит_мес | B35: 1 | C35: Гарантийный депозит по аренде, в месячных ставках (возвратный) – условия БЦ «Лазурный» не известны, принят 1 месяц
A36: Резерв | B36: 0.1 | C36: Резерв на непредвиденные расходы (10% — по требованию, было 5%)
A37: НДС | B37: 0.16 | C37: НДС 16% — для аутсорса (ТОО — плательщик НДС) и справочно для договора услуг
A39: Периоды: октябрь–декабрь 2026 (3 мес.) и 2027 (12 мес.).
A40: Старт позиции/расхода: 1 = октябрь 2026, 2 = ноябрь, 3 = декабрь, 4 = январь 2027 … 15 = декабрь 2027.
A42: Индекс_МРП_2027 | B42: 0.07 | C42: Индексация МРП на 2027 год, +7% (по запросу)
A43: МРП_2027 | B43: =МРП*(1+Индекс_МРП_2027) -> 4627.75 | C43: МРП на 2027 год с учётом индексации +7%, ₸ (4325*1.07)
A44: Поездка_РК_2027 | B44: =Авиа_РК+Отель_РК*Ночей_РК+Сут_РК*МРП_2027*Дней_РК+Трансп_РК -> 192766.5 | C44: Поездка по РК на человека в 2027 году — суточные считаются от МРП_2027 (2 МРП х проиндексированный МРП), ₸
A45: Поездка_местн_2027 | B45: =Трансп_РК+Сут_РК*МРП_2027 -> 24255.5 | C45: Выезд по макрорегиону на человека в 2027 году — суточные от МРП_2027, ₸
A47: Аренда – БЦ «Лазурный», ул. Сарайшык, 7/7, 6 этаж целиком
A48: Площадь_офиса | B48: =ROUND((244.37+93.3+53.43+45.85+12.39+11.2+8.8)*1.4,2) -> 657.08 | C48: Площадь к оплате, м²: open space 244,37 + залы 93,30, 53,43, 45,85 + кабинет 12,39 + подсобные 11,20 и 8,80 = 469,34 полезной по обмерному плану 6 этажа × коэффициент мест общего пользования 1,4 (≈ весь этаж, 656,41 м²)
A49: Ставка_аренды_м2 | B49: 15000 | C49: Ставка аренды, ₸ за 1 м² в месяц без НДС; коммунальные, клининг и охрана – в ставке (условия БЦ «Лазурный» на 10.10.2026)
A50: Коммун_мес | B50: 0 | C50: Коммунальные – входят в ставку БЦ «Лазурный»
A51: Парковка_мест | B51: 5 | C51: Парковка – 5 мест на этаж
A52: Парковка_цена | B52: 0 | C52: Парковка, ₸ за 1 место в месяц без НДС – в условиях БЦ отдельно не указана, уточнить
...

Sheet Штат
A1: Штатная структура ЦАКФ и проектного офиса «Таза Қазақстан» по штатному расписанию 01.10.2026 и расходы на персонал, ₸
A2: Оклады — из штатки 01.10.2026 (обновлённый должностной оклад); состав — по структуре 01.10.2026: 30 человек (Фонд с экспертной группой — 9, проектный офис — 21). Выход: с 21.10.2026 — 18, с 01.2027 — 1 (Ахантаева), с 02.2027 — 11 (в т.ч. экспертная группа и Абулхан). Строки с количеством 0 — аутсорс.
A4: № | B4: Блок | C4: Должность | D4: Подчиняется | E4: Форма | F4: Статус | G4: Кол-во | H4: Оклад за ед., гросс в мес. (аутсорс — без НДС) | I4: Старт (1=окт-26, 4=янв-27) | J4: Отчисления работодателя / НДС на ед. в мес. | K4: Стоимость строки в мес. | L4: Мес. 2026 (новые — с 21.10) | M4: Мес. 2027 | N4: ФОТ+отчисл. окт–дек 2026 | O4: ФОТ+отчисл. 2027 | P4: Новогодняя премия 2026 (1 оклад) | Q4: Квартальная премия, согласно KPI (2027): 1 оклад за квартал | R4: ДМС+ОСНС 2026 | S4: ДМС+ОСНС 2027 | T4: Итого окт–дек 2026 | U4: Итого 2027 | V4: Ключевые функции
A5: 1 | B5: ЦАКФ — руководство Фонда | C5: Главный исполнительный директор (ГИД) | D5: — | E5: штат | F5: действующий | G5: 1 | H5: 1600000 | I5: 1 | J5: =IF(E5="штат",ROUND(Ставка_СН*H5*(1-Ставка_ОПВ-Ставка_ВОСМС)+Ставка_ОПВР*H5+Ставка_СО*MIN(H5*(1-Ставка_ОПВ),Кап_СО*МЗП)+Ставка_ООСМС*MIN(H5,Кап_ООСМС*МЗП),0),ROUND(H5*НДС,0)) -> 218230 | K5: =G5*(H5+J5) -> 1818230 | L5: =IF(AND(F5="новая",I5=1),Мес_2026_новые,MAX(0,4-I5)) -> 3 | M5: =MAX(0,MIN(12,16-MAX(I5,4))) -> 12 | N5: =K5*L5 -> 5454690 | O5: =K5*M5 -> 21818760 | P5: =IF(AND(E5="штат",L5>0),(H5+J5)*G5,0) -> 1818230 | Q5: =IF(E5="штат",Премия_KPI*H5*(1+J5/H5)*G5*M5/12,0) -> 7272920 | R5: =IF(E5="штат",(ДМС+ОСНС)*G5*L5/12,0) -> 57000 | S5: =IF(E5="штат",(ДМС+ОСНС)*G5*M5/12,0) -> 228000 | T5: =N5+P5+R5 -> 7329920 | U5: =O5+Q5+S5 -> 29319680 | V5: [Қаражан Е.Н.] Общее руководство Фондом и проектным офисом, соглашение с МЭПР, отчётность перед органами Фонда
A6: 2 | B6: ЦАКФ — руководство Фонда | C6: Заместитель ГИД (стратегия, проекты) | D6: ГИД | E6: штат | F6: действующий | G6: 1 | H6: 1400000 | I6: 1 | J6: =IF(E6="штат",ROUND(Ставка_СН*H6*(1-Ставка_ОПВ-Ставка_ВОСМС)+Ставка_ОПВР*H6+Ставка_СО*MIN(H6*(1-Ставка_ОПВ),Кап_СО*МЗП)+Ставка_ООСМС*MIN(H6,Кап_ООСМС*МЗП),0),ROUND(H6*НДС,0)) -> 194670 | K6: =G6*(H6+J6) -> 1594670 | L6: =IF(AND(F6="новая",I6=1),Мес_2026_новые,MAX(0,4-I6)) -> 3 | M6: =MAX(0,MIN(12,16-MAX(I6,4))) -> 12 | N6: =K6*L6 -> 4784010 | O6: =K6*M6 -> 19136040 | P6: =IF(AND(E6="штат",L6>0),(H6+J6)*G6,0) -> 1594670 | Q6: =IF(E6="штат",Премия_KPI*H6*(1+J6/H6)*G6*M6/12,0) -> 6378680 | R6: =IF(E6="штат",(ДМС+ОСНС)*G6*L6/12,0) -> 57000 | S6: =IF(E6="штат",(ДМС+ОСНС)*G6*M6/12,0) -> 228000 | T6: =N6+P6+R6 -> 6435680 | U6: =O6+Q6+S6 -> 25742720 | V6: [Кононец А.В.] Стратегия и портфель проектов Фонда, партнёрства; экспертная группа; курация проектного управления
A7: 3 | B7: ЦАКФ — руководство Фонда | C7: Заместитель ГИД (адм.-хоз. вопросы, закупки, кадры, проекты) | D7: ГИД | E7: штат | F7: действующий | G7: 1 | H7: 1400000 | I7: 1 | J7: =IF(E7="штат",ROUND(Ставка_СН*H7*(1-Ставка_ОПВ-Ставка_ВОСМС)+Ставка_ОПВР*H7+Ставка_СО*MIN(H7*(1-Ставка_ОПВ),Кап_СО*МЗП)+Ставка_ООСМС*MIN(H7,Кап_ООСМС*МЗП),0),ROUND(H7*НДС,0)) -> 194670 | K7: =G7*(H7+J7) -> 1594670 | L7: =IF(AND(F7="новая",I7=1),Мес_2026_новые,MAX(0,4-I7)) -> 3 | M7: =MAX(0,MIN(12,16-MAX(I7,4))) -> 12 | N7: =K7*L7 -> 4784010 | O7: =K7*M7 -> 19136040 | P7: =IF(AND(E7="штат",L7>0),(H7+J7)*G7,0) -> 1594670 | Q7: =IF(E7="штат",Премия_KPI*H7*(1+J7/H7)*G7*M7/12,0) -> 6378680 | R7: =IF(E7="штат",(ДМС+ОСНС)*G7*L7/12,0) -> 57000 | S7: =IF(E7="штат",(ДМС+ОСНС)*G7*M7/12,0) -> 228000 | T7: =N7+P7+R7 -> 6435680 | U7: =O7+Q7+S7 -> 25742720 | V7: [Темирбеков М.Е.] Наём, закупки, офис, договоры с поставщиками
A8: 4 | B8: Проектный офис — руководство | C8: Национальный координатор проектного офиса | D8: ГИД | E8: штат | F8: новая | G8: 1 | H8: 1400000 | I8: 1 | J8: =IF(E8="штат",ROUND(Ставка_СН*H8*(1-Ставка_ОПВ-Ставка_ВОСМС)+Ставка_ОПВР*H8+Ставка_СО*MIN(H8*(1-Ставка_ОПВ),Кап_СО*МЗП)+Ставка_ООСМС*MIN(H8,Кап_ООСМС*МЗП),0),ROUND(H8*НДС,0)) -> 194670 | K8: =G8*(H8+J8) -> 1594670 | L8: =IF(AND(F8="новая",I8=1),Мес_2026_новые,MAX(0,4-I8)) -> 2.3548387 | M8: =MAX(0,MIN(12,16-MAX(I8,4))) -> 12 | N8: =K8*L8 -> 3755190.6 | O8: =K8*M8 -> 19136040 | P8: =IF(AND(E8="штат",L8>0),(H8+J8)*G8,0) -> 1594670 | Q8: =IF(E8="штат",Премия_KPI*H8*(1+J8/H8)*G8*M8/12,0) -> 6378680 | R8: =IF(E8="штат",(ДМС+ОСНС)*G8*L8/12,0) -> 44741.935 | S8: =IF(E8="штат",(ДМС+ОСНС)*G8*M8/12,0) -> 228000 | T8: =N8+P8+R8 -> 5394602.6 | U8: =O8+Q8+S8 -> 25742720 | V8: [Серикжанова А.] Руководство проектным офисом, календарь мероприятий, работа с акиматами и госорганами
A9: 5 | B9: Департамент социологических исследований и аналитики | C9: Руководитель департамента | D9: Национальному координатору | E9: штат | F9: новая | G9: 1 | H9: 1300000 | I9: 4 | J9: =IF(E9="штат",ROUND(Ставка_СН*H9*(1-Ставка_ОПВ-Ставка_ВОСМС)+Ставка_ОПВР*H9+Ставка_СО*MIN(H9*(1-Ставка_ОПВ),Кап_СО*МЗП)+Ставка_ООСМС*MIN(H9,Кап_ООСМС*МЗП),0),ROUND(H9*НДС,0)) -> 182890 | K9: =G9*(H9+J9) -> 1482890 | L9: =IF(AND(F9="новая",I9=1),Мес_2026_новые,MAX(0,4-I9)) -> 0 | M9: =MAX(0,MIN(12,16-MAX(I9,4))) -> 12 | N9: =K9*L9 -> 0 | O9: =K9*M9 -> 17794680 | P9: =IF(AND(E9="штат",L9>0),(H9+J9)*G9,0) -> 0 | Q9: =IF(E9="штат",Премия_KPI*H9*(1+J9/H9)*G9*M9/12,0) -> 5931560 | R9: =IF(E9="штат",(ДМС+ОСНС)*G9*L9/12,0) -> 0 | S9: =IF(E9="штат",(ДМС+ОСНС)*G9*M9/12,0) -> 228000 | T9: =N9+P9+R9 -> 0 | U9: =O9+Q9+S9 -> 23954240 | V9: [Ахантаева] Социологические исследования, методология оценки
A10: 6 | B10: Департамент социологических исследований и аналитики | C10: Главный специалист — социолог | D10: Руководителю департамента | E10: штат | F10: новая | G10: 1 | H10: 1000000 | I10: 1 | J10: =IF(E10="штат",ROUND(Ставка_СН*H10*(1-Ставка_ОПВ-Ставка_ВОСМС)+Ставка_ОПВР*H10+Ставка_СО*MIN(H10*(1-Ставка_ОПВ),Кап_СО*МЗП)+Ставка_ООСМС*MIN(H10,Кап_ООСМС*МЗП),0),ROUND(H10*НДС,0)) -> 147550 | K10: =G10*(H10+J10) -> 1147550 | L10: =IF(AND(F10="новая",I10=1),Мес_2026_новые,MAX(0,4-I10)) -> 2.3548387 | M10: =MAX(0,MIN(12,16-MAX(I10,4))) -> 12 | N10: =K10*L10 -> 2702295.2 | O10: =K10*M10 -> 13770600 | P10: =IF(AND(E10="штат",L10>0),(H10+J10)*G10,0) -> 1147550 | Q10: =IF(E10="штат",Премия_KPI*H10*(1+J10/H10)*G10*M10/12,0) -> 4590200 | R10: =IF(E10="штат",(ДМС+ОСНС)*G10*L10/12,0) -> 44741.935 | S10: =IF(E10="штат",(ДМС+ОСНС)*G10*M10/12,0) -> 228000 | T10: =N10+P10+R10 -> 3894587.1 | U10: =O10+Q10+S10 -> 18588800 | V10: [Тленчиева Ш.] Исследования восприятия акции, опросы
A11: 7 | B11: Департамент социологических исследований и аналитики | C11: Главный специалист — аналитик | D11: Руководителю департамента | E11: штат | F11: новая | G11: 1 | H11: 1000000 | I11: 5 | J11: =IF(E11="штат",ROUND(Ставка_СН*H11*(1-Ставка_ОПВ-Ставка_ВОСМС)+Ставка_ОПВР*H11+Ставка_СО*MIN(H11*(1-Ставка_ОПВ),Кап_СО*МЗП)+Ставка_ООСМС*MIN(H11,Кап_ООСМС*МЗП),0),ROUND(H11*НДС,0)) -> 147550 | K11: =G11*(H11+J11) -> 1147550 | L11: =IF(AND(F11="новая",I11=1),Мес_2026_новые,MAX(0,4-I11)) -> 0 | M11: =MAX(0,MIN(12,16-MAX(I11,4))) -> 11 | N11: =K11*L11 -> 0 | O11: =K11*M11 -> 12623050 | P11: =IF(AND(E11="штат",L11>0),(H11+J11)*G11,0) -> 0 | Q11: =IF(E11="штат",Премия_KPI*H11*(1+J11/H11)*G11*M11/12,0) -> 4207683.3 | R11: =IF(E11="штат",(ДМС+ОСНС)*G11*L11/12,0) -> 0 | S11: =IF(E11="штат",(ДМС+ОСНС)*G11*M11/12,0) -> 209000 | T11: =N11+P11+R11 -> 0 | U11: =O11+Q11+S11 -> 17039733 | V11: [Сандыбаева С.] Аналитика данных
A12: 8 | B12: Департамент социологических исследований и аналитики | C12: Ведущий специалист — социолог | D12: Руководителю департамента | E12: штат | F12: новая | G12: 1 | H12: 700000 | I12: 5 | J12: =IF(E12="штат",ROUND(Ставка_СН*H12*(1-Ставка_ОПВ-Ставка_ВОСМС)+Ставка_ОПВР*H12+Ставка_СО*MIN(H12*(1-Ставка_ОПВ),Кап_СО*МЗП)+Ставка_ООСМС*MIN(H12,Кап_ООСМС*МЗП),0),ROUND(H12*НДС,0)) -> 112210 | K12: =G12*(H12+J12) -> 812210 | L12: =IF(AND(F12="новая",I12=1),Мес_2026_новые,MAX(0,4-I12)) -> 0 | M12: =MAX(0,MIN(12,16-MAX(I12,4))) -> 11 | N12: =K12*L12 -> 0 | O12: =K12*M12 -> 8934310 | P12: =IF(AND(E12="штат",L12>0),(H12+J12)*G12,0) -> 0 | Q12: =IF(E12="штат",Премия_KPI*H12*(1+J12/H12)*G12*M12/12,0) -> 2978103.3 | R12: =IF(E12="штат",(ДМС+ОСНС)*G12*L12/12,0) -> 0 | S12: =IF(E12="штат",(ДМС+ОСНС)*G12*M12/12,0) -> 209000 | T12: =N12+P12+R12 -> 0 | U12: =O12+Q12+S12 -> 12121413 | V12: [Ашимханова Д.] Опросы, интерпретация результатов
A13: 9 | B13: Департамент социологических исследований и аналитики | C13: Ведущий специалист — аналитик | D13: Руководителю департамента | E13: штат | F13: новая | G13: 1 | H13: 700000 | I13: 5 | J13: =IF(E13="штат",ROUND(Ставка_СН*H13*(1-Ставка_ОПВ-Ставка_ВОСМС)+Ставка_ОПВР*H13+Ставка_СО*MIN(H13*(1-Ставка_ОПВ),Кап_СО*МЗП)+Ставка_ООСМС*MIN(H13,Кап_ООСМС*МЗП),0),ROUND(H13*НДС,0)) -> 112210 | K13: =G13*(H13+J13) -> 812210 | L13: =IF(AND(F13="новая",I13=1),Мес_2026_новые,MAX(0,4-I13)) -> 0 | M13: =MAX(0,MIN(12,16-MAX(I13,4))) -> 11 | N13: =K13*L13 -> 0 | O13: =K13*M13 -> 8934310 | P13: =IF(AND(E13="штат",L13>0),(H13+J13)*G13,0) -> 0 | Q13: =IF(E13="штат",Премия_KPI*H13*(1+J13/H13)*G13*M13/12,0) -> 2978103.3 | R13: =IF(E13="штат",(ДМС+ОСНС)*G13*L13/12,0) -> 0 | S13: =IF(E13="штат",(ДМС+ОСНС)*G13*M13/12,0) -> 209000 | T13: =N13+P13+R13 -> 0 | U13: =O13+Q13+S13 -> 12121413 | V13: [Мукашев Д.] Сбор и обработка данных регионов
A14: 10 | B14: Экспертная группа | C14: Руководитель экспертной группы | D14: Заместителю ГИД (стратегия, проекты) | E14: штат | F14: новая | G14: 1 | H14: 1300000 | I14: 5 | J14: =IF(E14="штат",ROUND(Ставка_СН*H14*(1-Ставка_ОПВ-Ставка_ВОСМС)+Ставка_ОПВР*H14+Ставка_СО*MIN(H14*(1-Ставка_ОПВ),Кап_СО*МЗП)+Ставка_ООСМС*MIN(H14,Кап_ООСМС*МЗП),0),ROUND(H14*НДС,0)) -> 182890 | K14: =G14*(H14+J14) -> 1482890 | L14: =IF(AND(F14="новая",I14=1),Мес_2026_новые,MAX(0,4-I14)) -> 0 | M14: =MAX(0,MIN(12,16-MAX(I14,4))) -> 11 | N14: =K14*L14 -> 0 | O14: =K14*M14 -> 16311790 | P14: =IF(AND(E14="штат",L14>0),(H14+J14)*G14,0) -> 0 | Q14: =IF(E14="штат",Премия_KPI*H14*(1+J14/H14)*G14*M14/12,0) -> 5437263.3 | R14: =IF(E14="штат",(ДМС+ОСНС)*G14*L14/12,0) -> 0 | S14: =IF(E14="штат",(ДМС+ОСНС)*G14*M14/12,0) -> 209000 | T14: =N14+P14+R14 -> 0 | U14: =O14+Q14+S14 -> 21958053 | V14: [Юнусов Т.] Научная экспертиза
A15: 11 | B15: Экспертная группа | C15: Эксперт-эколог | D15: Руководителю экспертной группы | E15: штат | F15: новая | G15: 1 | H15: 800000 | I15: 5 | J15: =IF(E15="штат",ROUND(Ставка_СН*H15*(1-Ставка_ОПВ-Ставка_ВОСМС)+Ставка_ОПВР*H15+Ставка_СО*MIN(H15*(1-Ставка_ОПВ),Кап_СО*МЗП)+Ставка_ООСМС*MIN(H15,Кап_ООСМС*МЗП),0),ROUND(H15*НДС,0)) -> 123990 | K15: =G15*(H15+J15) -> 923990 | L15: =IF(AND(F15="новая",I15=1),Мес_2026_новые,MAX(0,4-I15)) -> 0 | M15: =MAX(0,MIN(12,16-MAX(I15,4))) -> 11 | N15: =K15*L15 -> 0 | O15: =K15*M15 -> 10163890 | P15: =IF(AND(E15="штат",L15>0),(H15+J15)*G15,0) -> 0 | Q15: =IF(E15="штат",Премия_KPI*H15*(1+J15/H15)*G15*M15/12,0) -> 3387963.3 | R15: =IF(E15="штат",(ДМС+ОСНС)*G15*L15/12,0) -> 0 | S15: =IF(E15="штат",(ДМС+ОСНС)*G15*M15/12,0) -> 209000 | T15: =N15+P15+R15 -> 0 | U15: =O15+Q15+S15 -> 13760853 | V15: [Загирова А.] Экологическая экспертиза
A16: 12 | B16: Экспертная группа | C16: Эксперт по отходам, воде, воздуху | D16: Руководителю экспертной группы | E16: штат | F16: новая | G16: 1 | H16: 800000 | I16: 5 | J16: =IF(E16="штат",ROUND(Ставка_СН*H16*(1-Ставка_ОПВ-Ставка_ВОСМС)+Ставка_ОПВР*H16+Ставка_СО*MIN(H16*(1-Ставка_ОПВ),Кап_СО*МЗП)+Ставка_ООСМС*MIN(H16,Кап_ООСМС*МЗП),0),ROUND(H16*НДС,0)) -> 123990 | K16: =G16*(H16+J16) -> 923990 | L16: =IF(AND(F16="новая",I16=1),Мес_2026_новые,MAX(0,4-I16)) -> 0 | M16: =MAX(0,MIN(12,16-MAX(I16,4))) -> 11 | N16: =K16*L16 -> 0 | O16: =K16*M16 -> 10163890 | P16: =IF(AND(E16="штат",L16>0),(H16+J16)*G16,0) -> 0 | Q16: =IF(E16="штат",Премия_KPI*H16*(1+J16/H16)*G16*M16/12,0) -> 3387963.3 | R16: =IF(E16="штат",(ДМС+ОСНС)*G16*L16/12,0) -> 0 | S16: =IF(E16="штат",(ДМС+ОСНС)*G16*M16/12,0) -> 209000 | T16: =N16+P16+R16 -> 0 | U16: =O16+Q16+S16 -> 13760853 | V16: [вакансия] Отходы, вода, воздух
... A41: 37 | B41: Административный персонал | C41: Администратор (сис.админ) — аутсорс | D41: Заместителю ГИД (адм.-хоз.) | E41: аутсорс | F41: новая | G41: 0 | H41: 700000 | I41: 1 | J41: =IF(E41="штат",ROUND(Ставка_СН*H41*(1-Ставка_ОПВ-Ставка_ВОСМС)+Ставка_ОПВР*H41+Ставка_СО*MIN(H41*(1-Ставка_ОПВ),Кап_СО*МЗП)+Ставка_ООСМС*MIN(H41,Кап_ООСМС*МЗП),0),ROUND(H41*НДС,0)) -> 112000 | K41: =G41*(H41+J41) -> 0 | L41: =IF(AND(F41="новая",I41=1),Мес_2026_новые,MAX(0,4-I41)) -> 2.3548387 | M41: =MAX(0,MIN(12,16-MAX(I41,4))) -> 12 | N41: =K41*L41 -> 0 | O41: =K41*M41 -> 0 | P41: =IF(AND(E41="штат",L41>0),(H41+J41)*G41,0) -> 0 | Q41: =IF(E41="штат",Премия_KPI*H41*(1+J41/H41)*G41*M41/12,0) -> 0 | R41: =IF(E41="штат",(ДМС+ОСНС)*G41*L41/12,0) -> 0 | S41: =IF(E41="штат",(ДМС+ОСНС)*G41*M41/12,0) -> 0 | T41: =N41+P41+R41 -> 0 | U41: =O41+Q41+S41 -> 0 | V41: [аутсорс] ИТ-инфраструктура, сеть и техника; делопроизводство, хоз. администрирование, ассистирование
C42: ИТОГО (штат), оклады — ставки с 02.2027 | G42: =SUM(G5:G41) -> 30 | H42: =SUMPRODUCT(G5:G41,H5:H41) -> 31300000 | K42: =SUM(K5:K41) -> 35879640 | N42: =SUM(N5:N41) -> 58691748 | O42: =SUM(O5:O41) -> 419273990 | P42: =SUM(P5:P41) -> 23115060 | Q42: =SUM(Q5:Q41) -> 1.39758e+08 | R42: =SUM(R5:R41) -> 854387.1 | S42: =SUM(S5:S41) -> 6631000 | T42: =SUM(T5:T41) -> 82661195 | U42: =SUM(U5:U41) -> 5.6566299e+08
C43: в т.ч. проектный офис (21 чел.) | G43: =SUM(G8:G13)+SUM(G17:G36) -> 21 | H43: =SUMPRODUCT(G8:G13,H8:H13)+SUMPRODUCT(G17:G36,H17:H36) -> 20700000
C44: в т.ч. Фонд с экспертной группой (9 чел.) | G44: =SUM(G5:G7)+SUM(G14:G16)+SUM(G37:G41) -> 9 | H44: =SUMPRODUCT(G5:G7,H5:H7)+SUMPRODUCT(G14:G16,H14:H16)+SUMPRODUCT(G37:G41,H37:H41) -> 10600000

Sheet Аутсорс
A1: Аутсорс-услуги: расчёт на октябрь–декабрь 2026 и 2027 год, ₸
A3: № | B3: Позиция | C3: Подчиняется | D3: Функции | E3: Ставка в мес. без НДС | F3: НДС 16% | G3: В мес. с НДС | H3: Старт (1=окт-26, 4=янв-27) | I3: Мес. 2026 | J3: Мес. 2027 | K3: Окт–дек 2026 | L3: 2027
A4: 1 | B4: Юрист (МФЦА) | C4: Заместителю ГИД (адм.-хоз.) | D4: Договоры и соглашения, право МФЦА, сопровождение закупок и кадровых документов | E4: 1000000 | F4: =E4*НДС -> 160000 | G4: =E4+F4 -> 1160000 | H4: 1 | I4: =IF(H4=1,Мес_2026_новые,MAX(0,4-H4)) -> 2.3548387 | J4: =MAX(0,MIN(12,16-MAX(H4,4))) -> 12 | K4: =G4*I4 -> 2731612.9 | L4: =G4*J4 -> 13920000
A5: 2 | B5: Администратор (сис.админ) | C5: Заместителю ГИД (адм.-хоз.) | D5: ИТ-инфраструктура, сеть и техника; делопроизводство, хоз. администрирование, ассистирование | E5: 700000 | F5: =E5*НДС -> 112000 | G5: =E5+F5 -> 812000 | H5: 1 | I5: =IF(H5=1,Мес_2026_новые,MAX(0,4-H5)) -> 2.3548387 | J5: =MAX(0,MIN(12,16-MAX(H5,4))) -> 12 | K5: =G5*I5 -> 1912129 | L5: =G5*J5 -> 9744000
A6: 3 | B6: Разработчик (ИИ, ГИС), платформа | C6: Руководителю цифрового развития | D6: Разработка и сопровождение ИИ- и ГИС-инструментов, цифровой платформы | E6: 1000000 | F6: =E6*НДС -> 160000 | G6: =E6+F6 -> 1160000 | H6: 1 | I6: =IF(H6=1,Мес_2026_новые,MAX(0,4-H6)) -> 2.3548387 | J6: =MAX(0,MIN(12,16-MAX(H6,4))) -> 12 | K6: =G6*I6 -> 2731612.9 | L6: =G6*J6 -> 13920000
A7: 4 | B7: Режиссёр, видеограф-монтажёр | C7: Руководителю группы «Коммуникация и креатив» | D7: Съёмка и монтаж видео, ролики | E7: 1000000 | F7: =E7*НДС -> 160000 | G7: =E7+F7 -> 1160000 | H7: 1 | I7: =IF(H7=1,Мес_2026_новые,MAX(0,4-H7)) -> 2.3548387 | J7: =MAX(0,MIN(12,16-MAX(H7,4))) -> 12 | K7: =G7*I7 -> 2731612.9 | L7: =G7*J7 -> 13920000
A8: 5 | B8: Копирайтер | C8: Руководителю группы «Коммуникация и креатив» | D8: Тексты для соцсетей, сайта, СМИ | E8: 700000 | F8: =E8*НДС -> 112000 | G8: =E8+F8 -> 812000 | H8: 1 | I8: =IF(H8=1,Мес_2026_новые,MAX(0,4-H8)) -> 2.3548387 | J8: =MAX(0,MIN(12,16-MAX(H8,4))) -> 12 | K8: =G8*I8 -> 1912129 | L8: =G8*J8 -> 9744000
A9: 6 | B9: Дизайнер | C9: Руководителю группы «Коммуникация и креатив» | D9: Визуалы, инфографика, макеты | E9: 700000 | F9: =E9*НДС -> 112000 | G9: =E9+F9 -> 812000 | H9: 1 | I9: =IF(H9=1,Мес_2026_новые,MAX(0,4-H9)) -> 2.3548387 | J9: =MAX(0,MIN(12,16-MAX(H9,4))) -> 12 | K9: =G9*I9 -> 1912129 | L9: =G9*J9 -> 9744000
A10: 7 | B10: Менеджер по креаторам и креативным проектам | C10: Руководителю группы «Коммуникация и креатив» | D10: Работа с креаторами, креативные проекты | E10: 700000 | F10: =E10*НДС -> 112000 | G10: =E10+F10 -> 812000 | H10: 1 | I10: =IF(H10=1,Мес_2026_новые,MAX(0,4-H10)) -> 2.3548387 | J10: =MAX(0,MIN(12,16-MAX(H10,4))) -> 12 | K10: =G10*I10 -> 1912129 | L10: =G10*J10 -> 9744000
B11: ИТОГО аутсорс | E11: =SUM(E4:E10) -> 5800000 | F11: =SUM(F4:F10) -> 928000 | G11: =SUM(G4:G10) -> 6728000 | K11: =SUM(K4:K10) -> 15843355 | L11: =SUM(L4:L10) -> 80736000

Sheet Командировки
A1: Командировки, ₸
A2: Нормы поездок — на человека; стоимость поездки — лист «Параметры»; количество и старт — с листа «Штат» (структура от 16.09.2026).
A4: Роль | B4: Строка «Штат» | C4: Кол-во чел. | D4: Поездок по РК в год на чел. | E4: Выездов по макрорегиону в мес. на чел. | F4: Загранпоездок в год на чел. | G4: Мес. 2026 | H4: Мес. 2027 | I4: Окт–дек 2026 | J4: 2027
A5: =Штат!C5 -> Главный исполнительный директор (ГИД) | C5: =Штат!G5 -> 1 | D5: 4 | E5: 0 | F5: 1 | G5: =Штат!L5 -> 3 | H5: =Штат!M5 -> 12 | I5: =C5*(D5/12*G5*Поездка_РК+E5*G5*Поездка_местн+F5/12*G5*Поездка_межд) -> 495700 | J5: =C5*(D5/12*H5*Поездка_РК_2027+E5*H5*Поездка_местн_2027+F5/12*H5*Поездка_межд) -> 1990066
A6: =Штат!C6 -> Заместитель ГИД (стратегия, проекты) | C6: =Штат!G6 -> 1 | D6: 6 | E6: 0 | F6: 1 | G6: =Штат!L6 -> 3 | H6: =Штат!M6 -> 12 | I6: =C6*(D6/12*G6*Поездка_РК+E6*G6*Поездка_местн+F6/12*G6*Поездка_межд) -> 591175 | J6: =C6*(D6/12*H6*Поездка_РК_2027+E6*H6*Поездка_местн_2027+F6/12*H6*Поездка_межд) -> 2375599
A7: =Штат!C7 -> Заместитель ГИД (адм.-хоз. вопросы, закупки, кадры, проекты) | C7: =Штат!G7 -> 1 | D7: 2 | E7: 0 | F7: 0 | G7: =Штат!L7 -> 3 | H7: =Штат!M7 -> 12 | I7: =C7*(D7/12*G7*Поездка_РК+E7*G7*Поездка_местн+F7/12*G7*Поездка_межд) -> 95475 | J7: =C7*(D7/12*H7*Поездка_РК_2027+E7*H7*Поездка_местн_2027+F7/12*H7*Поездка_межд) -> 385533
A8: =Штат!C37 -> Финансовый директор | C8: =Штат!G37 -> 1 | D8: 0 | E8: 0 | F8: 0 | G8: =Штат!L37 -> 3 | H8: =Штат!M37 -> 12 | I8: =C8*(D8/12*G8*Поездка_РК+E8*G8*Поездка_местн+F8/12*G8*Поездка_межд) -> 0 | J8: =C8*(D8/12*H8*Поездка_РК_2027+E8*H8*Поездка_местн_2027+F8/12*H8*Поездка_межд) -> 0
A9: =Штат!C39 -> Менеджер международных проектов | C9: =Штат!G39 -> 1 | D9: 1 | E9: 0 | F9: 1 | G9: =Штат!L39 -> 2.3548387 | H9: =Штат!M39 -> 12 | I9: =C9*(D9/12*G9*Поездка_РК+E9*G9*Поездка_местн+F9/12*G9*Поездка_межд) -> 276683.74 | J9: =C9*(D9/12*H9*Поездка_РК_2027+E9*H9*Поездка_местн_2027+F9/12*H9*Поездка_межд) -> 1411766.5
A10: =Штат!C8 -> Национальный координатор проектного офиса | C10: =Штат!G8 -> 1 | D10: 10 | E10: 0 | F10: 1 | G10: =Штат!L8 -> 2.3548387 | H10: =Штат!M8 -> 12 | I10: =C10*(D10/12*G10*Поездка_РК+E10*G10*Поездка_местн+F10/12*G10*Поездка_межд) -> 613926.08 | J10: =C10*(D10/12*H10*Поездка_РК_2027+E10*H10*Поездка_местн_2027+F10/12*H10*Поездка_межд) -> 3146665
A11: Департамент социологических исследований и аналитики (5 чел.) | C11: =SUM(Штат!G9:G13) -> 5 | D11: 3 | E11: 3 | F11: 0 | G11: =Штат!L10 -> 2.3548387 | H11: =Штат!M10 -> 12 | I11: =C11*(D11/12*G11*Поездка_РК+E11*G11*Поездка_местн+F11/12*G11*Поездка_межд) -> 1397449.6 | J11: =C11*(D11/12*H11*Поездка_РК_2027+E11*H11*Поездка_местн_2027+F11/12*H11*Поездка_межд) -> 7257487.5
A12: Департамент проектного управления и региональной координации (10 чел.) | C12: =SUM(Штат!G17:G26) -> 10 | D12: 6 | E12: 0 | F12: 0 | G12: =Штат!L19 -> 2.3548387 | H12: =Штат!M19 -> 12 | I12: =C12*(D12/12*G12*Поездка_РК+E12*G12*Поездка_местн+F12/12*G12*Поездка_межд) -> 2248282.3 | J12: =C12*(D12/12*H12*Поездка_РК_2027+E12*H12*Поездка_местн_2027+F12/12*H12*Поездка_межд) -> 11565990
A13: Экспертная группа (3 чел.) | C13: =SUM(Штат!G14:G16) -> 3 | D13: 3 | E13: 0 | F13: 0 | G13: =Штат!L16 -> 0 | H13: =Штат!M16 -> 11 | I13: =C13*(D13/12*G13*Поездка_РК+E13*G13*Поездка_местн+F13/12*G13*Поездка_межд) -> 0 | J13: =C13*(D13/12*H13*Поездка_РК_2027+E13*H13*Поездка_местн_2027+F13/12*H13*Поездка_межд) -> 1590323.6
A14: Департамент цифрового развития (1 чел., разработчик — аутсорс) | C14: =SUM(Штат!G27:G28) -> 1 | D14: 1 | E14: 0 | F14: 0 | G14: =Штат!L27 -> 2.3548387 | H14: =Штат!M27 -> 12 | I14: =C14*(D14/12*G14*Поездка_РК+E14*G14*Поездка_местн+F14/12*G14*Поездка_межд) -> 37471.371 | J14: =C14*(D14/12*H14*Поездка_РК_2027+E14*H14*Поездка_местн_2027+F14/12*H14*Поездка_межд) -> 192766.5
A15: Группа «Коммуникация и креатив» (4 чел.): съёмки и освещение мероприятий в регионах | C15: =SUM(Штат!G29:G36) -> 4 | D15: 4 | E15: 4 | F15: 0 | G15: =Штат!L29 -> 2.3548387 | H15: =Штат!M29 -> 12 | I15: =C15*(D15/12*G15*Поездка_РК+E15*G15*Поездка_местн+F15/12*G15*Поездка_межд) -> 1490612.9 | J15: =C15*(D15/12*H15*Поездка_РК_2027+E15*H15*Поездка_местн_2027+F15/12*H15*Поездка_межд) -> 7741320
I16: =C16*(D16/12*G16*Поездка_РК+E16*G16*Поездка_местн+F16/12*G16*Поездка_межд) -> 0 | J16: =C16*(D16/12*H16*Поездка_РК_2027+E16*H16*Поездка_местн_2027+F16/12*H16*Поездка_межд) -> 0
I17: =C17*(D17/12*G17*Поездка_РК+E17*G17*Поездка_местн+F17/12*G17*Поездка_межд) -> 0 | J17: =C17*(D17/12*H17*Поездка_РК_2027+E17*H17*Поездка_местн_2027+F17/12*H17*Поездка_межд) -> 0
I18: =C18*(D18/12*G18*Поездка_РК+E18*G18*Поездка_местн+F18/12*G18*Поездка_межд) -> 0 | J18: =C18*(D18/12*H18*Поездка_РК_2027+E18*H18*Поездка_местн_2027+F18/12*H18*Поездка_межд) -> 0
I19: =C19*(D19/12*G19*Поездка_РК+E19*G19*Поездка_местн+F19/12*G19*Поездка_межд) -> 0 | J19: =C19*(D19/12*H19*Поездка_РК_2027+E19*H19*Поездка_местн_2027+F19/12*H19*Поездка_межд) -> 0
I20: =C20*(D20/12*G20*Поездка_РК+E20*G20*Поездка_местн+F20/12*G20*Поездка_межд) -> 0 | J20: =C20*(D20/12*H20*Поездка_РК_2027+E20*H20*Поездка_местн_2027+F20/12*H20*Поездка_межд) -> 0
I21: =C21*(D21/12*G21*Поездка_РК+E21*G21*Поездка_местн+F21/12*G21*Поездка_межд) -> 0 | J21: =C21*(D21/12*H21*Поездка_РК_2027+E21*H21*Поездка_местн_2027+F21/12*H21*Поездка_межд) -> 0
I22: =C22*(D22/12*G22*Поездка_РК+E22*G22*Поездка_местн+F22/12*G22*Поездка_межд) -> 0 | J22: =C22*(D22/12*H22*Поездка_РК_2027+E22*H22*Поездка_местн_2027+F22/12*H22*Поездка_межд) -> 0
I23: =C23*(D23/12*G23*Поездка_РК+E23*G23*Поездка_местн+F23/12*G23*Поездка_межд) -> 0 | J23: =C23*(D23/12*H23*Поездка_РК_2027+E23*H23*Поездка_местн_2027+F23/12*H23*Поездка_межд) -> 0
I24: =C24*(D24/12*G24*Поездка_РК+E24*G24*Поездка_местн+F24/12*G24*Поездка_межд) -> 0 | J24: =C24*(D24/12*H24*Поездка_РК_2027+E24*H24*Поездка_местн_2027+F24/12*H24*Поездка_межд) -> 0
I25: =C25*(D25/12*G25*Поездка_РК) -> 0 | J25: =C25*(D25/12*H25*Поездка_РК_2027) -> 0
A26: ИТОГО | I26: =SUM(I5:I25) -> 7246775.9 | J26: =SUM(J5:J25) -> 37657517

Sheet Оснащение и офис
A1: Оснащение, офис, цифровые инструменты, медиа и прочие расходы, ₸
A2: Тип: разово — в месяц старта; мес — ежемесячно с месяца старта; год — годовая сумма (в окт–дек 2026 — 3/12).
A4: Раздел | B4: Статья | C4: Ед. | D4: Кол-во | E4: Цена, ₸ | F4: Тип | G4: Старт (1=окт-26) | H4: Примечание | I4: Окт–дек 2026 | J4: 2027
A5: Оснащение | B5: Ноутбук стандартный (Core i5 / Ryzen 5, 16 ГБ, SSD 512 ГБ) | C5: шт. | D5: 25 | E5: 450000 | F5: разово | G5: 1 | H5: новые сотрудники (21) без 3 производительных; 4 действующих — со своей техникой | I5: =IF(F5="разово",IF(G5<=3,D5*E5,0),IF(F5="мес",D5*E5*MAX(0,4-G5),D5*E5*MAX(0,4-G5)/12)) -> 11250000 | J5: =IF(F5="разово",IF(AND(G5>3,G5<=15),D5*E5,0),IF(F5="мес",D5*E5*MAX(0,MIN(12,16-MAX(G5,4))),D5*E5*MAX(0,MIN(12,16-MAX(G5,4)))/12)) -> 0
A6: Оснащение | B6: Ноутбук производительный | C6: шт. | D6: 5 | E6: 900000 | F6: разово | G6: 1 | H6: программист ИИ, разработчик веб-продуктов, старший аналитик | I6: =IF(F6="разово",IF(G6<=3,D6*E6,0),IF(F6="мес",D6*E6*MAX(0,4-G6),D6*E6*MAX(0,4-G6)/12)) -> 4500000 | J6: =IF(F6="разово",IF(AND(G6>3,G6<=15),D6*E6,0),IF(F6="мес",D6*E6*MAX(0,MIN(12,16-MAX(G6,4))),D6*E6*MAX(0,MIN(12,16-MAX(G6,4)))/12)) -> 0
A7: Оснащение | B7: Монитор 24" + клавиатура, мышь, гарнитура | C7: компл. | D7: 15 | E7: 100000 | F7: разово | G7: 1 | H7: новые сотрудники в офисе (рег. координаторы — удалённо) | I7: =IF(F7="разово",IF(G7<=3,D7*E7,0),IF(F7="мес",D7*E7*MAX(0,4-G7),D7*E7*MAX(0,4-G7)/12)) -> 1500000 | J7: =IF(F7="разово",IF(AND(G7>3,G7<=15),D7*E7,0),IF(F7="мес",D7*E7*MAX(0,MIN(12,16-MAX(G7,4))),D7*E7*MAX(0,MIN(12,16-MAX(G7,4)))/12)) -> 0
A8: Оснащение | B8: Рабочее место: стол, кресло, тумба | C8: место | D8: 19 | E8: 200000 | F8: разово | G8: 1 | H8: 16 сотрудников в open space + 3 гостевых (продакшн-группа, координаторы в приезд) | I8: =IF(F8="разово",IF(G8<=3,D8*E8,0),IF(F8="мес",D8*E8*MAX(0,4-G8),D8*E8*MAX(0,4-G8)/12)) -> 3800000 | J8: =IF(F8="разово",IF(AND(G8>3,G8<=15),D8*E8,0),IF(F8="мес",D8*E8*MAX(0,MIN(12,16-MAX(G8,4))),D8*E8*MAX(0,MIN(12,16-MAX(G8,4)))/12)) -> 0
A9: Оснащение | B9: Мебель кабинетов руководства (ГИД, 2 заместителя, Нац.коорд., финдир) | C9: компл. | D9: 5 | E9: 500000 | F9: разово | G9: 1 | H9: новый офис | I9: =IF(F9="разово",IF(G9<=3,D9*E9,0),IF(F9="мес",D9*E9*MAX(0,4-G9),D9*E9*MAX(0,4-G9)/12)) -> 2500000 | J9: =IF(F9="разово",IF(AND(G9>3,G9<=15),D9*E9,0),IF(F9="мес",D9*E9*MAX(0,MIN(12,16-MAX(G9,4))),D9*E9*MAX(0,MIN(12,16-MAX(G9,4)))/12)) -> 0
A10: Оснащение | B10: Переговорная: стол + 12 стульев | C10: компл. | D10: 1 | E10: 800000 | F10: разово | G10: 1 | I10: =IF(F10="разово",IF(G10<=3,D10*E10,0),IF(F10="мес",D10*E10*MAX(0,4-G10),D10*E10*MAX(0,4-G10)/12)) -> 800000 | J10: =IF(F10="разово",IF(AND(G10>3,G10<=15),D10*E10,0),IF(F10="мес",D10*E10*MAX(0,MIN(12,16-MAX(G10,4))),D10*E10*MAX(0,MIN(12,16-MAX(G10,4)))/12)) -> 0
A11: Оснащение | B11: Зона ресепшн (стойка, диван для посетителей) | C11: компл. | D11: 1 | E11: 500000 | F11: разово | G11: 1 | I11: =IF(F11="разово",IF(G11<=3,D11*E11,0),IF(F11="мес",D11*E11*MAX(0,4-G11),D11*E11*MAX(0,4-G11)/12)) -> 500000 | J11: =IF(F11="разово",IF(AND(G11>3,G11<=15),D11*E11,0),IF(F11="мес",D11*E11*MAX(0,MIN(12,16-MAX(G11,4))),D11*E11*MAX(0,MIN(12,16-MAX(G11,4)))/12)) -> 0
A12: Оснащение | B12: Шкафы для документов и сейф | C12: компл. | D12: 1 | E12: 450000 | F12: разово | G12: 1 | H12: Сейф офисный для документов и печатей входит в этот комплект | I12: =IF(F12="разово",IF(G12<=3,D12*E12,0),IF(F12="мес",D12*E12*MAX(0,4-G12),D12*E12*MAX(0,4-G12)/12)) -> 450000 | J12: =IF(F12="разово",IF(AND(G12>3,G12<=15),D12*E12,0),IF(F12="мес",D12*E12*MAX(0,MIN(12,16-MAX(G12,4))),D12*E12*MAX(0,MIN(12,16-MAX(G12,4)))/12)) -> 0
A13: Оснащение | B13: Стеллажи для складов и архивов (склад техники, архив документов, архив основного блока) | C13: шт. | D13: 6 | E13: 60000 | F13: разово | G13: 1 | H13: Металлические стеллажи 2000×1000×500, 4–5 полок. По 2 шт.: склад фото- и видеотехники, архив документов, серверная (в БЦ «Санкт-Петербург» — помещение без окна 701Г или по месту). Цена ориентировочная, уточнить в КП | I13: =IF(F13="разово",IF(G13<=3,D13*E13,0),IF(F13="мес",D13*E13*MAX(0,4-G13),D13*E13*MAX(0,4-G13)/12)) -> 360000 | J13: =IF(F13="разово",IF(AND(G13>3,G13<=15),D13*E13,0),IF(F13="мес",D13*E13*MAX(0,MIN(12,16-MAX(G13,4))),D13*E13*MAX(0,MIN(12,16-MAX(G13,4)))/12)) -> 0
A14: Оснащение | B14: Сборка, доставка и подъём мебели | C14: компл. | D14: 1 | E14: =(D8*E8+D9*E9+D10*E10+D11*E11+D12*E12+D13*E13)*Сборка_мебели_проц -> 841000 | F14: разово | G14: 1 | H14: Сборка и занос: рабочие места, кабинеты руководства, переговорная, ресепшн, шкафы и сейф, стеллажи. Ориентир 10% от стоимости мебели и стеллажей (лист «Параметры»), уточнить в КП | I14: =IF(F14="разово",IF(G14<=3,D14*E14,0),IF(F14="мес",D14*E14*MAX(0,4-G14),D14*E14*MAX(0,4-G14)/12)) -> 841000 | J14: =IF(F14="разово",IF(AND(G14>3,G14<=15),D14*E14,0),IF(F14="мес",D14*E14*MAX(0,MIN(12,16-MAX(G14,4))),D14*E14*MAX(0,MIN(12,16-MAX(G14,4)))/12)) -> 0
A15: Оснащение | B15: МФУ цветное А3 (класс Kyocera TASKalfa 2554ci) с Wi-Fi, тумбой, доставкой и установкой | C15: шт. | D15: 1 | E15: 2500000 | F15: разово | G15: 1 | H15: печать/копия/скан А3; сетевой и Wi-Fi модуль — обязательно; уточнить КП | I15: =IF(F15="разово",IF(G15<=3,D15*E15,0),IF(F15="мес",D15*E15*MAX(0,4-G15),D15*E15*MAX(0,4-G15)/12)) -> 2500000 | J15: =IF(F15="разово",IF(AND(G15>3,G15<=15),D15*E15,0),IF(F15="мес",D15*E15*MAX(0,MIN(12,16-MAX(G15,4))),D15*E15*MAX(0,MIN(12,16-MAX(G15,4)))/12)) -> 0
A16: Оснащение | B16: Стартовый комплект тонеров CMYK для МФУ А3 | C16: компл. | D16: 1 | E16: 300000 | F16: разово | G16: 1 | I16: =IF(F16="разово",IF(G16<=3,D16*E16,0),IF(F16="мес",D16*E16*MAX(0,4-G16),D16*E16*MAX(0,4-G16)/12)) -> 300000 | J16: =IF(F16="разово",IF(AND(G16>3,G16<=15),D16*E16,0),IF(F16="мес",D16*E16*MAX(0,MIN(12,16-MAX(G16,4))),D16*E16*MAX(0,MIN(12,16-MAX(G16,4)))/12)) -> 0
A17: Оснащение | B17: МФУ А4 чёрно-белое с Wi-Fi, дуплексом и автоподатчиком (класс HP LaserJet Pro MFP 4103fdw / Kyocera ECOSYS MA4000fx) | C17: шт. | D17: 2 | E17: 280000 | F17: разово | G17: 1 | H17: ресепшн и кабинет аппарата: печать, копия, скан; работа по Wi-Fi и по сети | I17: =IF(F17="разово",IF(G17<=3,D17*E17,0),IF(F17="мес",D17*E17*MAX(0,4-G17),D17*E17*MAX(0,4-G17)/12)) -> 560000 | J17: =IF(F17="разово",IF(AND(G17>3,G17<=15),D17*E17,0),IF(F17="мес",D17*E17*MAX(0,MIN(12,16-MAX(G17,4))),D17*E17*MAX(0,MIN(12,16-MAX(G17,4)))/12)) -> 0
A18: Оснащение | B18: Резервные картриджи для МФУ А4 (по 2 на аппарат) | C18: шт. | D18: 4 | E18: 55000 | F18: разово | G18: 1 | H18: ресурс ≈3 000 страниц; запас на первый год | I18: =IF(F18="разово",IF(G18<=3,D18*E18,0),IF(F18="мес",D18*E18*MAX(0,4-G18),D18*E18*MAX(0,4-G18)/12)) -> 220000 | J18: =IF(F18="разово",IF(AND(G18>3,G18<=15),D18*E18,0),IF(F18="мес",D18*E18*MAX(0,MIN(12,16-MAX(G18,4))),D18*E18*MAX(0,MIN(12,16-MAX(G18,4)))/12)) -> 0
A19: Оснащение | B19: Резервный комплект тонеров CMYK для МФУ А3 | C19: компл. | D19: 1 | E19: 300000 | F19: разово | G19: 1 | H19: второй комплект вслед за стартовым | I19: =IF(F19="разово",IF(G19<=3,D19*E19,0),IF(F19="мес",D19*E19*MAX(0,4-G19),D19*E19*MAX(0,4-G19)/12)) -> 300000 | J19: =IF(F19="разово",IF(AND(G19>3,G19<=15),D19*E19,0),IF(F19="мес",D19*E19*MAX(0,MIN(12,16-MAX(G19,4))),D19*E19*MAX(0,MIN(12,16-MAX(G19,4)))/12)) -> 0
A20: Оснащение | B20: Ламинатор Deli ET104, А3, 300 мм/мин | C20: шт. | D20: 1 | E20: =ROUND(42340/(1+НДС),0) -> 36500 | F20: разово | G20: 1 | H20: План закупок 2026, поз. 57 (ламинатор Deli А3 — 25 980 ₸). Цена b2bcompany.kz на 24.09.2026 — 42 340 ₸ с НДС, в бюджете без НДС (÷1,16): https://b2bcompany.kz/catalog/ofisnaya_tekhnika_i_aksessuary/laminatory/99742/ | I20: =IF(F20="разово",IF(G20<=3,D20*E20,0),IF(F20="мес",D20*E20*MAX(0,4-G20),D20*E20*MAX(0,4-G20)/12)) -> 36500 | J20: =IF(F20="разово",IF(AND(G20>3,G20<=15),D20*E20,0),IF(F20="мес",D20*E20*MAX(0,MIN(12,16-MAX(G20,4))),D20*E20*MAX(0,MIN(12,16-MAX(G20,4)))/12)) -> 0
A21: Оснащение | B21: Плёнка для ламинирования А4, 100 мкм, 100 шт. в упаковке (OfficeSpace) | C21: уп. | D21: 1 | E21: =ROUND(6000/(1+НДС),0) -> 5172 | F21: разово | G21: 1 | H21: План закупок 2026, поз. 58 (8 880 ₸/уп.). b2bcompany.kz на 24.09.2026: 60 ₸/шт × 100 = 6 000 ₸ с НДС, в бюджете без НДС (÷1,16) — https://b2bcompany.kz/catalog/ofisnaya_tekhnika_i_aksessuary/pruzhiny_oblozhki_plyenka/plyenka_dlya_laminirovaniya/94307/ | I21: =IF(F21="разово",IF(G21<=3,D21*E21,0),IF(F21="мес",D21*E21*MAX(0,4-G21),D21*E21*MAX(0,4-G21)/12)) -> 5172 | J21: =IF(F21="разово",IF(AND(G21>3,G21<=15),D21*E21,0),IF(F21="мес",D21*E21*MAX(0,MIN(12,16-MAX(G21,4))),D21*E21*MAX(0,MIN(12,16-MAX(G21,4)))/12)) -> 0
A22: Оснащение | B22: Переплётная машина Deli 3873 для пластиковой пружины (перфорирует до 18 л., сшивает до 425 л.) | C22: шт. | D22: 1 | E22: =ROUND(114327/(1+НДС),0) -> 98558 | F22: разово | G22: 1 | H22: План закупок 2026, поз. 50 (77 105 ₸). Цена b2bcompany.kz на 24.09.2026 — 114 327 ₸ с НДС, в бюджете без НДС (÷1,16): https://b2bcompany.kz/catalog/ofisnaya_tekhnika_i_aksessuary/pereplyetchiki/98863/ | I22: =IF(F22="разово",IF(G22<=3,D22*E22,0),IF(F22="мес",D22*E22*MAX(0,4-G22),D22*E22*MAX(0,4-G22)/12)) -> 98558 | J22: =IF(F22="разово",IF(AND(G22>3,G22<=15),D22*E22,0),IF(F22="мес",D22*E22*MAX(0,MIN(12,16-MAX(G22,4))),D22*E22*MAX(0,MIN(12,16-MAX(G22,4)))/12)) -> 0
A23: Оснащение | B23: Расходники для переплёта: обложки А4 картонные и пластиковые, пружины 6, 10, 14 и 51 мм (по 100 шт.) | C23: компл. | D23: 1 | E23: =ROUND((100*55+100*68+100*26+100*37+100*57+100*244)/(1+НДС),0) -> 41983 | F23: разово | G23: 1 | H23: План закупок 2026, поз. 51–56. Итого 48 700 ₸ с НДС, в бюджете без НДС (÷1,16). Цены b2bcompany.kz на 24.09.2026, ₸/шт × 100 шт. (код товара на сайте): обложки картонные OfficeSpace А4 230 г/м² синие — 55 (94290); обложки пластиковые А4 200 мкм прозрачные — 68 (Brauberg 98583; OfficeSpace 200 мкм прозрачных нет); пружины Brauberg 6 мм — 26 (61538); OfficeSpace 10 мм — 37 (101049); 14 мм — 57 (81143); 51 мм, 2 уп. по 50 — 244 (81145) | I23: =IF(F23="разово",IF(G23<=3,D23*E23,0),IF(F23="мес",D23*E23*MAX(0,4-G23),D23*E23*MAX(0,4-G23)/12)) -> 41983 | J23: =IF(F23="разово",IF(AND(G23>3,G23<=15),D23*E23,0),IF(F23="мес",D23*E23*MAX(0,MIN(12,16-MAX(G23,4))),D23*E23*MAX(0,MIN(12,16-MAX(G23,4)))/12)) -> 0
A24: Оснащение | B24: Сетевые фильтры на рабочие места: 5 розеток, 3 м, с заземлением (Defender ES) | C24: шт. | D24: 31 | E24: =ROUND(4118/(1+НДС),0) -> 3550 | F24: разово | G24: 1 | H24: По 1 на рабочее место: 29 сотрудников + стол сисадмина + резерв/гостевое = 31. Ноутбук, монитор, зарядка телефона, лампа. Столы у стен и колонн — в розетку напрямую, островные блоки — в удлинитель блока (строка ниже). b2bcompany.kz на 30.09.2026 — 4 118 ₸ с НДС (код 9320), в бюджете без НДС (÷1,16): https://b2bcompany.kz/catalog/ofisnaya_tekhnika_i_aksessuary/elektrotovary/setevye_filtry/9320/ | I24: =IF(F24="разово",IF(G24<=3,D24*E24,0),IF(F24="мес",D24*E24*MAX(0,4-G24),D24*E24*MAX(0,4-G24)/12)) -> 110050 | J24: =IF(F24="разово",IF(AND(G24>3,G24<=15),D24*E24,0),IF(F24="мес",D24*E24*MAX(0,MIN(12,16-MAX(G24,4))),D24*E24*MAX(0,MIN(12,16-MAX(G24,4)))/12)) -> 0
A25: Оснащение | B25: Сетевые фильтры на общие зоны: 6 розеток, 5 м (Defender DFS 155) | C25: шт. | D25: 5 | E25: =ROUND(6101/(1+НДС),0) -> 5259 | F25: разово | G25: 1 | H25: Стол совещаний на 12 — 2 (ноутбуки участников), ТВ и ВКС — 1, МФУ и сетевое оборудование — 1, кухонная зона — 1. b2bcompany.kz на 30.09.2026 — 6 101 ₸ с НДС (код 51417), в бюджете без НДС (÷1,16): https://b2bcompany.kz/catalog/ofisnaya_tekhnika_i_aksessuary/elektrotovary/setevye_filtry/51417/ | I25: =IF(F25="разово",IF(G25<=3,D25*E25,0),IF(F25="мес",D25*E25*MAX(0,4-G25),D25*E25*MAX(0,4-G25)/12)) -> 26295 | J25: =IF(F25="разово",IF(AND(G25>3,G25<=15),D25*E25,0),IF(F25="мес",D25*E25*MAX(0,MIN(12,16-MAX(G25,4))),D25*E25*MAX(0,MIN(12,16-MAX(G25,4)))/12)) -> 0
A26: Оснащение | B26: Удлинители-магистрали 10 м, 3 розетки, с заземлением, ПВС 3×1 мм², 16 А (ЭРА U-3e-10m-3x1) | C26: шт. | D26: 4 | E26: =ROUND(7235/(1+НДС),0) -> 6237 | F26: разово | G26: 1 | H26: Розетки в офисе — только у стен и на колоннах. От колонны к каждому островному блоку столов: коммуникация — 1, проектное управление — 2 (9 мест), социология — 1. Kaspi.kz (Астана) на 30.09.2026 — 7 235 ₸ с НДС, в бюджете без НДС (÷1,16): https://kaspi.kz/shop/p/udlinitel-era-u-3e-10m-3x1-5055945573695-10-m-120249480/ | I26: =IF(F26="разово",IF(G26<=3,D26*E26,0),IF(F26="мес",D26*E26*MAX(0,4-G26),D26*E26*MAX(0,4-G26)/12)) -> 24948 | J26: =IF(F26="разово",IF(AND(G26>3,G26<=15),D26*E26,0),IF(F26="мес",D26*E26*MAX(0,MIN(12,16-MAX(G26,4))),D26*E26*MAX(0,MIN(12,16-MAX(G26,4)))/12)) -> 0
A27: Оснащение | B27: Кабель-канал напольный ПВХ 70×16 мм, секция 2 м (IEK) | C27: шт. | D27: 5 | E27: =ROUND(9039/(1+НДС),0) -> 7792 | F27: разово | G27: 1 | H27: Прокладка удлинителей по полу через проходы от колонн к блокам столов и к столу совещаний — ≈10 м. Kaspi.kz (Астана) на 30.09.2026 — 9 039 ₸ с НДС за 2 м, в бюджете без НДС (÷1,16): https://kaspi.kz/shop/p/iek-kabel--kanal-profil-pvh-70h16h2000-mm-115737589/ | I27: =IF(F27="разово",IF(G27<=3,D27*E27,0),IF(F27="мес",D27*E27*MAX(0,4-G27),D27*E27*MAX(0,4-G27)/12)) -> 38960 | J27: =IF(F27="разово",IF(AND(G27>3,G27<=15),D27*E27,0),IF(F27="мес",D27*E27*MAX(0,MIN(12,16-MAX(G27,4))),D27*E27*MAX(0,MIN(12,16-MAX(G27,4)))/12)) -> 0
A28: Оснащение | B28: Источник бесперебойного питания 1200 ВА / 650 Вт, линейно-интерактивный (APC Back-UPS BX1200MI-GR) | C28: шт. | D28: 10 | E28: =ROUND(89302/(1+НДС),0) -> 76984 | F28: разово | G28: 1 | H28: Kaspi.kz (Астана) на 10.10.2026 – 89 302 ₸ с НДС, в бюджете без НДС (÷1,16): https://kaspi.kz/shop/p/istochnik-bespereboinogo-pitanija-apc-by-schneider-electric-back-ups-bx1200mi-gr-101092827/ ; у b2bcompany.kz ИБП нет | I28: =IF(F28="разово",IF(G28<=3,D28*E28,0),IF(F28="мес",D28*E28*MAX(0,4-G28),D28*E28*MAX(0,4-G28)/12)) -> 769840 | J28: =IF(F28="разово",IF(AND(G28>3,G28<=15),D28*E28,0),IF(F28="мес",D28*E28*MAX(0,MIN(12,16-MAX(G28,4))),D28*E28*MAX(0,MIN(12,16-MAX(G28,4)))/12)) -> 0
A29: Оснащение | B29: ТВ-панель 65" для переговорной | C29: шт. | D29: 1 | E29: 450000 | F29: разово | G29: 1 | H29: для стола совещаний / видеоконференций; ставится на мобильную стойку (строка ниже) | I29: =IF(F29="разово",IF(G29<=3,D29*E29,0),IF(F29="мес",D29*E29*MAX(0,4-G29),D29*E29*MAX(0,4-G29)/12)) -> 450000 | J29: =IF(F29="разово",IF(AND(G29>3,G29<=15),D29*E29,0),IF(F29="мес",D29*E29*MAX(0,MIN(12,16-MAX(G29,4))),D29*E29*MAX(0,MIN(12,16-MAX(G29,4)))/12)) -> 0
A30: Оснащение | B30: Мобильная стойка для ТВ на колёсах, 32–65″ (A-case AVA1500-60-1P) | C30: шт. | D30: 1 | E30: =ROUND(57852/(1+НДС),0) -> 49872 | F30: разово | G30: 1 | H30: ТВ для видеоконференций — на передвижной стойке у стола совещаний. Цена Kaspi.kz (Астана) на 30.09.2026 — 57 852 ₸ с НДС, в бюджете без НДС (÷1,16): https://kaspi.kz/shop/p/a-case-ava1500-60-1p--135144097/ ; у b2bcompany.kz стоек нет | I30: =IF(F30="разово",IF(G30<=3,D30*E30,0),IF(F30="мес",D30*E30*MAX(0,4-G30),D30*E30*MAX(0,4-G30)/12)) -> 49872 | J30: =IF(F30="разово",IF(AND(G30>3,G30<=15),D30*E30,0),IF(F30="мес",D30*E30*MAX(0,MIN(12,16-MAX(G30,4))),D30*E30*MAX(0,MIN(12,16-MAX(G30,4)))/12)) -> 0
A31: Оснащение | B31: Конференц-камера и спикерфон | C31: компл. | D31: 1 | E31: 300000 | F31: разово | G31: 1 | H31: ВКС с акиматами и координаторами | I31: =IF(F31="разово",IF(G31<=3,D31*E31,0),IF(F31="мес",D31*E31*MAX(0,4-G31),D31*E31*MAX(0,4-G31)/12)) -> 300000 | J31: =IF(F31="разово",IF(AND(G31>3,G31<=15),D31*E31,0),IF(F31="мес",D31*E31*MAX(0,MIN(12,16-MAX(G31,4))),D31*E31*MAX(0,MIN(12,16-MAX(G31,4)))/12)) -> 0
A32: Оснащение | B32: Сетевое оборудование и СКС (роутер, коммутатор, Wi-Fi, монтаж) | C32: компл. | D32: 1 | E32: 800000 | F32: разово | G32: 1 | H32: новый офис | I32: =IF(F32="разово",IF(G32<=3,D32*E32,0),IF(F32="мес",D32*E32*MAX(0,4-G32),D32*E32*MAX(0,4-G32)/12)) -> 800000 | J32: =IF(F32="разово",IF(AND(G32>3,G32<=15),D32*E32,0),IF(F32="мес",D32*E32*MAX(0,MIN(12,16-MAX(G32,4))),D32*E32*MAX(0,MIN(12,16-MAX(G32,4)))/12)) -> 0
A33: Оснащение | B33: Сетевой накопитель (NAS) с дисками — архив фото/видео и документов | C33: шт. | D33: 1 | E33: 700000 | F33: разово | G33: 1 | I33: =IF(F33="разово",IF(G33<=3,D33*E33,0),IF(F33="мес",D33*E33*MAX(0,4-G33),D33*E33*MAX(0,4-G33)/12)) -> 700000 | J33: =IF(F33="разово",IF(AND(G33>3,G33<=15),D33*E33,0),IF(F33="мес",D33*E33*MAX(0,MIN(12,16-MAX(G33,4))),D33*E33*MAX(0,MIN(12,16-MAX(G33,4)))/12)) -> 0
A34: Оснащение | B34: Фото- и видеооборудование (КП PSP Digital), аккумуляторы на год, доп. оборудование | C34: смета | D34: 1 | E34: ='Смета фото-видео'!G35 -> 7062880 | F34: разово | G34: 1 | H34: лист «Смета фото-видео»: КП 5 517 890 + аккумуляторы на год 970 000 + доп. оборудование 574 990 | I34: =IF(F34="разово",IF(G34<=3,D34*E34,0),IF(F34="мес",D34*E34*MAX(0,4-G34),D34*E34*MAX(0,4-G34)/12)) -> 7062880 | J34: =IF(F34="разово",IF(AND(G34>3,G34<=15),D34*E34,0),IF(F34="мес",D34*E34*MAX(0,MIN(12,16-MAX(G34,4))),D34*E34*MAX(0,MIN(12,16-MAX(G34,4)))/12)) -> 0
A35: Оснащение | B35: Бытовая техника (кулер, холодильник, микроволновка, кофемашина) | C35: компл. | D35: 1 | E35: 400000 | F35: разово | G35: 1 | I35: =IF(F35="разово",IF(G35<=3,D35*E35,0),IF(F35="мес",D35*E35*MAX(0,4-G35),D35*E35*MAX(0,4-G35)/12)) -> 400000 | J35: =IF(F35="разово",IF(AND(G35>3,G35<=15),D35*E35,0),IF(F35="мес",D35*E35*MAX(0,MIN(12,16-MAX(G35,4))),D35*E35*MAX(0,MIN(12,16-MAX(G35,4)))/12)) -> 0
A36: Оснащение | B36: Лицензии 1С на дополнительные рабочие места | C36: компл. | D36: 1 | E36: 150000 | F36: разово | G36: 1 | I36: =IF(F36="разово",IF(G36<=3,D36*E36,0),IF(F36="мес",D36*E36*MAX(0,4-G36),D36*E36*MAX(0,4-G36)/12)) -> 150000 | J36: =IF(F36="разово",IF(AND(G36>3,G36<=15),D36*E36,0),IF(F36="мес",D36*E36*MAX(0,MIN(12,16-MAX(G36,4))),D36*E36*MAX(0,MIN(12,16-MAX(G36,4)))/12)) -> 0
A37: Оснащение | B37: Вывеска и брендирование офиса | C37: компл. | D37: 1 | E37: 400000 | F37: разово | G37: 1 | I37: =IF(F37="разово",IF(G37<=3,D37*E37,0),IF(F37="мес",D37*E37*MAX(0,4-G37),D37*E37*MAX(0,4-G37)/12)) -> 400000 | J37: =IF(F37="разово",IF(AND(G37>3,G37<=15),D37*E37,0),IF(F37="мес",D37*E37*MAX(0,MIN(12,16-MAX(G37,4))),D37*E37*MAX(0,MIN(12,16-MAX(G37,4)))/12)) -> 0
A38: Оснащение | B38: Пожарная безопасность и аптечки (огнетушители, знаки, аптечки) | C38: компл. | D38: 1 | E38: 100000 | F38: разово | G38: 1 | H38: оценка; уточнить после осмотра помещений (БЦ «Лазурный», 6 этаж) | I38: =IF(F38="разово",IF(G38<=3,D38*E38,0),IF(F38="мес",D38*E38*MAX(0,4-G38),D38*E38*MAX(0,4-G38)/12)) -> 100000 | J38: =IF(F38="разово",IF(AND(G38>3,G38<=15),D38*E38,0),IF(F38="мес",D38*E38*MAX(0,MIN(12,16-MAX(G38,4))),D38*E38*MAX(0,MIN(12,16-MAX(G38,4)))/12)) -> 0
A39: Офис | B39: Аренда офиса | C39: мес. | D39: 1 | E39: =Аренда_мес -> 9856200 | F39: мес | G39: 1 | H39: БЦ «Лазурный», ул. Сарайшык, 7/7, 6 этаж: 469,34 м² полезной × 1,4 = 657,08 м² × 15 000 ₸ = 9 856 200 ₸/мес без НДС (11 433 192 ₸ с НДС); коммунальные, клининг и охрана – в ставке; 5 парковочных мест на этаж. Расчёт: D:\Аренда\Сравнение вариантов аренды – Сыганак и Лазурный (2026-10-10).xlsx. В 2026 – с 21.10 (≈2,35 мес.) | I39: =D39*E39*Аренда_мес_2026 -> 23209761 | J39: =IF(F39="разово",IF(AND(G39>3,G39<=15),D39*E39,0),IF(F39="мес",D39*E39*MAX(0,MIN(12,16-MAX(G39,4))),D39*E39*MAX(0,MIN(12,16-MAX(G39,4)))/12)) -> 118274400
A40: Офис | B40: Гарантийный депозит по аренде (1 месячная ставка, возвратный) | C40: депозит | D40: 1 | E40: =Аренда_мес*Депозит_мес -> 9856200 | F40: разово | G40: 1 | H40: Возвращается по окончании аренды. Условия депозита БЦ «Лазурный» не известны – принят 1 месяц | I40: =IF(F40="разово",IF(G40<=3,D40*E40,0),IF(F40="мес",D40*E40*MAX(0,4-G40),D40*E40*MAX(0,4-G40)/12)) -> 9856200 | J40: =IF(F40="разово",IF(AND(G40>3,G40<=15),D40*E40,0),IF(F40="мес",D40*E40*MAX(0,MIN(12,16-MAX(G40,4))),D40*E40*MAX(0,MIN(12,16-MAX(G40,4)))/12)) -> 0
A41: Офис | B41: Косметический ремонт помещения при заезде (покраска, свет, розетки, перегородки) | C41: работы | D41: 1 | E41: 3000000 | F41: разово | G41: 1 | H41: оценка; уточнить после осмотра помещения | I41: =IF(F41="разово",IF(G41<=3,D41*E41,0),IF(F41="мес",D41*E41*MAX(0,4-G41),D41*E41*MAX(0,4-G41)/12)) -> 3000000 | J41: =IF(F41="разово",IF(AND(G41>3,G41<=15),D41*E41,0),IF(F41="мес",D41*E41*MAX(0,MIN(12,16-MAX(G41,4))),D41*E41*MAX(0,MIN(12,16-MAX(G41,4)))/12)) -> 0
...

Sheet Проекты (вне бюджета)
A1: Проекты и мероприятия, не вошедшие в бюджет (по статьям проектного офиса), ₸ — в ИТОГО свода не входят
A4: Раздел | B4: Статья | C4: Ед. | D4: Кол-во | E4: Цена, ₸ | F4: Тип | G4: Окт–дек 2026 | H4: 2027
A5: Проекты | B5: Реализация проекта «TAZA TALQY» (проведение встреч в регионах), в т.ч. круглые столы и семинары для акиматов | C5: сумма | F5: по ПО | G5: 6000000 | H5: 12000000
A6: Проекты | B6: Реализация проекта «TAZA OI» | C6: сумма | F6: по ПО | G6: 2000000 | H6: 8000000
A7: Проекты | B7: Реализация проектов, в т.ч. итоговый форум и слёт волонтёров | C7: сумма | F7: по ПО | G7: 10000000 | H7: 300000000
A8: Проекты | B8: Проведение международного эко-лагеря для школьников | C8: сумма | F8: по ПО | G8: 0 | H8: 500000000
A9: Проекты | B9: Проведение социологических исследований | C9: сумма | F9: по ПО | G9: 0 | H9: 45000000
A10: Проекты | B10: Подготовка ежегодного доклада | C10: сумма | F10: по ПО | G10: 0 | H10: 25000000
A11: Проекты | B11: Информационное сопровождение, в т.ч. презентация проектного офиса, пресс-мероприятия, мобильный брендинг | C11: сумма | F11: по ПО | G11: 30000000 | H11: 120000000
A12: Проекты | B12: Привлечение инфлюенсеров | C12: сумма | F12: по ПО | G12: 15000000 | H12: 120000000
A13: Проекты | B13: Реализация специальных / креативных проектов | C13: сумма | F13: по ПО | G13: 50000000 | H13: 300000000
A14: Проекты | B14: Разработка и техническое сопровождение цифровой платформы | C14: сумма | F14: по ПО | G14: 100000000 | H14: 100000000
B16: ИТОГО проекты и мероприятия | G16: =SUM(G5:G14) -> 213000000 | H16: =SUM(H5:H14) -> 1530000000
B18: ВСЕГО за 2026-27 гг.: | G18: =G16+H16 -> 1743000000

Sheet Канцелярия
A1: Канцелярия, бумага и хозяйственные товары — расчёт в месяц, ₸
A2: Офис 310,9 м², 20 сотрудников в офисе (25 в штате − 5 региональных координаторов). Итог переносится в лист «Оснащение и офис» (раздел «Офис»).
A4: Группа | B4: Позиция | C4: Ед. | D4: Кол-во в месяц | E4: Цена, ₸ | F4: Сумма в месяц, ₸ | G4: Примечание
A5: Бумага и печать | B5: Бумага А4, 80 г/м² (пачка 500 л.) | C5: пачка | D5: 7 | E5: 3000 | F5: =D5*E5 -> 21000 | G5: ≈3 500 страниц в месяц
A6: Бумага и печать | B6: Бумага А3 (пачка 500 л.) | C6: пачка | D6: 0.5 | E6: 6500 | F6: =D6*E6 -> 3250 | G6: схемы, плакаты, раздаточные материалы
A7: Бумага и печать | B7: Бумага для флипчарта (блок) | C7: блок | D7: 1 | E7: 6000 | F7: =D7*E7 -> 6000 | G7: совещания, семинары
A8: Бумага и печать | B8: Плотная бумага и обложки для брошюровки | C8: компл. | D8: 0.5 | E8: 5000 | F8: =D8*E8 -> 2500 | G8: отчёты, методические материалы
A9: Канцелярия | B9: Ручки, карандаши, маркеры, текстовыделители | C9: компл. | D9: 20 | E9: 1200 | F9: =D9*E9 -> 24000 | G9: на сотрудника в офисе
A10: Канцелярия | B10: Блокноты, стикеры, закладки | C10: компл. | D10: 20 | E10: 900 | F10: =D10*E10 -> 18000 | G10: на сотрудника в офисе
A11: Канцелярия | B11: Папки-регистраторы, скоросшиватели, файлы А4 | C11: компл. | D11: 10 | E11: 1500 | F11: =D11*E11 -> 15000 | G11: делопроизводство, договоры, кадры
A12: Канцелярия | B12: Конверты, почтовые пакеты, бумага для заметок | C12: компл. | D12: 0.5 | E12: 8000 | F12: =D12*E12 -> 4000 | G12: переписка с МЭПР и акиматами
A13: Канцелярия | B13: Скобы, скрепки, клей, ножницы, ножи, линейки | C13: компл. | D13: 1 | E13: 10000 | F13: =D13*E13 -> 10000 | G13: пополнение
A14: Канцелярия | B14: Степлеры, дыроколы, лотки, органайзеры (пополнение) | C14: компл. | D14: 0.5 | E14: 6000 | F14: =D14*E14 -> 3000
A15: Канцелярия | B15: Архивные короба и файлы для архива | C15: компл. | D15: 1 | E15: 12000 | F15: =D15*E15 -> 12000 | G15: хранение документов проекта
A16: Канцелярия | B16: Батарейки, удлинители, мелкая электрика | C16: компл. | D16: 0.5 | E16: 8000 | F16: =D16*E16 -> 4000 | G16: техника, пульты, микрофоны
A17: Хозтовары | B17: Бытовая химия и средства для уборки | C17: компл. | D17: 0.2 | E17: 25000 | F17: =D17*E17 -> 5000 | G17: сверх договора клининга
A18: Хозтовары | B18: Санитарно-гигиенические товары (бумага, полотенца, мыло) | C18: компл. | D18: 1 | E18: 35000 | F18: =D18*E18 -> 35000 | G18: на 310,9 м², с/у и кухня
A19: Хозтовары | B19: Мешки для мусора, перчатки, губки | C19: компл. | D19: 0.2 | E19: 10000 | F19: =D19*E19 -> 2000
A20: Хозтовары | B20: Питьевая вода (бутыль 19 л) | C20: бутыль | D20: 20 | E20: 1800 | F20: =D20*E20 -> 36000 | G20: кулеры в офисе
